<?xml version="1.0" encoding="utf-8"?>
<!-- This URDF was automatically created by SolidWorks to URDF Exporter! Originally created by Stephen Brawner (brawner@gmail.com) 
     Commit Version: 1.6.0-4-g7f85cfe  Build Version: 1.6.7995.38578
     For more information, please see http://wiki.ros.org/sw_urdf_exporter -->
<robot
  name="bessica_d">
    <mujoco>
        <compiler meshdir="../../meshes/Bessica_D_v1_0/withCover" balanceinertia="true" discardvisual="false" />
        <contact>
            <exclude body1="base_link" body2="left_arm_base_link" />
            <exclude body1="left_arm_base_link" body2="left_arm_link1" />
            <exclude body1="left_arm_link1" body2="left_arm_link2" />
            <exclude body1="left_arm_link2" body2="left_arm_link3" />
            <exclude body1="left_arm_link3" body2="left_arm_link4" />
            <exclude body1="left_arm_link4" body2="left_arm_link5" />
            <exclude body1="left_arm_link5" body2="left_arm_link6" />
            <exclude body1="left_arm_link6" body2="left_arm_link7" />
            <exclude body1="left_arm_link7" body2="left_arm_gripper_left_finger" />
            <exclude body1="left_arm_link7" body2="left_arm_gripper_right_finger" />
            <exclude body1="base_link" body2="right_arm_base_link" />
            <exclude body1="right_arm_base_link" body2="right_arm_link1" />
            <exclude body1="right_arm_link1" body2="right_arm_link2" />
            <exclude body1="right_arm_link2" body2="right_arm_link3" />
            <exclude body1="right_arm_link3" body2="right_arm_link4" />
            <exclude body1="right_arm_link4" body2="right_arm_link5" />
            <exclude body1="right_arm_link5" body2="right_arm_link6" />
            <exclude body1="right_arm_link6" body2="right_arm_link7" />
            <exclude body1="right_arm_link7" body2="right_arm_gripper_left_finger" />
            <exclude body1="right_arm_link7" body2="right_arm_gripper_right_finger" />
        </contact>
    </mujoco>
  <link
    name="base_link">
    <inertial>
      <origin
        xyz="-0.00686734373371353 -0.000830132301508779 0.890581345312217"
        rpy="0 0 0" />
      <mass
        value="2.26415289791904" />
      <inertia
        ixx="0.0565673679158182"
        ixy="-2.41210319670709E-05"
        ixz="-0.000382817871659701"
        iyy="0.054770906068853"
        iyz="-4.80169539965677E-05"
        izz="0.017371857678062" />
    </inertial>
    <visual>
      <origin
        xyz="0 0 0"
        rpy="0 0 0" />
      <geometry>
        <mesh
          filename="../../meshes/Bessica_D_v1_0/withCover/base_link.STL" />
      </geometry>
      <material
        name="">
        <color
          rgba="0.807843137254902 0.843137254901961 0.905882352941176 1" />
      </material>
    </visual>
    <collision>
      <origin
        xyz="0 0 0"
        rpy="0 0 0" />
      <geometry>
        <mesh
          filename="../../meshes/Bessica_D_v1_0/withCover/base_link.STL" />
      </geometry>
    </collision>
  </link>
  <link
    name="right_arm_base_link">
    <inertial>
      <origin
        xyz="-1.63473947356365E-05 0.0103241813477426 -0.00300662501800325"
        rpy="0 0 0" />
      <mass
        value="0.760760214237615" />
      <inertia
        ixx="0.00140239578150425"
        ixy="-1.42916140940146E-07"
        ixz="-1.37239405098036E-07"
        iyy="0.00186458776403398"
        iyz="1.55314870843035E-05"
        izz="0.00146104425715145" />
    </inertial>
    <visual>
      <origin
        xyz="0 0 0"
        rpy="0 0 0" />
      <geometry>
        <mesh
          filename="../../meshes/Bessica_D_v1_0/withCover/right_arm_base_link.STL" />
      </geometry>
      <material
        name="">
        <color
          rgba="0.592156862745098 0.666666666666667 0.682352941176471 1" />
      </material>
    </visual>
    <collision>
      <origin
        xyz="0 0 0"
        rpy="0 0 0" />
      <geometry>
        <mesh
          filename="../../meshes/Bessica_D_v1_0/withCover/right_arm_base_link.STL" />
      </geometry>
    </collision>
  </link>
  <joint
    name="right_arm_base_joint"
    type="fixed">
    <origin
      xyz="0 0.0999999996666618 1.01500000066667"
      rpy="0 0 0" />
    <parent
      link="base_link" />
    <child
      link="right_arm_base_link" />
    <axis
      xyz="0 0 0" />
  </joint>
  <link
    name="right_arm_link1">
    <inertial>
      <origin
        xyz="-3.24321468574207E-05 -0.0169208473091281 -3.91830093831036E-05"
        rpy="0 0 0" />
      <mass
        value="0.3157339691478" />
      <inertia
        ixx="0.000355333070561494"
        ixy="-1.12251445571214E-06"
        ixz="-8.96327030265676E-07"
        iyy="0.000465495696286629"
        iyz="4.11555770442059E-07"
        izz="0.000358749747002376" />
    </inertial>
    <visual>
      <origin
        xyz="0 0 0"
        rpy="0 0 0" />
      <geometry>
        <mesh
          filename="../../meshes/Bessica_D_v1_0/withCover/right_arm_link1.STL" />
      </geometry>
      <material
        name="">
        <color
          rgba="0.796078431372549 0.823529411764706 0.937254901960784 1" />
      </material>
    </visual>
    <collision>
      <origin
        xyz="0 0 0"
        rpy="0 0 0" />
      <geometry>
        <mesh
          filename="../../meshes/Bessica_D_v1_0/withCover/right_arm_link1.STL" />
      </geometry>
    </collision>
  </link>
  <joint
    name="right_arm_joint1"
    type="revolute">
    <origin
      xyz="0 0.114500000000005 0"
      rpy="3.14159265358979 0 0" />
    <parent
      link="right_arm_base_link" />
    <child
      link="right_arm_link1" />
    <axis
      xyz="0 -1 0" />
    <limit
      lower="-2.14"
      upper="2.14"
      effort="5"
      velocity="12" />
  </joint>
  <link
    name="right_arm_link2">
    <inertial>
      <origin
        xyz="-0.0294208677882922 0.000476964264629454 -0.000518958897082481"
        rpy="0 0 0" />
      <mass
        value="0.0501482304791555" />
      <inertia
        ixx="7.68324123453959E-06"
        ixy="-5.76060636775063E-07"
        ixz="-1.43192461618645E-06"
        iyy="1.62270247131465E-05"
        iyz="1.34505028400584E-08"
        izz="1.55418254850871E-05" />
    </inertial>
    <visual>
      <origin
        xyz="0 0 0"
        rpy="0 0 0" />
      <geometry>
        <mesh
          filename="../../meshes/Bessica_D_v1_0/withCover/right_arm_link2.STL" />
      </geometry>
      <material
        name="">
        <color
          rgba="0.807843137254902 0.843137254901961 0.905882352941176 1" />
      </material>
    </visual>
    <collision>
      <origin
        xyz="0 0 0"
        rpy="0 0 0" />
      <geometry>
        <mesh
          filename="../../meshes/Bessica_D_v1_0/withCover/right_arm_link2.STL" />
      </geometry>
    </collision>
  </link>
  <joint
    name="right_arm_joint2"
    type="revolute">
    <origin
      xyz="0 -0.0428699999999995 0"
      rpy="-3.14159264133724 1.57079625690226 0" />
    <parent
      link="right_arm_link1" />
    <child
      link="right_arm_link2" />
    <axis
      xyz="0 0 -1" />
    <limit
      lower="-2.14"
      upper="2.14"
      effort="5"
      velocity="12" />
  </joint>
  <link
    name="right_arm_link3">
    <inertial>
      <origin
        xyz="-0.00598311053812289 4.94633393373142E-05 0.107926403527906"
        rpy="0 0 0" />
      <mass
        value="0.368447313337917" />
      <inertia
        ixx="0.00067108569280531"
        ixy="1.46838855377877E-08"
        ixz="-3.24538603955447E-05"
        iyy="0.00060342414221262"
        iyz="-7.1361626089816E-08"
        izz="0.000364264970999212" />
    </inertial>
    <visual>
      <origin
        xyz="0 0 0"
        rpy="0 0 0" />
      <geometry>
        <mesh
          filename="../../meshes/Bessica_D_v1_0/withCover/right_arm_link3.STL" />
      </geometry>
      <material
        name="">
        <color
          rgba="0.807843137254902 0.843137254901961 0.905882352941176 1" />
      </material>
    </visual>
    <collision>
      <origin
        xyz="0 0 0"
        rpy="0 0 0" />
      <geometry>
        <mesh
          filename="../../meshes/Bessica_D_v1_0/withCover/right_arm_link3.STL" />
      </geometry>
    </collision>
  </link>
  <joint
    name="right_arm_joint3"
    type="revolute">
    <origin
      xyz="-0.0639500000000018 -0.000100000000001099 -0.000399999996885698"
      rpy="1.57079632679464 0 -1.5707963267949" />
    <parent
      link="right_arm_link2" />
    <child
      link="right_arm_link3" />
    <axis
      xyz="0 0 1" />
    <limit
      lower="-2.14"
      upper="2.14"
      effort="5"
      velocity="12" />
  </joint>
  <link
    name="right_arm_link4">
    <inertial>
      <origin
        xyz="-0.000541938873679149 -0.0284058068549827 -0.000370347235469402"
        rpy="0 0 0" />
      <mass
        value="0.048007139134458" />
      <inertia
        ixx="1.64141913809997E-05"
        ixy="5.78456736280739E-07"
        ixz="-9.62946715665583E-09"
        iyy="7.5409381512228E-06"
        iyz="-1.52193904300628E-06"
        izz="1.5513339098241E-05" />
    </inertial>
    <visual>
      <origin
        xyz="0 0 0"
        rpy="0 0 0" />
      <geometry>
        <mesh
          filename="../../meshes/Bessica_D_v1_0/withCover/right_arm_link4.STL" />
      </geometry>
      <material
        name="">
        <color
          rgba="0.807843137254902 0.843137254901961 0.905882352941176 1" />
      </material>
    </visual>
    <collision>
      <origin
        xyz="0 0 0"
        rpy="0 0 0" />
      <geometry>
        <mesh
          filename="../../meshes/Bessica_D_v1_0/withCover/right_arm_link4.STL" />
      </geometry>
    </collision>
  </link>
  <joint
    name="right_arm_joint4"
    type="revolute">
    <origin
      xyz="0.00384000000000018 0 0.20261"
      rpy="-1.57079632679465 0 0" />
    <parent
      link="right_arm_link3" />
    <child
      link="right_arm_link4" />
    <axis
      xyz="0 0 -1" />
    <limit
      lower="-2.14"
      upper="2.14"
      effort="5"
      velocity="12" />
  </joint>
  <link
    name="right_arm_link5">
    <inertial>
      <origin
        xyz="-0.00628108914650888 0.00021285362579031 -0.0733506437231033"
        rpy="0 0 0" />
      <mass
        value="0.207077281082729" />
      <inertia
        ixx="0.000306349652131258"
        ixy="-2.73142529971129E-08"
        ixz="3.50645300826623E-05"
        iyy="0.000340615582191323"
        iyz="-3.40700219751777E-07"
        izz="0.000142891896252893" />
    </inertial>
    <visual>
      <origin
        xyz="0 0 0"
        rpy="0 0 0" />
      <geometry>
        <mesh
          filename="../../meshes/Bessica_D_v1_0/withCover/right_arm_link5.STL" />
      </geometry>
      <material
        name="">
        <color
          rgba="0.807843137254902 0.843137254901961 0.905882352941176 1" />
      </material>
    </visual>
    <collision>
      <origin
        xyz="0 0 0"
        rpy="0 0 0" />
      <geometry>
        <mesh
          filename="../../meshes/Bessica_D_v1_0/withCover/right_arm_link5.STL" />
      </geometry>
    </collision>
  </link>
  <joint
    name="right_arm_joint5"
    type="revolute">
    <origin
      xyz="0 -0.0639500000000002 0.000199999999992483"
      rpy="-1.57079632679515 0 0" />
    <parent
      link="right_arm_link4" />
    <child
      link="right_arm_link5" />
    <axis
      xyz="0 0 -1" />
    <limit
      lower="-2.14"
      upper="2.14"
      effort="5"
      velocity="12" />
  </joint>
  <link
    name="right_arm_link6">
    <inertial>
      <origin
        xyz="-0.000759194613459746 -0.0240065529819558 -5.58164371063984E-05"
        rpy="0 0 0" />
      <mass
        value="0.0325622574715594" />
      <inertia
        ixx="1.56755999138145E-05"
        ixy="1.61833904253333E-07"
        ixz="-7.68617040661809E-09"
        iyy="1.27877692587484E-05"
        iyz="-2.84599247552984E-08"
        izz="9.25035078924867E-06" />
    </inertial>
    <visual>
      <origin
        xyz="0 0 0"
        rpy="0 0 0" />
      <geometry>
        <mesh
          filename="../../meshes/Bessica_D_v1_0/withCover/right_arm_link6.STL" />
      </geometry>
      <material
        name="">
        <color
          rgba="0.807843137254902 0.843137254901961 0.905882352941176 1" />
      </material>
    </visual>
    <collision>
      <origin
        xyz="0 0 0"
        rpy="0 0 0" />
      <geometry>
        <mesh
          filename="../../meshes/Bessica_D_v1_0/withCover/right_arm_link6.STL" />
      </geometry>
    </collision>
  </link>
  <joint
    name="right_arm_joint6"
    type="revolute">
    <origin
      xyz="0.00378999999999963 5.00000000468472E-05 -0.1806"
      rpy="1.57079632679515 0 0" />
    <parent
      link="right_arm_link5" />
    <child
      link="right_arm_link6" />
    <axis
      xyz="0 0 1" />
    <limit
      lower="-2.14"
      upper="2.14"
      effort="5"
      velocity="12" />
  </joint>
  <link
    name="right_arm_link7">
    <inertial>
      <origin
        xyz="0.0410271822605306 -0.000104797361222926 -0.0275632955071975"
        rpy="0 0 0" />
      <mass
        value="0.130617660751133" />
      <inertia
        ixx="9.37555144818836E-05"
        ixy="-2.67295143369452E-08"
        ixz="-3.95378371535052E-06"
        iyy="4.22371579950213E-05"
        iyz="-1.83444197853209E-08"
        izz="8.40584344645817E-05" />
    </inertial>
    <visual>
      <origin
        xyz="0 0 0"
        rpy="0 0 0" />
      <geometry>
        <mesh
          filename="../../meshes/Bessica_D_v1_0/withCover/right_arm_link7.STL" />
      </geometry>
      <material
        name="">
        <color
          rgba="0.592156862745098 0.666666666666667 0.682352941176471 1" />
      </material>
    </visual>
    <collision>
      <origin
        xyz="0 0 0"
        rpy="0 0 0" />
      <geometry>
        <mesh
          filename="../../meshes/Bessica_D_v1_0/withCover/right_arm_link7.STL" />
      </geometry>
    </collision>
  </link>
  <joint
    name="right_arm_joint7"
    type="revolute">
    <origin
      xyz="0.000100000000024303 -0.0556000006666655 -9.99999999954217E-05"
      rpy="-1.57079632679513 0 -1.5707963267949" />
    <parent
      link="right_arm_link6" />
    <child
      link="right_arm_link7" />
    <axis
      xyz="0 0 1" />
    <limit
      lower="-2.14"
      upper="2.14"
      effort="5"
      velocity="12" />
  </joint>
  <link
    name="right_arm_gripper_left_finger">
    <inertial>
      <origin
        xyz="-0.0434086638781261 -1.54809455255034E-08 -0.0106596340340038"
        rpy="0 0 0" />
      <mass
        value="0.0256462690507917" />
      <inertia
        ixx="5.13427082573144E-06"
        ixy="2.44818388644314E-11"
        ixz="-1.26430153754371E-06"
        iyy="6.46826201248428E-06"
        iyz="-4.17381205497342E-13"
        izz="8.03606718172591E-06" />
    </inertial>
    <visual>
      <origin
        xyz="0 0 0"
        rpy="0 0 0" />
      <geometry>
        <mesh
          filename="../../meshes/Bessica_D_v1_0/withCover/right_arm_gripper_left_finger.STL" />
      </geometry>
      <material
        name="">
        <color
          rgba="0.592156862745098 0.666666666666667 0.682352941176471 1" />
      </material>
    </visual>
    <collision>
      <origin
        xyz="0 0 0"
        rpy="0 0 0" />
      <geometry>
        <mesh
          filename="../../meshes/Bessica_D_v1_0/withCover/right_arm_gripper_left_finger.STL" />
      </geometry>
    </collision>
  </link>
  <joint
    name="right_arm_gripper_joint1"
    type="fixed">
    <origin
      xyz="0.141279659620446 -0.0505000000000126 -0.000150000000035122"
      rpy="-1.57079632679466 0 0" />
    <parent
      link="right_arm_link7" />
    <child
      link="right_arm_gripper_left_finger" />
    <axis
      xyz="0 0 0" />
    <limit
      lower="0"
      upper="-0.05"
      effort="5"
      velocity="12" />
  </joint>
  <link
    name="right_arm_gripper_right_finger">
    <inertial>
      <origin
        xyz="-0.043408663878126 -1.54809454699922E-08 -0.0106596340340039"
        rpy="0 0 0" />
      <mass
        value="0.025646269050792" />
      <inertia
        ixx="5.1342708257315E-06"
        ixy="2.44818388777405E-11"
        ixz="-1.26430153754368E-06"
        iyy="6.4682620124843E-06"
        iyz="-4.17381216149094E-13"
        izz="8.03606718172598E-06" />
    </inertial>
    <visual>
      <origin
        xyz="0 0 0"
        rpy="0 0 0" />
      <geometry>
        <mesh
          filename="../../meshes/Bessica_D_v1_0/withCover/right_arm_gripper_right_finger.STL" />
      </geometry>
      <material
        name="">
        <color
          rgba="0.592156862745098 0.666666666666667 0.682352941176471 1" />
      </material>
    </visual>
    <collision>
      <origin
        xyz="0 0 0"
        rpy="0 0 0" />
      <geometry>
        <mesh
          filename="../../meshes/Bessica_D_v1_0/withCover/right_arm_gripper_right_finger.STL" />
      </geometry>
    </collision>
  </link>
  <joint
    name="right_arm_gripper_joint2"
    type="fixed">
    <origin
      xyz="0.141279659620446 0.050499999999987 -0.00015000000001425"
      rpy="1.57079632679513 0 0" />
    <parent
      link="right_arm_link7" />
    <child
      link="right_arm_gripper_right_finger" />
    <axis
      xyz="0 0 0" />
    <limit
      lower="0.05"
      upper="0"
      effort="5"
      velocity="12" />
  </joint>
 <link
    name="left_gripper_center">
    <!-- <inertial>
      <origin
        xyz="-0.567708783489947 0.00325239950363646 -0.250001266606243"
        rpy="0 0 0" /> -->
    <visual>
      <origin
        xyz="0 0 0"
        rpy="0 0 0" />
      <geometry>
        <sphere radius="0.005" />
      </geometry>
      <material
        name="green_virtual_sphere_material">
        <color
          rgba="0 1 0 1" />
      </material>
    </visual>
  </link>

  <joint
    name="right_gripper_joint"
    type="fixed">
    <origin
      xyz="0.14127965895378 0 -0.000150000000023076"
      rpy="-3.14159265358956 0 0" />
    <parent
      link="right_arm_link7" />
    <child
      link="right_gripper_center" />
    <axis
      xyz="0 0 0" />
  </joint>
  <link
    name="left_arm_base_link">
    <inertial>
      <origin
        xyz="1.6347368044371E-05 -0.00300662518201564 0.0103241813503003"
        rpy="0 0 0" />
      <mass
        value="0.760760214288355" />
      <inertia
        ixx="0.00140239578154612"
        ixy="1.37239409841342E-07"
        ixz="1.42916131747707E-07"
        iyy="0.00146104425718537"
        iyz="1.55314878250857E-05"
        izz="0.00186458776404591" />
    </inertial>
    <visual>
      <origin
        xyz="0 0 0"
        rpy="0 0 0" />
      <geometry>
        <mesh
          filename="../../meshes/Bessica_D_v1_0/withCover/left_arm_base_link.STL" />
      </geometry>
      <material
        name="">
        <color
          rgba="0.592156862745098 0.666666666666667 0.682352941176471 1" />
      </material>
    </visual>
    <collision>
      <origin
        xyz="0 0 0"
        rpy="0 0 0" />
      <geometry>
        <mesh
          filename="../../meshes/Bessica_D_v1_0/withCover/left_arm_base_link.STL" />
      </geometry>
    </collision>
  </link>
  <joint
    name="left_arm_base_joint"
    type="fixed">
    <origin
      xyz="0 -0.100000000333333 1.01500000133333"
      rpy="1.5707963267949 0 0" />
    <parent
      link="base_link" />
    <child
      link="left_arm_base_link" />
    <axis
      xyz="0 0 0" />
  </joint>
  <link
    name="left_arm_link1">
    <inertial>
      <origin
        xyz="3.24314962781516E-05 3.91850195176346E-05 0.0169208489159685"
        rpy="0 0 0" />
      <mass
        value="0.315733947117255" />
      <inertia
        ixx="0.000355333065420966"
        ixy="-8.96328098207904E-07"
        ixz="-1.12251532402765E-06"
        iyy="0.000358749744495488"
        iyz="4.11557020562811E-07"
        izz="0.000465495689650493" />
    </inertial>
    <visual>
      <origin
        xyz="0 0 0"
        rpy="0 0 0" />
      <geometry>
        <mesh
          filename="../../meshes/Bessica_D_v1_0/withCover/left_arm_link1.STL" />
      </geometry>
      <material
        name="">
        <color
          rgba="0.796078431372549 0.823529411764706 0.937254901960784 1" />
      </material>
    </visual>
    <collision>
      <origin
        xyz="0 0 0"
        rpy="0 0 0" />
      <geometry>
        <mesh
          filename="../../meshes/Bessica_D_v1_0/withCover/left_arm_link1.STL" />
      </geometry>
    </collision>
  </link>
  <joint
    name="left_arm_joint1"
    type="revolute">
    <origin
      xyz="0 0 0.1145"
      rpy="0 0 0" />
    <parent
      link="left_arm_base_link" />
    <child
      link="left_arm_link1" />
    <axis
      xyz="0 0 1" />
    <limit
      lower="-2.14"
      upper="2.14"
      effort="5"
      velocity="12" />
  </joint>
  <link
    name="left_arm_link2">
    <inertial>
      <origin
        xyz="-0.0294208664452417 0.000476964259329749 -0.000518958903691429"
        rpy="0 0 0" />
      <mass
        value="0.0501482304995307" />
      <inertia
        ixx="7.68324123570206E-06"
        ixy="-5.7606063498267E-07"
        ixz="-1.43192461955293E-06"
        iyy="1.62270247045509E-05"
        iyz="1.34505025118424E-08"
        izz="1.55418254808189E-05" />
    </inertial>
    <visual>
      <origin
        xyz="0 0 0"
        rpy="0 0 0" />
      <geometry>
        <mesh
          filename="../../meshes/Bessica_D_v1_0/withCover/left_arm_link2.STL" />
      </geometry>
      <material
        name="">
        <color
          rgba="0.807843137254902 0.843137254901961 0.905882352941176 1" />
      </material>
    </visual>
    <collision>
      <origin
        xyz="0 0 0"
        rpy="0 0 0" />
      <geometry>
        <mesh
          filename="../../meshes/Bessica_D_v1_0/withCover/left_arm_link2.STL" />
      </geometry>
    </collision>
  </link>
  <joint
    name="left_arm_joint2"
    type="revolute">
    <origin
      xyz="0 0 0.04287"
      rpy="1.57079632679489 0 1.5707963267949" />
    <parent
      link="left_arm_link1" />
    <child
      link="left_arm_link2" />
    <axis
      xyz="0 0 -1" />
    <limit
      lower="-2.14"
      upper="2.14"
      effort="5"
      velocity="12" />
  </joint>
  <link
    name="left_arm_link3">
    <inertial>
      <origin
        xyz="-0.0060702147964071 -7.96525933281031E-05 0.105091704714287"
        rpy="0 0 0" />
      <mass
        value="0.373333387538863" />
      <inertia
        ixx="0.000671566223902426"
        ixy="1.39420999698332E-08"
        ixz="-3.24356386877245E-05"
        iyy="0.000604631229031791"
        iyz="-7.14074904026189E-08"
        izz="0.0003658333287676" />
    </inertial>
    <visual>
      <origin
        xyz="0 0 0"
        rpy="0 0 0" />
      <geometry>
        <mesh
          filename="../../meshes/Bessica_D_v1_0/withCover/left_arm_link3.STL" />
      </geometry>
      <material
        name="">
        <color
          rgba="0.807843137254902 0.843137254901961 0.905882352941176 1" />
      </material>
    </visual>
    <collision>
      <origin
        xyz="0 0 0"
        rpy="0 0 0" />
      <geometry>
        <mesh
          filename="../../meshes/Bessica_D_v1_0/withCover/left_arm_link3.STL" />
      </geometry>
    </collision>
  </link>
  <joint
    name="left_arm_joint3"
    type="revolute">
    <origin
      xyz="-0.0657500000000001 -9.99999999995171E-05 -0.000400000003120824"
      rpy="1.5707963267949 0 -1.5707963267949" />
    <parent
      link="left_arm_link2" />
    <child
      link="left_arm_link3" />
    <axis
      xyz="0 0 1" />
    <limit
      lower="-2.14"
      upper="2.14"
      effort="5"
      velocity="12" />
  </joint>
  <link
    name="left_arm_link4">
    <inertial>
      <origin
        xyz="-0.000541938878732995 -0.0284058061970597 -0.000370347235388107"
        rpy="0 0 0" />
      <mass
        value="0.0480071391158089" />
      <inertia
        ixx="1.64141913891154E-05"
        ixy="5.78456737691363E-07"
        ixz="-9.62946752549522E-09"
        iyy="7.54093815008549E-06"
        iyz="-1.52193904000394E-06"
        izz="1.55133391025037E-05" />
    </inertial>
    <visual>
      <origin
        xyz="0 0 0"
        rpy="0 0 0" />
      <geometry>
        <mesh
          filename="../../meshes/Bessica_D_v1_0/withCover/left_arm_link4.STL" />
      </geometry>
      <material
        name="">
        <color
          rgba="0.807843137254902 0.843137254901961 0.905882352941176 1" />
      </material>
    </visual>
    <collision>
      <origin
        xyz="0 0 0"
        rpy="0 0 0" />
      <geometry>
        <mesh
          filename="../../meshes/Bessica_D_v1_0/withCover/left_arm_link4.STL" />
      </geometry>
    </collision>
  </link>
  <joint
    name="left_arm_joint4"
    type="revolute">
    <origin
      xyz="0.00383999999999432 0 0.20080999933334"
      rpy="-1.5707963267949 0 0" />
    <parent
      link="left_arm_link3" />
    <child
      link="left_arm_link4" />
    <axis
      xyz="0 0 1" />
    <limit
      lower="-2.14"
      upper="2.14"
      effort="5"
      velocity="12" />
  </joint>
  <link
    name="left_arm_link5">
    <inertial>
      <origin
        xyz="-0.00625732698958872 0.000212853305092465 -0.0763030662658679"
        rpy="0 0 0" />
      <mass
        value="0.207077276180107" />
      <inertia
        ixx="0.000306349645859208"
        ixy="-2.73143795587977E-08"
        ixz="3.50645299236523E-05"
        iyy="0.000340615577044975"
        iyz="-3.40698306916482E-07"
        izz="0.000142891895196546" />
    </inertial>
    <visual>
      <origin
        xyz="0 0 0"
        rpy="0 0 0" />
      <geometry>
        <mesh
          filename="../../meshes/Bessica_D_v1_0/withCover/left_arm_link5.STL" />
      </geometry>
      <material
        name="">
        <color
          rgba="0.807843137254902 0.843137254901961 0.905882352941176 1" />
      </material>
    </visual>
    <collision>
      <origin
        xyz="0 0 0"
        rpy="0 0 0" />
      <geometry>
        <mesh
          filename="../../meshes/Bessica_D_v1_0/withCover/left_arm_link5.STL" />
      </geometry>
    </collision>
  </link>
  <joint
    name="left_arm_joint5"
    type="revolute">
    <origin
      xyz="0 -0.0657500006666611 0.000199999999990721"
      rpy="-1.5707963267949 0 0" />
    <parent
      link="left_arm_link4" />
    <child
      link="left_arm_link5" />
    <axis
      xyz="0 0 -1" />
    <limit
      lower="-2.14"
      upper="2.14"
      effort="5"
      velocity="12" />
  </joint>
  <link
    name="left_arm_link6">
    <inertial>
      <origin
        xyz="-0.00075919461347998 -0.024006552315284 -5.58164371072249E-05"
        rpy="0 0 0" />
      <mass
        value="0.0325622574715583" />
      <inertia
        ixx="1.56755999138142E-05"
        ixy="1.61833904253336E-07"
        ixz="-7.68617040663822E-09"
        iyy="1.27877692587482E-05"
        iyz="-2.84599247551008E-08"
        izz="9.25035078924841E-06" />
    </inertial>
    <visual>
      <origin
        xyz="0 0 0"
        rpy="0 0 0" />
      <geometry>
        <mesh
          filename="../../meshes/Bessica_D_v1_0/withCover/left_arm_link6.STL" />
      </geometry>
      <material
        name="">
        <color
          rgba="0.807843137254902 0.843137254901961 0.905882352941176 1" />
      </material>
    </visual>
    <collision>
      <origin
        xyz="0 0 0"
        rpy="0 0 0" />
      <geometry>
        <mesh
          filename="../../meshes/Bessica_D_v1_0/withCover/left_arm_link6.STL" />
      </geometry>
    </collision>
  </link>
  <joint
    name="left_arm_joint6"
    type="revolute">
    <origin
      xyz="0.00379000000002061 5.00000000002069E-05 -0.17879999933334"
      rpy="1.5707963267949 0 0" />
    <parent
      link="left_arm_link5" />
    <child
      link="left_arm_link6" />
    <axis
      xyz="0 0 -1" />
    <limit
      lower="-2.14"
      upper="2.14"
      effort="5"
      velocity="12" />
  </joint>
  <link
    name="left_arm_link7">
    <inertial>
      <origin
        xyz="0.0408026542444621 -0.000102206604270802 -0.0271637511314085"
        rpy="0 0 0" />
      <mass
        value="0.134233364312826" />
      <inertia
        ixx="9.48394067897535E-05"
        ixy="-2.66849771333094E-08"
        ixz="-3.97199050560631E-06"
        iyy="4.30798330610582E-05"
        iyz="-1.89333961977832E-08"
        izz="8.43835119906452E-05" />
    </inertial>
    <visual>
      <origin
        xyz="0 0 0"
        rpy="0 0 0" />
      <geometry>
        <mesh
          filename="../../meshes/Bessica_D_v1_0/withCover/left_arm_link7.STL" />
      </geometry>
      <material
        name="">
        <color
          rgba="0.592156862745098 0.666666666666667 0.682352941176471 1" />
      </material>
    </visual>
    <collision>
      <origin
        xyz="0 0 0"
        rpy="0 0 0" />
      <geometry>
        <mesh
          filename="../../meshes/Bessica_D_v1_0/withCover/left_arm_link7.STL" />
      </geometry>
    </collision>
  </link>
  <joint
    name="left_arm_joint7"
    type="revolute">
    <origin
      xyz="9.99999999615753E-05 -0.0556000006666605 -9.99999999948057E-05"
      rpy="-1.57079632679513 0 -1.5707963267949" />
    <parent
      link="left_arm_link6" />
    <child
      link="left_arm_link7" />
    <axis
      xyz="0 0 -1" />
    <limit
      lower="-2.14"
      upper="2.14"
      effort="5"
      velocity="12" />
  </joint>
  <link
    name="left_arm_gripper_left_finger">
    <inertial>
      <origin
        xyz="-0.0434086646602379 -1.54642348093592E-08 -0.0106596340402454"
        rpy="0 0 0" />
      <mass
        value="0.0256462689646809" />
      <inertia
        ixx="5.13427082329405E-06"
        ixy="2.4466938335663E-11"
        ixz="-1.26430153296146E-06"
        iyy="6.46826191340513E-06"
        iyz="-4.18082754482212E-13"
        izz="8.03606708048574E-06" />
    </inertial>
    <visual>
      <origin
        xyz="0 0 0"
        rpy="0 0 0" />
      <geometry>
        <mesh
          filename="../../meshes/Bessica_D_v1_0/withCover/left_arm_gripper_left_finger.STL" />
      </geometry>
      <material
        name="">
        <color
          rgba="0.592156862745098 0.666666666666667 0.682352941176471 1" />
      </material>
    </visual>
    <collision>
      <origin
        xyz="0 0 0"
        rpy="0 0 0" />
      <geometry>
        <mesh
          filename="../../meshes/Bessica_D_v1_0/withCover/left_arm_gripper_left_finger.STL" />
      </geometry>
    </collision>
  </link>
  <joint
    name="left_arm_gripper_joint1"
    type="fixed">
    <origin
      xyz="0.141279659620444 -0.0505000000000146 -0.000149999999993239"
      rpy="-1.57079632679466 0 0" />
    <parent
      link="left_arm_link7" />
    <child
      link="left_arm_gripper_left_finger" />
    <axis
      xyz="0 0 0" />
    <limit
      lower="0.05"
      upper="0"
      effort="5"
      velocity="12" />
  </joint>
  <link
    name="left_arm_gripper_right_finger">
    <inertial>
      <origin
        xyz="-0.0434086645988102 -1.54744198288537E-08 -0.0106596340364537"
        rpy="0 0 0" />
      <mass
        value="0.0256462690106051" />
      <inertia
        ixx="5.13427082501838E-06"
        ixy="2.44760154920438E-11"
        ixz="-1.26430153583774E-06"
        iyy="6.4682619660796E-06"
        iyz="-4.17571995548422E-13"
        izz="8.03606713459143E-06" />
    </inertial>
    <visual>
      <origin
        xyz="0 0 0"
        rpy="0 0 0" />
      <geometry>
        <mesh
          filename="../../meshes/Bessica_D_v1_0/withCover/left_arm_gripper_right_finger.STL" />
      </geometry>
      <material
        name="">
        <color
          rgba="0.592156862745098 0.666666666666667 0.682352941176471 1" />
      </material>
    </visual>
    <collision>
      <origin
        xyz="0 0 0"
        rpy="0 0 0" />
      <geometry>
        <mesh
          filename="../../meshes/Bessica_D_v1_0/withCover/left_arm_gripper_right_finger.STL" />
      </geometry>
    </collision>
  </link>
  <joint
    name="left_arm_gripper_joint2"
    type="fixed">
    <origin
      xyz="0.141279659620445 0.0504999999999851 -0.000149999999972228"
      rpy="1.57079632679513 0 0" />
    <parent
      link="left_arm_link7" />
    <child
      link="left_arm_gripper_right_finger" />
    <axis
      xyz="0 0 0" />
  </joint>
  <link
    name="right_gripper_center">
    <!-- <inertial>
      <origin
        xyz="-0.567708783489944 -0.00255239950365633 -0.249378733393753"
        rpy="0 0 0" /> -->
    <visual>
      <origin
        xyz="0 0 0"
        rpy="0 0 0" />
      <geometry>
        <sphere radius="0.005" />
      </geometry>
      <material
        name="green_virtual_sphere_material">
        <color
          rgba="0 1 0 1" />
      </material>
    </visual>
  </link>

  <joint
    name="left_gripper_joint"
    type="fixed">
    <origin
      xyz="0.14128 0 -0.00015"
      rpy="-3.1416 0 0" />
    <parent
      link="left_arm_link7" />
    <child
      link="left_gripper_center" />
    <axis
      xyz="0 0 0" />
  </joint>
  <link
    name="head">
    <inertial>
      <origin
        xyz="-0.00247749465632648 -0.000216488006302029 -0.000252183296815235"
        rpy="0 0 0" />
      <mass
        value="0.048731326683931" />
      <inertia
        ixx="5.98156721802178E-05"
        ixy="2.48836385219022E-07"
        ixz="1.0824303836918E-07"
        iyy="5.83469219661141E-06"
        iyz="-1.06689291159939E-07"
        izz="5.93294337141664E-05" />
    </inertial>
    <visual>
      <origin
        xyz="0 0 0"
        rpy="0 0 0" />
      <geometry>
        <mesh
          filename="../../meshes/Bessica_D_v1_0/withCover/head.STL" />
      </geometry>
      <material
        name="">
        <color
          rgba="0.592156862745098 0.666666666666667 0.682352941176471 1" />
      </material>
    </visual>
    <collision>
      <origin
        xyz="0 0 0"
        rpy="0 0 0" />
      <geometry>
        <mesh
          filename="../../meshes/Bessica_D_v1_0/withCover/head.STL" />
      </geometry>
    </collision>
  </link>
  <joint
    name="head"
    type="fixed">
    <origin
      xyz="-0.058269 -0.0021593 1.1945"
      rpy="0 0 0" />
    <parent
      link="base_link" />
    <child
      link="head" />
    <axis
      xyz="0 0 0" />
  </joint>
</robot>