<mujoco model="Alicia_D_v5_6_gripper_50mm">
  <compiler angle="radian" meshdir="../../meshes/Alicia_D_v5_6/follower_standard/"/>

  <asset>
    <mesh name="base_link" file="base_link.STL"/>
    <mesh name="link1" file="link1.STL"/>
    <mesh name="link2" content_type="model/stl" file="link2.STL"/>
    <mesh name="link3" content_type="model/stl" file="link3.STL"/>
    <mesh name="link4" content_type="model/stl" file="link4.STL"/>
    <mesh name="link5" file="link5.STL"/>
    <mesh name="link6" content_type="model/stl" file="link6.STL"/>
    <mesh name="left_gripper_50mm" content_type="model/stl" file="left_gripper_50mm.STL"/>
    <mesh name="right_gripper_50mm" content_type="model/stl" file="right_gripper_50mm.STL"/>
    <texture builtin="gradient" height="100" rgb1=".4 .5 .6" rgb2="0 0 0" type="skybox" width="100" />
    <texture builtin="checker" height="100" name="texplane" rgb1="1 1 1" rgb2=".8 .9 1" type="2d" width="100" />
    <material name="MatPlane" reflectance="0.5" texrepeat="1 1" texture="texplane" texuniform="true" />
    <material name="white" rgba="1 1 1 1" shininess="0.5" specular="0.1" />
    <material name="black" rgba="0.15 0.15 0.15 1" shininess="0.2" specular="0.05" />
    <material name="invisible" rgba="1 1 1 0" shininess="0" specular="0" />
  </asset>

  <worldbody>
    <geom conaffinity="1" condim="3" contype="1" friction="1 .1 .1" group="2" material="MatPlane" name="floor" pos="0 0 0" rgba="0.8 0.9 0.8 1" size="10 10 0.125" type="plane" />
    <light castshadow="false" cutoff="100" diffuse="1 1 1" dir="-0 0 -1.3" directional="true" exponent="1" pos="0 0 1.3" specular=".1 .1 .1" />
    <body name="base_link" pos="0 0 0">
      <geom type="mesh" contype="0" conaffinity="0" group="1" density="0" rgba="0.15 0.15 0.15 1" mesh="base_link"/>
      <geom type="mesh" rgba="0.15 0.15 0.15 1" mesh="base_link"/>
      <body name="link1" pos="0 0 0.1295">
        <inertial pos="0.000230596 1.29045e-05 0.00303136" quat="0.501534 0.502707 -0.494443 0.501274" mass="0.195233" diaginertia="0.000339803 0.000258352 0.000149295"/>
        <joint name="Joint1" pos="0 0 0" axis="0 0 1" range="-2.749 2.749" actuatorfrcrange="-5 5"/>
        <geom type="mesh" contype="0" conaffinity="0" group="1" density="0" rgba="0.15 0.15 0.15 1" mesh="link1"/>
        <geom type="mesh" rgba="0.15 0.15 0.15 1" mesh="link1"/>
        <body name="link2" pos="0 0 0.04287" quat="0.499998 0.5 0.5 -0.500002">
          <inertial pos="-0.150589 0.000866069 -0.000650951" quat="0.680967 0.18776 0.185184 0.683182" mass="0.207034" diaginertia="0.00020571 0.000131041 0.000119814"/>
          <joint name="Joint2" pos="0 0 0" axis="0 0 1" range="-2 2" actuatorfrcrange="-5 5"/>
          <geom type="mesh" contype="0" conaffinity="0" group="1" density="0" rgba="0.15 0.15 0.15 1" mesh="link2"/>
          <geom type="mesh" rgba="0.15 0.15 0.15 1" mesh="link2"/>
          <body name="link3" pos="-0.22367 0.022492 -5e-05" quat="0.382681 0 0 0.923881">
            <inertial pos="0.00248144 -0.0557863 0.000269721" quat="0.505129 0.478686 -0.468559 0.544203" mass="0.0845576" diaginertia="8.09971e-05 7.62965e-05 2.81294e-05"/>
            <joint name="Joint3" pos="0 0 0" axis="0 0 1" range="-0.5 3.14159" actuatorfrcrange="-5 5"/>
            <geom type="mesh" contype="0" conaffinity="0" group="1" density="0" rgba="0.15 0.15 0.15 1" mesh="link3"/>
            <geom type="mesh" rgba="0.15 0.15 0.15 1" mesh="link3"/>
            <body name="link4" pos="-0.00211 -0.099 0.0002" quat="-2.59734e-06 2.59735e-06 0.707108 -0.707105">
              <inertial pos="0.000298365 -0.000601369 0.065974" quat="0.99997 0.000404214 0.00701296 -0.00329826" mass="0.0653696" diaginertia="7.0311e-05 6.8747e-05 1.68121e-05"/>
              <joint name="Joint4" pos="0 0 0" axis="0 0 -1" range="-2.79 2.79" actuatorfrcrange="-5 5"/>
              <geom type="mesh" contype="0" conaffinity="0" group="1" density="0" rgba="0.15 0.15 0.15 1" mesh="link4"/>
              <geom type="mesh" rgba="0.15 0.15 0.15 1" mesh="link4"/>
              <body name="link5" pos="0 -0.0005 0.12235" quat="0.707105 -0.707108 0 0">
                <inertial pos="-0.0113684 -0.0308687 0.00087045" quat="0.600148 -0.0147585 -0.0142327 0.799626" mass="0.0507639" diaginertia="2.56871e-05 1.81869e-05 1.72553e-05"/>
                <joint name="Joint5" pos="0 0 0" axis="0 0 -1" range="-1.57 1.57" actuatorfrcrange="-5 5"/>
                <geom type="mesh" contype="0" conaffinity="0" group="1" density="0" rgba="0.15 0.15 0.15 1" mesh="link5"/>
                <geom type="mesh" rgba="0.15 0.15 0.15 1" mesh="link5"/>
                <body name="link6" pos="-0.00385 -0.0575 0.001" quat="0.707105 -0.707108 0 0">
                  <inertial pos="-0.0274898 1.78816e-05 -0.0342551" quat="0.587235 0.586837 -0.394197 0.394189" mass="0.130365" diaginertia="8.46616e-05 7.44396e-05 3.53175e-05"/>
                  <joint name="Joint6" pos="0 0 0" axis="0 0 1" range="-3.14159 3.14159" actuatorfrcrange="-5 5"/>
                  <geom type="mesh" contype="0" conaffinity="0" group="1" density="0" rgba="0.15 0.15 0.15 1" mesh="link6"/>
                  <geom type="mesh" rgba="0.15 0.15 0.15 1" mesh="link6"/>
                  <geom size="0.005" pos="0.0002 0 -0.13098" contype="0" conaffinity="0" group="1" density="0" rgba="0 1 0 1"/>
                  <body name="left_gripper" pos="0.0002 0.0255 -0.13098" quat="0 0 0.707107 -0.707107">
                    <inertial pos="2.97088e-08 -0.0434088 -0.0106559" quat="0.402878 0.581113 -0.581114 0.402868" mass="0.0256461" diaginertia="8.50964e-06 6.4683e-06 4.66071e-06"/>
                    <joint name="left_finger" pos="0 0 0" axis="0 0 1" type="slide" range="0 0.025" actuatorfrcrange="-5 5"/>
                    <geom type="mesh" contype="0" conaffinity="0" group="1" density="0" rgba="0.15 0.15 0.15 1" mesh="left_gripper_50mm"/>
                    <geom type="mesh" rgba="0.15 0.15 0.15 1" mesh="left_gripper_50mm"/>
                  </body>
                  <body name="right_gripper" pos="0.0002 -0.0255 -0.13098" quat="0.707105 0.707108 0 0">
                    <inertial pos="2.97088e-08 0.0434088 0.0106559" quat="0.402868 0.581114 -0.581113 0.402878" mass="0.0256461" diaginertia="8.50964e-06 6.4683e-06 4.66071e-06"/>
                    <joint name="right_finger" pos="0 0 0" axis="0 0 1" type="slide" range="-0.025 0" actuatorfrcrange="-5 5"/>
                    <geom type="mesh" contype="0" conaffinity="0" group="1" density="0" rgba="0.15 0.15 0.15 1" mesh="right_gripper_50mm"/>
                    <geom type="mesh" rgba="0.15 0.15 0.15 1" mesh="right_gripper_50mm"/>
                  </body>
                </body>
              </body>
            </body>
          </body>
        </body>
      </body>
    </body>
  </worldbody>
  <contact>
    <exclude body1="base_link" body2="link1" />
    <exclude body1="link1" body2="link2" />
    <exclude body1="link2" body2="link3" />
    <exclude body1="link3" body2="link4" />
    <exclude body1="link4" body2="link5" />
    <exclude body1="link5" body2="link6" />
    <exclude body1="link6" body2="left_gripper" />
    <exclude body1="left_gripper" body2="right_gripper" />
  </contact>
</mujoco>
