<mujoco model="Alicia_D_v5_6_leader">
  <compiler angle="radian" meshdir="../../meshes/Alicia_D_v5_6/leader/"/>

  <asset>
    <mesh name="base_link" content_type="model/stl" file="base_link.STL"/>
    <mesh name="link1" content_type="model/stl" file="link1.STL"/>
    <mesh name="link2" content_type="model/stl" file="link2.STL"/>
    <mesh name="link3" content_type="model/stl" file="link3.STL"/>
    <mesh name="link4" content_type="model/stl" file="link4.STL"/>
    <mesh name="link5" content_type="model/stl" file="link5.STL"/>
    <mesh name="link6" content_type="model/stl" file="link6.STL"/>
    <texture builtin="gradient" height="100" rgb1=".4 .5 .6" rgb2="0 0 0" type="skybox" width="100" />
    <texture builtin="checker" height="100" name="texplane" rgb1="1 1 1" rgb2=".8 .9 1" type="2d" width="100" />
    <material name="MatPlane" reflectance="0.5" texrepeat="1 1" texture="texplane" texuniform="true" />
    <material name="white" rgba="1 1 1 1" shininess="0.5" specular="0.1" />
    <material name="black" rgba="0.15 0.15 0.15 1" shininess="0.2" specular="0.05" />
    <material name="invisible" rgba="1 1 1 0" shininess="0" specular="0" />
  </asset>

  <worldbody>
    <geom conaffinity="1" condim="3" contype="1" friction="1 .1 .1" group="2" material="MatPlane" name="floor" pos="0 0 0" rgba="0.8 0.9 0.8 1" size="10 10 0.125" type="plane" />
    <light castshadow="false" cutoff="100" diffuse="1 1 1" dir="-0 0 -1.3" directional="true" exponent="1" pos="0 0 1.3" specular=".1 .1 .1" />
    <body name="base_link" pos="0 0 0">
      <geom type="mesh" contype="0" conaffinity="0" group="1" density="0" rgba="0.15 0.15 0.15 1" mesh="base_link"/>
      <geom type="mesh" rgba="0.15 0.15 0.15 1" mesh="base_link"/>
      <body name="link1" pos="0 0 0.05085" quat="0.707107 0.707107 0 0">
        <inertial pos="-2.80403e-05 0.0195626 -0.0025162" quat="0.930394 0.366424 0.00442635 -0.00894704" mass="0.0243713" diaginertia="6.62423e-06 5.8811e-06 5.73995e-06"/>
        <joint name="joint1" pos="0 0 0" axis="0 1 0" range="-2.749 2.749" actuatorfrcrange="-5 5"/>
        <geom type="mesh" contype="0" conaffinity="0" group="1" density="0" rgba="0.15 0.15 0.15 1" mesh="link1"/>
        <geom type="mesh" rgba="0.15 0.15 0.15 1" mesh="link1"/>
        <body name="link2" pos="0 0.04286 -0.0003" quat="0 0.707107 0.707107 0">
          <inertial pos="0.105079 0.00201788 -0.000193248" quat="0.498033 0.477654 0.514169 0.509353" mass="0.095362" diaginertia="6.60825e-05 5.66505e-05 2.48985e-05"/>
          <joint name="joint2" pos="0 0 0" axis="0 0 -1" range="-1.75 1.75" actuatorfrcrange="-5 5"/>
          <geom type="mesh" contype="0" conaffinity="0" group="1" density="0" rgba="0.15 0.15 0.15 1" mesh="link2"/>
          <geom type="mesh" rgba="0.15 0.15 0.15 1" mesh="link2"/>
          <body name="link3" pos="0.1892 0.027452 0.001" quat="0.382681 0 0 -0.923881">
            <inertial pos="-0.0114876 -0.0328018 0.000119091" quat="0.604151 -0.0255667 -0.0365774 0.795619" mass="0.0548527" diaginertia="2.78971e-05 1.9525e-05 1.88322e-05"/>
            <joint name="joint3" pos="0 0 0" axis="0 0 -1" range="-0.6 2.2" actuatorfrcrange="-5 5"/>
            <geom type="mesh" contype="0" conaffinity="0" group="1" density="0" rgba="0.15 0.15 0.15 1" mesh="link3"/>
            <geom type="mesh" rgba="0.15 0.15 0.15 1" mesh="link3"/>
            <body name="link4" pos="-0.00389378 -0.0576 0.0005" quat="0.707107 0.707107 0 0">
              <inertial pos="0.000302577 -0.000654183 0.0662938" quat="0.999965 0.00134424 0.00709253 -0.00434056" mass="0.0644612" diaginertia="6.92187e-05 6.77552e-05 1.66713e-05"/>
              <joint name="joint4" pos="0 0 0" axis="0 0 -1" range="-2.79 2.79" actuatorfrcrange="-5 5"/>
              <geom type="mesh" contype="0" conaffinity="0" group="1" density="0" rgba="0.15 0.15 0.15 1" mesh="link4"/>
              <geom type="mesh" rgba="0.15 0.15 0.15 1" mesh="link4"/>
              <body name="link5" pos="0 0 0.12231" quat="0.707107 -0.707107 0 0">
                <inertial pos="-0.0107578 -0.0305542 0.000363115" quat="0.600719 -0.0156964 -0.0158002 0.79915" mass="0.0510331" diaginertia="2.66558e-05 1.87232e-05 1.78187e-05"/>
                <joint name="joint5" pos="0 0 0" axis="0 0 -1" range="-1.57 1.57" actuatorfrcrange="-5 5"/>
                <geom type="mesh" contype="0" conaffinity="0" group="1" density="0" rgba="0.15 0.15 0.15 1" mesh="link5"/>
                <geom type="mesh" rgba="0.15 0.15 0.15 1" mesh="link5"/>
                <body name="link6" pos="-0.0038938 -0.0575 0.0005" quat="0.707105 0.707108 0 0">
                  <inertial pos="-0.000627624 -7.97093e-05 0.0717231" quat="0.704853 0.00286502 0.00565058 0.709325" mass="0.148889" diaginertia="9.98502e-05 8.45586e-05 3.99573e-05"/>
                  <joint name="joint6" pos="0 0 0" axis="0 0 -1" range="-3.14159 3.14159" actuatorfrcrange="-5 5"/>
                  <geom type="mesh" contype="0" conaffinity="0" group="1" density="0" rgba="0.15 0.15 0.15 1" mesh="link6"/>
                  <geom type="mesh" rgba="0.15 0.15 0.15 1" mesh="link6"/>
                  <body name="tool0" pos="0 0 0.05">
                    <inertial pos="0 0 0" quat="1 0 0 0" mass="0.001" diaginertia="1e-08 1e-08 1e-08" />
                    <geom type="sphere" size="0.01" contype="0" conaffinity="0" group="1" density="0" rgba="1 0 0 0.5" />
                    <site name="tool0_site" pos="0 0 0" size="0.01" type="sphere" />
                  </body>
                </body>
              </body>
            </body>
          </body>
        </body>
      </body>
    </body>
  </worldbody>
  <contact>
    <exclude body1="base_link" body2="link1" />
    <exclude body1="link1" body2="link2" />
    <exclude body1="link2" body2="link3" />
    <exclude body1="link3" body2="link4" />
    <exclude body1="link4" body2="link5" />
    <exclude body1="link5" body2="link6" />
  </contact>
</mujoco>
