<mujoco model="Bessica_D_v1_1_skeleton">
  <compiler angle="radian" meshdir="../../meshes/Bessica_D_v1_1/SkeletonOnly/"/>

  <asset>
    <mesh name="base_link" file="base_link.STL"/>
    <mesh name="head" file="head.STL"/>
    <mesh name="right_arm_base_link" file="right_arm_base_link.STL"/>
    <mesh name="right_arm_link1" file="right_arm_link1.STL"/>
    <mesh name="right_arm_link2" file="right_arm_link2.STL"/>
    <mesh name="right_arm_link3" file="right_arm_link3.STL"/>
    <mesh name="right_arm_link4" file="right_arm_link4.STL"/>
    <mesh name="right_arm_link5" file="right_arm_link5.STL"/>
    <mesh name="right_arm_link6" file="right_arm_link6.STL"/>
    <mesh name="right_arm_link7" file="right_arm_link7.STL"/>
    <mesh name="right_arm_gripper_left_finger" file="right_arm_gripper_left_finger.STL"/>
    <mesh name="right_arm_gripper_right_finger" file="right_arm_gripper_right_finger.STL"/>
    <mesh name="left_arm_base_link" file="left_arm_base_link.STL"/>
    <mesh name="left_arm_link1" file="left_arm_link1.STL"/>
    <mesh name="left_arm_link2" file="left_arm_link2.STL"/>
    <mesh name="left_arm_link3" file="left_arm_link3.STL"/>
    <mesh name="left_arm_link4" file="left_arm_link4.STL"/>
    <mesh name="left_arm_link5" file="left_arm_link5.STL"/>
    <mesh name="left_arm_link6" file="left_arm_link6.STL"/>
    <mesh name="left_arm_link7" file="left_arm_link7.STL"/>
    <mesh name="left_arm_gripper_right_finger" file="left_arm_gripper_right_finger.STL"/>
    <mesh name="left_arm_gripper_left_finger" file="left_arm_gripper_left_finger.STL"/>
    <texture builtin="gradient" height="100" rgb1=".4 .5 .6" rgb2="0 0 0" type="skybox" width="100" />
    <texture builtin="checker" height="100" name="texplane" rgb1="1 1 1" rgb2=".8 .9 1" type="2d" width="100" />
    <material name="MatPlane" reflectance="0.5" texrepeat="1 1" texture="texplane" texuniform="true" />
    <material name="white" rgba="1 1 1 1" shininess="0.5" specular="0.1" />
    <material name="black" rgba="0.15 0.15 0.15 1" shininess="0.2" specular="0.05" />
    <material name="invisible" rgba="1 1 1 0" shininess="0" specular="0" />
  </asset>

  <worldbody>
    <geom conaffinity="1" condim="3" contype="1" friction="1 .1 .1" group="2" material="MatPlane" name="floor" pos="0 0 0" rgba="0.8 0.9 0.8 1" size="10 10 0.125" type="plane" />
    <light castshadow="false" cutoff="100" diffuse="1 1 1" dir="-0 0 -1.3" directional="true" exponent="1" pos="0 0 1.3" specular=".1 .1 .1" />
    <body name="base_link" pos="0 0 0" quat="1 0 0 0">
      <geom type="mesh" contype="0" conaffinity="0" group="1" density="0" rgba="0.7 0.7 0.7 1" mesh="base_link"/>
      <geom type="mesh" rgba="0.7 0.7 0.7 1" mesh="base_link"/>
      <geom pos="0.0608245 0.00175926 0.700041" type="mesh" contype="0" conaffinity="0" group="1" density="0" rgba="0.7 0.7 0.7 1" mesh="head"/>
      <geom pos="0.0608245 0.00175926 0.700041" type="mesh" rgba="0.7 0.7 0.7 1" mesh="head"/>
      <geom pos="-5.01018e-07 -0.0899997 0.514501" quat="1.34924e-11 -3.67321e-06 -1 3.67321e-06" type="mesh" contype="0" conaffinity="0" group="1" density="0" rgba="0.15 0.15 0.15 1" mesh="right_arm_base_link"/>
      <geom pos="-5.01018e-07 -0.0899997 0.514501" quat="1.34924e-11 -3.67321e-06 -1 3.67321e-06" type="mesh" rgba="0.15 0.15 0.15 1" mesh="right_arm_base_link"/>
      <geom pos="8.16691e-09 0.09 0.5145" quat="0 0 -0.707107 -0.707107" type="mesh" contype="0" conaffinity="0" group="1" density="0" rgba="0.15 0.15 0.15 1" mesh="left_arm_base_link"/>
      <geom pos="8.16691e-09 0.09 0.5145" quat="0 0 -0.707107 -0.707107" type="mesh" rgba="0.15 0.15 0.15 1" mesh="left_arm_base_link"/>
      <body name="right_arm_link1" pos="4.86521e-05 -0.2046 0.514502" quat="1.34924e-11 -3.67321e-06 -1 3.67321e-06">
        <inertial pos="0.000110932 -0.00312062 0.000177905" quat="0.503324 0.499404 0.49881 0.498447" mass="0.208266" diaginertia="0.00034002 0.000262863 0.000150646"/>
        <joint name="right_arm_joint1" pos="0 0 0" axis="0 -1 0" range="-2.749 2.749" actuatorfrcrange="-5 5"/>
        <geom type="mesh" contype="0" conaffinity="0" group="1" density="0" rgba="0.15 0.15 0.15 1" mesh="right_arm_link1"/>
        <geom type="mesh" rgba="0.15 0.15 0.15 1" mesh="right_arm_link1"/>
        <body name="right_arm_link2" pos="0 -0.04286 0" quat="0.707105 0 0.707108 0">
          <inertial pos="-0.0297081 -0.000293736 -0.000469869" quat="0.480696 0.536148 0.512721 0.46754" mass="0.0472691" diaginertia="1.62077e-05 1.58746e-05 7.75482e-06"/>
          <joint name="right_arm_joint2" pos="0 0 0" axis="0 0 1" range="-0.1 3.1416" actuatorfrcrange="-5 5"/>
          <geom type="mesh" contype="0" conaffinity="0" group="1" density="0" rgba="0.15 0.15 0.15 1" mesh="right_arm_link2"/>
          <geom type="mesh" rgba="0.15 0.15 0.15 1" mesh="right_arm_link2"/>
          <body name="right_arm_link3" pos="-0.06455 0 -0.0003" quat="-2.59734e-06 0.707105 -2.59735e-06 -0.707108">
            <inertial pos="-0.00359313 -0.000221911 0.094469" quat="0.709839 0.0300787 0.0347342 0.702864" mass="0.140452" diaginertia="8.80484e-05 7.8681e-05 5.52303e-05"/>
            <joint name="right_arm_joint3" pos="0 0 0" axis="0 0 1" range="-2.79 2.79" actuatorfrcrange="-5 5"/>
            <geom type="mesh" contype="0" conaffinity="0" group="1" density="0" rgba="0.15 0.15 0.15 1" mesh="right_arm_link3"/>
            <geom type="mesh" rgba="0.15 0.15 0.15 1" mesh="right_arm_link3"/>
            <body name="right_arm_link4" pos="-1.8989e-05 -4.9997e-05 0.1816" quat="0.499998 0.5 0.5 -0.500002">
              <inertial pos="-2.80229e-05 0.0241583 4.84136e-05" quat="1 0 0 -0.000169427" mass="0.0427207" diaginertia="1.04868e-05 8.49768e-06 8.00565e-06"/>
              <joint name="right_arm_joint4" pos="0 0 0" axis="0 0 1" range="-0.5236 2.95" actuatorfrcrange="-5 5"/>
              <geom type="mesh" contype="0" conaffinity="0" group="1" density="0" rgba="0.15 0.15 0.15 1" mesh="right_arm_link4"/>
              <geom type="mesh" rgba="0.15 0.15 0.15 1" mesh="right_arm_link4"/>
              <body name="right_arm_link5" pos="0 0.0488 0.000100003" quat="-0.5 0.5 0.5 0.5">
                <inertial pos="-0.00180911 -0.000196778 0.0430793" quat="0.96714 0.0368465 0.108778 0.226828" mass="0.110397" diaginertia="8.7423e-05 8.69117e-05 4.35431e-05"/>
                <joint name="right_arm_joint5" pos="0 0 0" axis="0 0 1" range="-2.79 2.79" actuatorfrcrange="-5 5"/>
                <geom type="mesh" contype="0" conaffinity="0" group="1" density="0" rgba="0.15 0.15 0.15 1" mesh="right_arm_link5"/>
                <geom type="mesh" rgba="0.15 0.15 0.15 1" mesh="right_arm_link5"/>
                <body name="right_arm_link6" pos="0.00289 -0.0020761 0.10801" quat="0.707105 -0.707108 0 0">
                  <inertial pos="0.000365898 -0.0257376 -4.10017e-05" quat="0.999601 0.00397576 0.000622093 -0.0279465" mass="0.0345707" diaginertia="1.56449e-05 1.27188e-05 9.19996e-06"/>
                  <joint name="right_arm_joint6" pos="0 0 0" axis="0 0 -1" range="-1.675 1.675" actuatorfrcrange="-5 5"/>
                  <geom type="mesh" contype="0" conaffinity="0" group="1" density="0" rgba="0.15 0.15 0.15 1" mesh="right_arm_link6"/>
                  <geom type="mesh" rgba="0.15 0.15 0.15 1" mesh="right_arm_link6"/>
                  <body name="right_arm_link7" pos="-0.0015 -0.05561 0" quat="0.499998 0.5 -0.500002 -0.5">
                    <inertial pos="0.0415076 -0.000152826 0.0262967" quat="0.698357 0.698702 -0.109714 0.109886" mass="0.134443" diaginertia="9.59304e-05 8.33778e-05 4.31456e-05"/>
                    <joint name="right_arm_joint7" pos="0 0 0" axis="0 0 1" range="-1.448 1.448" actuatorfrcrange="-5 5"/>
                    <geom type="mesh" contype="0" conaffinity="0" group="1" density="0" rgba="0.15 0.15 0.15 1" mesh="right_arm_link7"/>
                    <geom type="mesh" rgba="0.15 0.15 0.15 1" mesh="right_arm_link7"/>
                    <geom pos="0.14128 -0.0505 0.00015" quat="0.707105 -0.707108 0 0" type="mesh" contype="0" conaffinity="0" group="1" density="0" rgba="0.15 0.15 0.15 1" mesh="right_arm_gripper_left_finger"/>
                    <geom pos="0.14128 -0.0505 0.00015" quat="0.707105 -0.707108 0 0" type="mesh" rgba="0.15 0.15 0.15 1" mesh="right_arm_gripper_left_finger"/>
                    <geom pos="0.14128 0.0505 0.00015" quat="0.707105 0.707108 0 0" type="mesh" contype="0" conaffinity="0" group="1" density="0" rgba="0.15 0.15 0.15 1" mesh="right_arm_gripper_right_finger"/>
                    <geom pos="0.14128 0.0505 0.00015" quat="0.707105 0.707108 0 0" type="mesh" rgba="0.15 0.15 0.15 1" mesh="right_arm_gripper_right_finger"/>
                    <geom size="0.005" pos="0.14128 0 0.00015" contype="0" conaffinity="0" group="1" density="0" rgba="0 1 0 1"/>
                    <!-- Gripper center site (between fingers) -->
                    <site name="ik_offset_right_gripper" pos="0.14128 0 0.00015" size="0.005" rgba="1 0 0 0.5" />
                  </body>
                </body>
              </body>
            </body>
          </body>
        </body>
      </body>
      <body name="left_arm_link1" pos="-4.99893e-05 0.2046 0.5145" quat="0 0 -0.707107 0.707107">
        <inertial pos="-0.000114066 0.000187361 -0.00370369" quat="-0.000282854 0.70515 -0.00280194 0.709053" mass="0.197841" diaginertia="0.000335797 0.000260031 0.000148034"/>
        <joint name="left_arm_joint1" pos="0 0 0" axis="0 0 1" range="-2.749 2.749" actuatorfrcrange="-5 5"/>
        <geom type="mesh" contype="0" conaffinity="0" group="1" density="0" rgba="0.15 0.15 0.15 1" mesh="left_arm_link1"/>
        <geom type="mesh" rgba="0.15 0.15 0.15 1" mesh="left_arm_link1"/>
        <body name="left_arm_link2" pos="0 0 -0.04286" quat="0.5 0.5 -0.5 -0.5">
          <inertial pos="-0.0297081 -0.000293734 -0.000469873" quat="0.480696 0.536148 0.512721 0.46754" mass="0.0472691" diaginertia="1.62077e-05 1.58746e-05 7.75482e-06"/>
          <joint name="left_arm_joint2" pos="0 0 0" axis="0 0 1" range="-0.1 3.14159" actuatorfrcrange="-5 5"/>
          <geom type="mesh" contype="0" conaffinity="0" group="1" density="0" rgba="0.15 0.15 0.15 1" mesh="left_arm_link2"/>
          <geom type="mesh" rgba="0.15 0.15 0.15 1" mesh="left_arm_link2"/>
          <body name="left_arm_link3" pos="-0.06455 0 -0.000299996" quat="0.707107 0 -0.707107 0">
            <inertial pos="-0.00359314 -0.000221914 0.094469" quat="0.709839 0.0300787 0.0347342 0.702864" mass="0.140452" diaginertia="8.80484e-05 7.8681e-05 5.52303e-05"/>
            <joint name="left_arm_joint3" pos="0 0 0" axis="0 0 -1" range="-2.79 2.79" actuatorfrcrange="-5 5"/>
            <geom type="mesh" contype="0" conaffinity="0" group="1" density="0" rgba="0.15 0.15 0.15 1" mesh="left_arm_link3"/>
            <geom type="mesh" rgba="0.15 0.15 0.15 1" mesh="left_arm_link3"/>
            <body name="left_arm_link4" pos="-1.89942e-05 -5e-05 0.1816" quat="0.5 0.5 -0.5 0.5">
              <inertial pos="2.80229e-05 -0.0241582 4.84136e-05" quat="1 0 0 -0.000169427" mass="0.0427207" diaginertia="1.04868e-05 8.49768e-06 8.00565e-06"/>
              <joint name="left_arm_joint4" pos="0 0 0" axis="0 0 1" range="-0.5236 2.95" actuatorfrcrange="-5 5"/>
              <geom type="mesh" contype="0" conaffinity="0" group="1" density="0" rgba="0.15 0.15 0.15 1" mesh="left_arm_link4"/>
              <geom type="mesh" rgba="0.15 0.15 0.15 1" mesh="left_arm_link4"/>
              <body name="left_arm_link5" pos="0 -0.0488 0.0001" quat="0.5 0.5 0.5 -0.5">
                <inertial pos="-0.00180911 -0.000196785 0.0430793" quat="0.96714 0.0368465 0.108778 0.226827" mass="0.110397" diaginertia="8.7423e-05 8.69117e-05 4.35431e-05"/>
                <joint name="left_arm_joint5" pos="0 0 0" axis="0 0 -1" range="-2.79 2.79" actuatorfrcrange="-5 5"/>
                <geom type="mesh" contype="0" conaffinity="0" group="1" density="0" rgba="0.15 0.15 0.15 1" mesh="left_arm_link5"/>
                <geom type="mesh" rgba="0.15 0.15 0.15 1" mesh="left_arm_link5"/>
                <body name="left_arm_link6" pos="0.00289 -0.00207607 0.10801" quat="0.707107 -0.707107 0 0">
                  <inertial pos="0.000365898 -0.0257376 -4.10017e-05" quat="0.999601 0.00397576 0.000622093 -0.0279465" mass="0.0345707" diaginertia="1.56449e-05 1.27188e-05 9.19996e-06"/>
                  <joint name="left_arm_joint6" pos="0 0 0" axis="0 0 -1" range="-1.675 1.675" actuatorfrcrange="-5 5"/>
                  <geom type="mesh" contype="0" conaffinity="0" group="1" density="0" rgba="0.15 0.15 0.15 1" mesh="left_arm_link6"/>
                  <geom type="mesh" rgba="0.15 0.15 0.15 1" mesh="left_arm_link6"/>
                  <body name="left_arm_link7" pos="-0.0015 -0.0563101 0.00415239" quat="0.5 0.5 -0.5 -0.5">
                    <inertial pos="0.0410511 -0.00430969 0.0266716" quat="0.697385 0.697718 -0.115769 0.115941" mass="0.130828" diaginertia="9.49108e-05 8.29883e-05 4.23029e-05"/>
                    <joint name="left_arm_joint7" pos="0 0 0" axis="0 0 -1" range="-1.448 1.448" actuatorfrcrange="-5 5"/>
                    <geom type="mesh" contype="0" conaffinity="0" group="1" density="0" rgba="0.15 0.15 0.15 1" mesh="left_arm_link7"/>
                    <geom type="mesh" rgba="0.15 0.15 0.15 1" mesh="left_arm_link7"/>
                    <geom pos="0.14058 -0.054652 0.00015" quat="0.707105 -0.707108 0 0" type="mesh" contype="0" conaffinity="0" group="1" density="0" rgba="0.15 0.15 0.15 1" mesh="left_arm_gripper_left_finger"/>
                    <geom pos="0.14058 -0.054652 0.00015" quat="0.707105 -0.707108 0 0" type="mesh" rgba="0.15 0.15 0.15 1" mesh="left_arm_gripper_left_finger"/>
                    <geom pos="0.14058 0.046348 0.00015" quat="0.707105 0.707108 0 0" type="mesh" contype="0" conaffinity="0" group="1" density="0" rgba="0.15 0.15 0.15 1" mesh="left_arm_gripper_right_finger"/>
                    <geom pos="0.14058 0.046348 0.00015" quat="0.707105 0.707108 0 0" type="mesh" rgba="0.15 0.15 0.15 1" mesh="left_arm_gripper_right_finger"/>
                    <geom size="0.005" pos="0.14058 -0.0041524 0.00015" contype="0" conaffinity="0" group="1" density="0" rgba="0 1 0 1"/>
                    <!-- Gripper center site (between fingers) -->
                    <site name="ik_offset_left_gripper" pos="0.14058 -0.0041524 0.00015" size="0.005" rgba="0 0 1 0.5" />
                  </body>
                </body>
              </body>
            </body>
          </body>
        </body>
      </body>
    </body>

    <!-- Interactive mocap targets for IK visualization -->
    <!-- Left arm target: Red coordinate frame -->
    <body name="ik_target_left_gripper" mocap="true" pos="0.4 0.3 1.2">
      <!-- X axis - Red -->
      <geom type="cylinder" size="0.003 0.05" rgba="1 0 0 0.8" contype="0" conaffinity="0" fromto="0 0 0 0.1 0 0" />
      <geom type="sphere" size="0.008" rgba="1 0 0 0.9" contype="0" conaffinity="0" pos="0.1 0 0" />
      <!-- Y axis - Green -->
      <geom type="cylinder" size="0.003 0.05" rgba="0 1 0 0.8" contype="0" conaffinity="0" fromto="0 0 0 0 0.1 0" />
      <geom type="sphere" size="0.008" rgba="0 1 0 0.9" contype="0" conaffinity="0" pos="0 0.1 0" />
      <!-- Z axis - Blue -->
      <geom type="cylinder" size="0.003 0.05" rgba="0 0 1 0.8" contype="0" conaffinity="0" fromto="0 0 0 0 0 0.1" />
      <geom type="sphere" size="0.008" rgba="0 0 1 0.9" contype="0" conaffinity="0" pos="0 0 0.1" />
      <!-- Origin sphere -->
      <geom type="sphere" size="0.015" rgba="1 0.5 0.5 0.6" contype="0" conaffinity="0" pos="0 0 0" />
    </body>

    <!-- Right arm target: Blue coordinate frame -->
    <body name="ik_target_right_gripper" mocap="true" pos="0.4 -0.3 1.2">
      <!-- X axis - Red -->
      <geom type="cylinder" size="0.003 0.05" rgba="1 0 0 0.8" contype="0" conaffinity="0" fromto="0 0 0 0.1 0 0" />
      <geom type="sphere" size="0.008" rgba="1 0 0 0.9" contype="0" conaffinity="0" pos="0.1 0 0" />
      <!-- Y axis - Green -->
      <geom type="cylinder" size="0.003 0.05" rgba="0 1 0 0.8" contype="0" conaffinity="0" fromto="0 0 0 0 0.1 0" />
      <geom type="sphere" size="0.008" rgba="0 1 0 0.9" contype="0" conaffinity="0" pos="0 0.1 0" />
      <!-- Z axis - Blue -->
      <geom type="cylinder" size="0.003 0.05" rgba="0 0 1 0.8" contype="0" conaffinity="0" fromto="0 0 0 0 0 0.1" />
      <geom type="sphere" size="0.008" rgba="0 0 1 0.9" contype="0" conaffinity="0" pos="0 0 0.1" />
      <!-- Origin sphere -->
      <geom type="sphere" size="0.015" rgba="0.5 0.5 1 0.6" contype="0" conaffinity="0" pos="0 0 0" />
    </body>

    <!-- Center target: Green coordinate frame -->
    <body name="ik_target_center" mocap="true" pos="0.4 0.0 1.2">
      <!-- X axis - Red -->
      <geom type="cylinder" size="0.0025 0.04" rgba="1 0 0 0.8" contype="0" conaffinity="0" fromto="0 0 0 0.08 0 0" />
      <geom type="sphere" size="0.006" rgba="1 0 0 0.9" contype="0" conaffinity="0" pos="0.08 0 0" />
      <!-- Y axis - Green -->
      <geom type="cylinder" size="0.0025 0.04" rgba="0 1 0 0.8" contype="0" conaffinity="0" fromto="0 0 0 0 0.08 0" />
      <geom type="sphere" size="0.006" rgba="0 1 0 0.9" contype="0" conaffinity="0" pos="0 0.08 0" />
      <!-- Z axis - Blue -->
      <geom type="cylinder" size="0.0025 0.04" rgba="0 0 1 0.8" contype="0" conaffinity="0" fromto="0 0 0 0 0 0.08" />
      <geom type="sphere" size="0.006" rgba="0 0 1 0.9" contype="0" conaffinity="0" pos="0 0 0.08" />
      <!-- Origin sphere -->
      <geom type="sphere" size="0.012" rgba="0.5 1 0.5 0.6" contype="0" conaffinity="0" pos="0 0 0" />
    </body>
  </worldbody>

  <contact>
    <exclude body1="base_link" body2="left_arm_link1" />
    <exclude body1="left_arm_link1" body2="left_arm_link2" />
    <exclude body1="left_arm_link1" body2="left_arm_link3" />
    <exclude body1="left_arm_link2" body2="left_arm_link3" />
    <exclude body1="left_arm_link3" body2="left_arm_link4" />
    <exclude body1="left_arm_link4" body2="left_arm_link5" />
    <exclude body1="left_arm_link5" body2="left_arm_link6" />
    <exclude body1="left_arm_link6" body2="left_arm_link7" />

    <exclude body1="base_link" body2="right_arm_link1" />
    <exclude body1="right_arm_link1" body2="right_arm_link2" />
    <exclude body1="right_arm_link1" body2="right_arm_link3" />
    <exclude body1="right_arm_link2" body2="right_arm_link3" />
    <exclude body1="right_arm_link3" body2="right_arm_link4" />
    <exclude body1="right_arm_link4" body2="right_arm_link5" />
    <exclude body1="right_arm_link5" body2="right_arm_link6" />
    <exclude body1="right_arm_link6" body2="right_arm_link7" />
  </contact>

</mujoco>
