<mujoco model="Bessica_D_v1_0_Interactive">
  <compiler angle="radian" meshdir="../../meshes/Bessica_D_v1_0/withCover/" />
  <statistic center="-0.012496 0.000424702 0.622672" extent="1.93611" meansize="0.179951" />

  <asset>
    <mesh name="base_link" file="base_link.STL" />
    <mesh name="right_arm_base_link" file="right_arm_base_link.STL" />
    <mesh name="right_arm_link1" file="right_arm_link1.STL" />
    <mesh name="right_arm_link2" file="right_arm_link2.STL" />
    <mesh name="right_arm_link3" file="right_arm_link3.STL" />
    <mesh name="right_arm_link4" file="right_arm_link4.STL" />
    <mesh name="right_arm_link5" file="right_arm_link5.STL" />
    <mesh name="right_arm_link6" file="right_arm_link6.STL" />
    <mesh name="right_arm_link7" file="right_arm_link7.STL" />
    <mesh name="right_arm_gripper_left_finger" file="right_arm_gripper_left_finger.STL" />
    <mesh name="right_arm_gripper_right_finger" file="right_arm_gripper_right_finger.STL" />
    <mesh name="left_arm_base_link" file="left_arm_base_link.STL" />
    <mesh name="left_arm_link1" file="left_arm_link1.STL" />
    <mesh name="left_arm_link2" file="left_arm_link2.STL" />
    <mesh name="left_arm_link3" file="left_arm_link3.STL" />
    <mesh name="left_arm_link4" file="left_arm_link4.STL" />
    <mesh name="left_arm_link5" file="left_arm_link5.STL" />
    <mesh name="left_arm_link6" file="left_arm_link6.STL" />
    <mesh name="left_arm_link7" file="left_arm_link7.STL" />
    <mesh name="left_arm_gripper_left_finger" file="left_arm_gripper_left_finger.STL" />
    <mesh name="left_arm_gripper_right_finger" file="left_arm_gripper_right_finger.STL" />
    <mesh name="head" file="head.STL" />
    <texture builtin="gradient" height="100" rgb1=".4 .5 .6" rgb2="0 0 0" type="skybox" width="100" />
    <texture builtin="checker" height="100" name="texplane" rgb1="1 1 1" rgb2=".8 .9 1" type="2d" width="100" />
    <material name="MatPlane" reflectance="0.5" texrepeat="1 1" texture="texplane" texuniform="true" />
    <material name="white" rgba="1 1 1 1" shininess="0.5" specular="0.1" />
    <material name="black" rgba="0.15 0.15 0.15 1" shininess="0.2" specular="0.05" />
    <material name="invisible" rgba="1 1 1 0" shininess="0" specular="0" />
  </asset>

  <worldbody>
    <geom conaffinity="1" condim="3" contype="1" friction="1 .1 .1" group="2" material="MatPlane" name="floor" pos="0 0 0" rgba="0.8 0.9 0.8 1" size="500 500 0.125" type="plane" />
    <light castshadow="false" cutoff="100" diffuse="1 1 1" dir="-0 0 -1.3" directional="true" exponent="1" pos="0 0 1.3" specular=".1 .1 .1" />
    <body name="base_link" pos="0 0 0">
      <inertial pos="0 0 0.5075" quat="1 0 0 0" mass="10.0" diaginertia="0.0825 0.0825 0.1375"/>
      <geom type="mesh" contype="0" conaffinity="0" group="1" density="0" rgba="0.807843 0.843137 0.905882 1" mesh="base_link"/>
      <!-- <geom type="mesh" rgba="0.807843 0.843137 0.905882 1" mesh="base_link"/> -->
      <geom pos="0 0.1 1.015" quat="1 0 0 0" type="mesh" contype="0" conaffinity="0" group="1" density="0" rgba="0.592157 0.666667 0.682353 1" mesh="right_arm_base_link"/>
      <geom pos="0 0.1 1.015" quat="1 0 0 0" type="mesh" rgba="0.592157 0.666667 0.682353 1" mesh="right_arm_base_link"/>
      <geom pos="0 -0.1 1.015" quat="0.707107 0.707107 0 0" type="mesh" contype="0" conaffinity="0" group="1" density="0" rgba="0.592157 0.666667 0.682353 1" mesh="left_arm_base_link"/>
      <geom pos="0 -0.1 1.015" quat="0.707107 0.707107 0 0" type="mesh" rgba="0.592157 0.666667 0.682353 1" mesh="left_arm_base_link"/>
      <geom pos="-0.058269 -0.0021593 1.1945" quat="1 0 0 0" type="mesh" contype="0" conaffinity="0" group="1" density="0" rgba="0.592157 0.666667 0.682353 1" mesh="head"/>
      <geom pos="-0.058269 -0.0021593 1.1945" quat="1 0 0 0" type="mesh" rgba="0.592157 0.666667 0.682353 1" mesh="head"/>
      <body name="right_arm_link1" pos="0 0.2145 1.015" quat="0 1 0 0">
        <inertial pos="-3.24321e-05 -0.0169208 -3.9183e-05" quat="0.552553 0.435403 0.437672 0.559958" mass="0.315734" diaginertia="0.000465509 0.000358966 0.000355103"/>
        <joint name="right_arm_joint1" pos="0 0 0" axis="0 -1 0" range="-2.14 2.14" actuatorfrcrange="-5 5"/>
        <geom type="mesh" contype="0" conaffinity="0" group="1" density="0" rgba="0.796078 0.823529 0.937255 1" mesh="right_arm_link1"/>
        <geom type="mesh" rgba="0.796078 0.823529 0.937255 1" mesh="right_arm_link1"/>
        <body name="right_arm_link2" pos="0 -0.04287 0" quat="4.33193e-09 -0.707107 4.33193e-09 0.707107">
          <inertial pos="-0.0294209 0.000476964 -0.000518959" quat="0.461025 0.487356 0.419718 0.611373" mass="0.0501482" diaginertia="1.62891e-05 1.57687e-05 7.39432e-06"/>
          <joint name="right_arm_joint2" pos="0 0 0" axis="0 0 -1" range="-2.14 2.14" actuatorfrcrange="-5 5"/>
          <geom type="mesh" contype="0" conaffinity="0" group="1" density="0" rgba="0.807843 0.843137 0.905882 1" mesh="right_arm_link2"/>
          <geom type="mesh" rgba="0.807843 0.843137 0.905882 1" mesh="right_arm_link2"/>
          <body name="right_arm_link3" pos="-0.06395 -0.0001 -0.0004" quat="0.5 0.5 -0.5 -0.5">
            <inertial pos="-0.00598311 4.94633e-05 0.107926" quat="0.998642 -0.000134887 0.0520953 0.000162259" mass="0.368447" diaginertia="0.000674481 0.000603424 0.00036087"/>
            <joint name="right_arm_joint3" pos="0 0 0" axis="0 0 1" range="-2.14 2.14" actuatorfrcrange="-5 5"/>
            <geom type="mesh" contype="0" conaffinity="0" group="1" density="0" rgba="0.807843 0.843137 0.905882 1" mesh="right_arm_link3"/>
            <geom type="mesh" rgba="0.807843 0.843137 0.905882 1" mesh="right_arm_link3"/>
            <body name="right_arm_link4" pos="0.00384 0 0.20261" quat="0.707107 -0.707107 0 0">
              <inertial pos="-0.000541939 -0.0284058 -0.000370347" quat="0.639534 0.763579 0.0839367 -0.0299576" mass="0.0480071" diaginertia="1.64685e-05 1.57747e-05 7.22527e-06"/>
              <joint name="right_arm_joint4" pos="0 0 0" axis="0 0 -1" range="-2.14 2.14" actuatorfrcrange="-5 5"/>
              <geom type="mesh" contype="0" conaffinity="0" group="1" density="0" rgba="0.807843 0.843137 0.905882 1" mesh="right_arm_link4"/>
              <geom type="mesh" rgba="0.807843 0.843137 0.905882 1" mesh="right_arm_link4"/>
              <body name="right_arm_link5" pos="0 -0.06395 0.0002" quat="0.707107 -0.707107 0 0">
                <inertial pos="-0.00628109 0.000212854 -0.0733506" quat="0.702297 -0.0722103 -0.0708316 0.704661" mass="0.207077" diaginertia="0.000340616 0.000313554 0.000135687"/>
                <joint name="right_arm_joint5" pos="0 0 0" axis="0 0 -1" range="-2.14 2.14" actuatorfrcrange="-5 5"/>
                <geom type="mesh" contype="0" conaffinity="0" group="1" density="0" rgba="0.807843 0.843137 0.905882 1" mesh="right_arm_link5"/>
                <geom type="mesh" rgba="0.807843 0.843137 0.905882 1" mesh="right_arm_link5"/>
                <body name="right_arm_link6" pos="0.00379 5e-05 -0.1806" quat="0.707107 0.707107 0 0">
                  <inertial pos="-0.000759195 -0.0240066 -5.58164e-05" quat="0.999602 -0.00398416 0.000608784 0.0279095" mass="0.0325623" diaginertia="1.56847e-05 1.2779e-05 9.25012e-06"/>
                  <joint name="right_arm_joint6" pos="0 0 0" axis="0 0 1" range="-2.14 2.14" actuatorfrcrange="-5 5"/>
                  <geom type="mesh" contype="0" conaffinity="0" group="1" density="0" rgba="0.807843 0.843137 0.905882 1" mesh="right_arm_link6"/>
                  <geom type="mesh" rgba="0.807843 0.843137 0.905882 1" mesh="right_arm_link6"/>
                  <body name="right_arm_link7" pos="0.0001 -0.0556 -0.0001" quat="0.5 -0.5 0.5 -0.5">
                    <inertial pos="0.0570552 -7.5248e-05 -0.0198337" quat="0.366078 0.364899 -0.606287 0.604361" mass="0.18191" diaginertia="0.00044014 0.000291282 0.000204991"/>
                    <joint name="right_arm_joint7" pos="0 0 0" axis="0 0 1" range="-2.14 2.14" actuatorfrcrange="-5 5"/>
                    <geom type="mesh" contype="0" conaffinity="0" group="1" density="0" rgba="0.592157 0.666667 0.682353 1" mesh="right_arm_link7"/>
                    <geom type="mesh" rgba="0.592157 0.666667 0.682353 1" mesh="right_arm_link7"/>
                    <geom pos="0.14128 -0.0505 -0.00015" quat="0.707107 -0.707107 0 0" type="mesh" contype="0" conaffinity="0" group="1" density="0" rgba="0.592157 0.666667 0.682353 1" mesh="right_arm_gripper_left_finger"/>
                    <geom pos="0.14128 -0.0505 -0.00015" quat="0.707107 -0.707107 0 0" type="mesh" rgba="0.592157 0.666667 0.682353 1" mesh="right_arm_gripper_left_finger"/>
                    <geom pos="0.14128 0.0505 -0.00015" quat="0.707107 0.707107 0 0" type="mesh" contype="0" conaffinity="0" group="1" density="0" rgba="0.592157 0.666667 0.682353 1" mesh="right_arm_gripper_right_finger"/>
                    <geom pos="0.14128 0.0505 -0.00015" quat="0.707107 0.707107 0 0" type="mesh" rgba="0.592157 0.666667 0.682353 1" mesh="right_arm_gripper_right_finger"/>
                    <geom size="0.005" pos="0.14128 0 -0.00015" quat="0 -1 0 0" contype="0" conaffinity="0" group="1" density="0" rgba="0 1 0 1"/>
                    <!-- Gripper center site (between fingers) -->
                    <site name="right_gripper_center" pos="0.14128 0 -0.00015" size="0.005" rgba="1 0 0 0.5" />
                  </body>
                </body>
              </body>
            </body>
          </body>
        </body>
      </body>
      <body name="left_arm_link1" pos="0 -0.2145 1.015" quat="0.707107 0.707107 0 0">
        <inertial pos="3.24315e-05 3.9185e-05 0.0169208" quat="-0.0828378 0.69859 0.0864694 0.705431" mass="0.315734" diaginertia="0.000465509 0.000358966 0.000355103"/>
        <joint name="left_arm_joint1" pos="0 0 0" axis="0 0 1" range="-2.14 2.14" actuatorfrcrange="-5 5"/>
        <geom type="mesh" contype="0" conaffinity="0" group="1" density="0" rgba="0.796078 0.823529 0.937255 1" mesh="left_arm_link1"/>
        <geom type="mesh" rgba="0.796078 0.823529 0.937255 1" mesh="left_arm_link1"/>
        <body name="left_arm_link2" pos="0 0 0.04287" quat="0.5 0.5 0.5 0.5">
          <inertial pos="-0.0294209 0.000476964 -0.000518959" quat="0.461025 0.487356 0.419718 0.611373" mass="0.0501482" diaginertia="1.62891e-05 1.57687e-05 7.39432e-06"/>
          <joint name="left_arm_joint2" pos="0 0 0" axis="0 0 -1" range="-2.14 2.14" actuatorfrcrange="-5 5"/>
          <geom type="mesh" contype="0" conaffinity="0" group="1" density="0" rgba="0.807843 0.843137 0.905882 1" mesh="left_arm_link2"/>
          <geom type="mesh" rgba="0.807843 0.843137 0.905882 1" mesh="left_arm_link2"/>
          <body name="left_arm_link3" pos="-0.06575 -0.0001 -0.0004" quat="0.5 0.5 -0.5 -0.5">
            <inertial pos="-0.00607021 -7.96526e-05 0.105092" quat="0.998634 -0.000135492 0.0522467 0.000158831" mass="0.373333" diaginertia="0.000674969 0.000604631 0.00036243"/>
            <joint name="left_arm_joint3" pos="0 0 0" axis="0 0 1" range="-2.14 2.14" actuatorfrcrange="-5 5"/>
            <geom type="mesh" contype="0" conaffinity="0" group="1" density="0" rgba="0.807843 0.843137 0.905882 1" mesh="left_arm_link3"/>
            <geom type="mesh" rgba="0.807843 0.843137 0.905882 1" mesh="left_arm_link3"/>
            <body name="left_arm_link4" pos="0.00384 0 0.20081" quat="0.707107 -0.707107 0 0">
              <inertial pos="-0.000541939 -0.0284058 -0.000370347" quat="0.639534 0.763579 0.0839367 -0.0299576" mass="0.0480071" diaginertia="1.64685e-05 1.57747e-05 7.22527e-06"/>
              <joint name="left_arm_joint4" pos="0 0 0" axis="0 0 1" range="-2.14 2.14" actuatorfrcrange="-5 5"/>
              <geom type="mesh" contype="0" conaffinity="0" group="1" density="0" rgba="0.807843 0.843137 0.905882 1" mesh="left_arm_link4"/>
              <geom type="mesh" rgba="0.807843 0.843137 0.905882 1" mesh="left_arm_link4"/>
              <body name="left_arm_link5" pos="0 -0.06575 0.0002" quat="0.707107 -0.707107 0 0">
                <inertial pos="-0.00625733 0.000212853 -0.0763031" quat="0.702297 -0.0722103 -0.0708316 0.704661" mass="0.207077" diaginertia="0.000340616 0.000313554 0.000135687"/>
                <joint name="left_arm_joint5" pos="0 0 0" axis="0 0 -1" range="-2.14 2.14" actuatorfrcrange="-5 5"/>
                <geom type="mesh" contype="0" conaffinity="0" group="1" density="0" rgba="0.807843 0.843137 0.905882 1" mesh="left_arm_link5"/>
                <geom type="mesh" rgba="0.807843 0.843137 0.905882 1" mesh="left_arm_link5"/>
                <body name="left_arm_link6" pos="0.00379 5e-05 -0.1788" quat="0.707107 0.707107 0 0">
                  <inertial pos="-0.000759195 -0.0240066 -5.58164e-05" quat="0.999602 -0.00398416 0.000608784 0.0279095" mass="0.0325623" diaginertia="1.56847e-05 1.2779e-05 9.25012e-06"/>
                  <joint name="left_arm_joint6" pos="0 0 0" axis="0 0 -1" range="-2.14 2.14" actuatorfrcrange="-5 5"/>
                  <geom type="mesh" contype="0" conaffinity="0" group="1" density="0" rgba="0.807843 0.843137 0.905882 1" mesh="left_arm_link6"/>
                  <geom type="mesh" rgba="0.807843 0.843137 0.905882 1" mesh="left_arm_link6"/>
                  <body name="left_arm_link7" pos="0.0001 -0.0556 -0.0001" quat="0.5 -0.5 0.5 -0.5">
                    <inertial pos="0.0565804 -7.39494e-05 -0.0196952" quat="0.367677 0.366494 -0.605317 0.603396" mass="0.185526" diaginertia="0.000441829 0.000292266 0.000207098"/>
                    <joint name="left_arm_joint7" pos="0 0 0" axis="0 0 -1" range="-2.14 2.14" actuatorfrcrange="-5 5"/>
                    <geom type="mesh" contype="0" conaffinity="0" group="1" density="0" rgba="0.592157 0.666667 0.682353 1" mesh="left_arm_link7"/>
                    <geom type="mesh" rgba="0.592157 0.666667 0.682353 1" mesh="left_arm_link7"/>
                    <geom pos="0.14128 -0.0505 -0.00015" quat="0.707107 -0.707107 0 0" type="mesh" contype="0" conaffinity="0" group="1" density="0" rgba="0.592157 0.666667 0.682353 1" mesh="left_arm_gripper_left_finger"/>
                    <geom pos="0.14128 -0.0505 -0.00015" quat="0.707107 -0.707107 0 0" type="mesh" rgba="0.592157 0.666667 0.682353 1" mesh="left_arm_gripper_left_finger"/>
                    <geom pos="0.14128 0.0505 -0.00015" quat="0.707107 0.707107 0 0" type="mesh" contype="0" conaffinity="0" group="1" density="0" rgba="0.592157 0.666667 0.682353 1" mesh="left_arm_gripper_right_finger"/>
                    <geom pos="0.14128 0.0505 -0.00015" quat="0.707107 0.707107 0 0" type="mesh" rgba="0.592157 0.666667 0.682353 1" mesh="left_arm_gripper_right_finger"/>
                    <geom size="0.005" pos="0.14128 0 -0.00015" quat="-3.67321e-06 -1 0 0" contype="0" conaffinity="0" group="1" density="0" rgba="0 1 0 1"/>
                    <!-- Gripper center site (between fingers) -->
                    <site name="left_gripper_center" pos="0.14128 0 -0.00015" size="0.005" rgba="0 0 1 0.5" />
                  </body>
                </body>
              </body>
            </body>
          </body>
        </body>
      </body>
    </body>
    <!-- Interactive mocap targets for IK visualization -->
    <!-- Left arm target: Red coordinate frame -->
    <body name="left_target" mocap="true" pos="0.4 0.3 1.2">
      <!-- X axis - Red -->
      <geom type="cylinder" size="0.003 0.05" rgba="1 0 0 0.8" contype="0" conaffinity="0" fromto="0 0 0 0.1 0 0" />
      <geom type="sphere" size="0.008" rgba="1 0 0 0.9" contype="0" conaffinity="0" pos="0.1 0 0" />
      <!-- Y axis - Green -->
      <geom type="cylinder" size="0.003 0.05" rgba="0 1 0 0.8" contype="0" conaffinity="0" fromto="0 0 0 0 0.1 0" />
      <geom type="sphere" size="0.008" rgba="0 1 0 0.9" contype="0" conaffinity="0" pos="0 0.1 0" />
      <!-- Z axis - Blue -->
      <geom type="cylinder" size="0.003 0.05" rgba="0 0 1 0.8" contype="0" conaffinity="0" fromto="0 0 0 0 0 0.1" />
      <geom type="sphere" size="0.008" rgba="0 0 1 0.9" contype="0" conaffinity="0" pos="0 0 0.1" />
      <!-- Origin sphere -->
      <geom type="sphere" size="0.015" rgba="1 0.5 0.5 0.6" contype="0" conaffinity="0" pos="0 0 0" />
    </body>

    <!-- Right arm target: Blue coordinate frame -->
    <body name="right_target" mocap="true" pos="0.4 -0.3 1.2">
      <!-- X axis - Red -->
      <geom type="cylinder" size="0.003 0.05" rgba="1 0 0 0.8" contype="0" conaffinity="0" fromto="0 0 0 0.1 0 0" />
      <geom type="sphere" size="0.008" rgba="1 0 0 0.9" contype="0" conaffinity="0" pos="0.1 0 0" />
      <!-- Y axis - Green -->
      <geom type="cylinder" size="0.003 0.05" rgba="0 1 0 0.8" contype="0" conaffinity="0" fromto="0 0 0 0 0.1 0" />
      <geom type="sphere" size="0.008" rgba="0 1 0 0.9" contype="0" conaffinity="0" pos="0 0.1 0" />
      <!-- Z axis - Blue -->
      <geom type="cylinder" size="0.003 0.05" rgba="0 0 1 0.8" contype="0" conaffinity="0" fromto="0 0 0 0 0 0.1" />
      <geom type="sphere" size="0.008" rgba="0 0 1 0.9" contype="0" conaffinity="0" pos="0 0 0.1" />
      <!-- Origin sphere -->
      <geom type="sphere" size="0.015" rgba="0.5 0.5 1 0.6" contype="0" conaffinity="0" pos="0 0 0" />
    </body>

    <!-- Center target: Green coordinate frame -->
    <body name="center_target" mocap="true" pos="0.4 0.0 1.2">
      <!-- X axis - Red -->
      <geom type="cylinder" size="0.0025 0.04" rgba="1 0 0 0.8" contype="0" conaffinity="0" fromto="0 0 0 0.08 0 0" />
      <geom type="sphere" size="0.006" rgba="1 0 0 0.9" contype="0" conaffinity="0" pos="0.08 0 0" />
      <!-- Y axis - Green -->
      <geom type="cylinder" size="0.0025 0.04" rgba="0 1 0 0.8" contype="0" conaffinity="0" fromto="0 0 0 0 0.08 0" />
      <geom type="sphere" size="0.006" rgba="0 1 0 0.9" contype="0" conaffinity="0" pos="0 0.08 0" />
      <!-- Z axis - Blue -->
      <geom type="cylinder" size="0.0025 0.04" rgba="0 0 1 0.8" contype="0" conaffinity="0" fromto="0 0 0 0 0 0.08" />
      <geom type="sphere" size="0.006" rgba="0 0 1 0.9" contype="0" conaffinity="0" pos="0 0 0.08" />
      <!-- Origin sphere -->
      <geom type="sphere" size="0.012" rgba="0.5 1 0.5 0.6" contype="0" conaffinity="0" pos="0 0 0" />
    </body>

  </worldbody>

  <contact>
    <exclude body1="base_link" body2="left_arm_link1" />
    <exclude body1="left_arm_link1" body2="left_arm_link2" />
    <exclude body1="left_arm_link1" body2="left_arm_link3" />
    <exclude body1="left_arm_link2" body2="left_arm_link3" />
    <exclude body1="left_arm_link3" body2="left_arm_link4" />
    <exclude body1="left_arm_link4" body2="left_arm_link5" />
    <exclude body1="left_arm_link5" body2="left_arm_link6" />
    <exclude body1="left_arm_link6" body2="left_arm_link7" />
    <exclude body1="base_link" body2="right_arm_link1" />
    <exclude body1="right_arm_link1" body2="right_arm_link2" />
    <exclude body1="right_arm_link1" body2="right_arm_link3" />
    <exclude body1="right_arm_link2" body2="right_arm_link3" />
    <exclude body1="right_arm_link3" body2="right_arm_link4" />
    <exclude body1="right_arm_link4" body2="right_arm_link5" />
    <exclude body1="right_arm_link5" body2="right_arm_link6" />
    <exclude body1="right_arm_link6" body2="right_arm_link7" />
  </contact>
</mujoco>
