<mujoco model="Bessica_D_v1_0_Skeleton">
  <compiler angle="radian" meshdir="../../meshes/Bessica_D_v1_0/SkeletonOnly/" />
  <statistic center="-0.012496 0.000424702 0.622672" extent="1.93611" meansize="0.179951" />

  <asset>
    <mesh name="base_link" file="base_link.STL" />
    <mesh name="left_arm_base_link" file="left_arm_base_link.STL" />
    <mesh name="left_arm_link1" file="left_arm_link1.STL" />
    <mesh name="left_arm_link2" file="left_arm_link2.STL" />
    <mesh name="left_arm_link3" file="left_arm_link3.STL" />
    <mesh name="left_arm_link4" file="left_arm_link4.STL" />
    <mesh name="left_arm_link5" file="left_arm_link5.STL" />
    <mesh name="left_arm_link6" file="left_arm_link6.STL" />
    <mesh name="left_arm_link7" file="left_arm_link7.STL" />
    <mesh name="left_arm_gripper_base" file="left_arm_gripper_base.STL" />
    <mesh name="left_arm_gripper_left_finger" file="left_arm_gripper_left_finger.STL" />
    <mesh name="left_arm_gripper_right_finger" file="left_arm_gripper_right_finger.STL" />
    <mesh name="right_arm_base_link" file="right_arm_base_link.STL" />
    <mesh name="right_arm_link1" file="right_arm_link1.STL" />
    <mesh name="right_arm_link2" file="right_arm_link2.STL" />
    <mesh name="right_arm_link3" file="right_arm_link3.STL" />
    <mesh name="right_arm_link4" file="right_arm_link4.STL" />
    <mesh name="right_arm_link5" file="right_arm_link5.STL" />
    <mesh name="right_arm_link6" file="right_arm_link6.STL" />
    <mesh name="right_arm_link7" file="right_arm_link7.STL" />
    <mesh name="right_arm_gripper_base" file="right_arm_gripper_base.STL" />
    <mesh name="right_arm_gripper_left_finger" file="right_arm_gripper_left_finger.STL" />
    <mesh name="right_arm_gripper_right_finger" file="right_arm_gripper_right_finger.STL" />
    <texture builtin="gradient" height="100" rgb1=".4 .5 .6" rgb2="0 0 0" type="skybox" width="100" />
    <texture builtin="checker" height="100" name="texplane" rgb1="1 1 1" rgb2=".8 .9 1" type="2d" width="100" />
    <material name="MatPlane" reflectance="0.5" texrepeat="1 1" texture="texplane" texuniform="true" />
    <material name="white" rgba="1 1 1 1" shininess="0.5" specular="0.1" />
    <material name="black" rgba="0.15 0.15 0.15 1" shininess="0.2" specular="0.05" />
    <material name="invisible" rgba="1 1 1 0" shininess="0" specular="0" />
  </asset>

  <worldbody>
    <geom conaffinity="1" condim="3" contype="1" friction="1 .1 .1" group="2" material="MatPlane" name="floor" pos="0 0 0" rgba="0.8 0.9 0.8 1" size="500 500 0.125" type="plane" />
    <light castshadow="false" cutoff="100" diffuse="1 1 1" dir="-0 0 -1.3" directional="true" exponent="1" pos="0 0 1.3" specular=".1 .1 .1" />
    <body name="base_link" pos="0 0 0">
      <inertial pos="0 0 0.051" mass="3.74344" diaginertia="0.00230599 0.00230599 0.00230599" />
      <geom type="mesh" contype="0" conaffinity="0" group="1" density="0" rgba="0.592157 0.666667 0.682353 1" mesh="base_link" />
      <geom type="mesh" rgba="0.592157 0.666667 0.682353 1" mesh="base_link" />
      <geom pos="0 0.1 1.015" quat="0.707107 -0.707107 0 0" type="mesh" contype="0" conaffinity="0" group="1" density="0" rgba="0.592157 0.666667 0.682353 1" mesh="left_arm_base_link" />
      <geom pos="0 0.1 1.015" quat="0.707107 -0.707107 0 0" type="mesh" rgba="0.592157 0.666667 0.682353 1" mesh="left_arm_base_link" />
      <geom pos="0 -0.1 1.015" quat="0.707107 0.707107 0 0" type="mesh" contype="0" conaffinity="0" group="1" density="0" rgba="0.592157 0.666667 0.682353 1" mesh="right_arm_base_link" />
      <geom pos="0 -0.1 1.015" quat="0.707107 0.707107 0 0" type="mesh" rgba="0.592157 0.666667 0.682353 1" mesh="right_arm_base_link" />
      <body name="left_arm_link1" pos="0 0.2145 1.015" quat="0.707107 0.707107 0 0">
        <inertial pos="-0.000164978 6.51728e-05 -0.0024357" quat="0.0012119 0.704936 -0.00489326 0.709253" mass="0.189922" diaginertia="0.000330272 0.000249765 0.000146333" />
        <joint name="left_arm_joint1" pos="0 0 0" axis="0 0 1" range="-2.14 2.14" actuatorfrcrange="-12 12" />
        <geom type="mesh" contype="0" conaffinity="0" group="1" density="0" rgba="0.796078 0.823529 0.937255 1" mesh="left_arm_link1" />
        <geom type="mesh" rgba="0.796078 0.823529 0.937255 1" mesh="left_arm_link1" />
        <body name="left_arm_link2" pos="0.00045 0 -0.04287" quat="0.5 -0.5 0.5 -0.5">
          <inertial pos="0.0292979 0.000514106 0.00037109" quat="0.607053 0.424784 0.480473 0.469245" mass="0.0465253" diaginertia="1.57559e-05 1.51621e-05 7.00441e-06" />
          <joint name="left_arm_joint2" pos="0 0 0" axis="0 0 1" range="-0.25 2.14" actuatorfrcrange="-12 12" />
          <geom type="mesh" contype="0" conaffinity="0" group="1" density="0" rgba="0.807843 0.843137 0.905882 1" mesh="left_arm_link2" />
          <geom type="mesh" rgba="0.807843 0.843137 0.905882 1" mesh="left_arm_link2" />
          <body name="left_arm_link3" pos="0.06395 -0.0001 -5e-05" quat="0.5 0.5 -0.5 -0.5">
            <inertial pos="0.000585817 2.67134e-05 -0.120888" quat="0.705612 0.708341 -0.0135456 0.0134441" mass="0.213446" diaginertia="0.000225683 0.000161805 0.000143351" />
            <joint name="left_arm_joint3" pos="0 0 0" axis="0 0 1" range="-2.14 2.14" actuatorfrcrange="-12 12" />
            <geom type="mesh" contype="0" conaffinity="0" group="1" density="0" rgba="0.807843 0.843137 0.905882 1" mesh="left_arm_link3" />
            <geom type="mesh" rgba="0.807843 0.843137 0.905882 1" mesh="left_arm_link3" />
            <body name="left_arm_link4" pos="0.00384 5e-05 -0.20261" quat="0.707107 -0.707107 0 0">
              <inertial pos="-0.000541939 0.0284058 0.000320347" quat="0.639534 0.763579 -0.0839367 0.0299576" mass="0.0480071" diaginertia="1.64685e-05 1.57747e-05 7.22527e-06" />
              <joint name="left_arm_joint4" pos="0 0 0" axis="0 0 1" range="-1.57 1.57" actuatorfrcrange="-12 12" />
              <geom type="mesh" contype="0" conaffinity="0" group="1" density="0" rgba="0.807843 0.843137 0.905882 1" mesh="left_arm_link4" />
              <geom type="mesh" rgba="0.807843 0.843137 0.905882 1" mesh="left_arm_link4" />
              <body name="left_arm_link5" pos="0 0.06395 -0.00025" quat="0.707107 0.707107 0 0">
                <inertial pos="-0.000910668 -0.000236819 -0.0811518" quat="0.706373 -0.0214097 -0.0227093 0.707152" mass="0.11632" diaginertia="0.000100264 9.34946e-05 3.80105e-05" />
                <joint name="left_arm_joint5" pos="0 0 0" axis="0 0 1" range="-2.14 2.14" actuatorfrcrange="-12 12" />
                <geom type="mesh" contype="0" conaffinity="0" group="1" density="0" rgba="0.807843 0.843137 0.905882 1" mesh="left_arm_link5" />
                <geom type="mesh" rgba="0.807843 0.843137 0.905882 1" mesh="left_arm_link5" />
                <body name="left_arm_link6" pos="0.00384 0 -0.2106" quat="0.707107 -0.707107 0 0">
                  <inertial pos="0.000759195 0.0240066 4.41836e-05" quat="0.999602 0.00398416 -0.000608784 0.0279095" mass="0.0325623" diaginertia="1.56847e-05 1.2779e-05 9.25012e-06" />
                  <joint name="left_arm_joint6" pos="0 0 0" axis="0 0 1" range="-1.57 1.57" actuatorfrcrange="-12 12" />
                  <geom type="mesh" contype="0" conaffinity="0" group="1" density="0" rgba="0.807843 0.843137 0.905882 1" mesh="left_arm_link6" />
                  <geom type="mesh" rgba="0.807843 0.843137 0.905882 1" mesh="left_arm_link6" />
                  <body name="left_arm_link7" pos="0.0009 0.0556 0" quat="0.5 -0.5 -0.5 0.5">
                    <inertial pos="0.0419064 -0.000135185 0.0266704" quat="0.702948 0.64131 0.227637 -0.206801" mass="0.130618" diaginertia="0.000133483 9.13959e-05 8.92644e-05" />
                    <joint name="left_arm_joint7" pos="0 0 0" axis="0 0 -1" range="-1.57 1.57" actuatorfrcrange="-12 12" />
                    <geom type="mesh" contype="0" conaffinity="0" group="1" density="0" rgba="0.592157 0.666667 0.682353 1" mesh="left_arm_link7" />
                    <geom type="mesh" rgba="0.592157 0.666667 0.682353 1" mesh="left_arm_link7" />
                    <geom type="mesh" contype="0" conaffinity="0" group="1" density="0" rgba="0.807843 0.843137 0.905882 1" mesh="left_arm_gripper_base" />
                    <geom type="mesh" rgba="0.807843 0.843137 0.905882 1" mesh="left_arm_gripper_base" />
                    <body name="left_arm_gripper_left_finger" pos="0.14128 0.05 5e-05" quat="0.707107 0.707107 0 0">
                      <inertial pos="-0.0434087 -1.54744e-08 -0.0111596" quat="1.78243e-06 0.569751 -6.42992e-06 0.821818" mass="0.0256463" diaginertia="8.50963e-06 6.46826e-06 4.6607e-06" />
                      <joint name="left_arm_gripper_joint1" pos="0 0 0" axis="0 0 1" type="slide" range="0 0.05" actuatorfrcrange="-12 12" />
                      <geom type="mesh" contype="0" conaffinity="0" group="1" density="0" rgba="0.592157 0.666667 0.682353 1" mesh="left_arm_gripper_left_finger" />
                      <geom type="mesh" rgba="0.592157 0.666667 0.682353 1" mesh="left_arm_gripper_left_finger" />
                    </body>
                    <body name="left_arm_gripper_right_finger">
                      <inertial pos="0.097871 -0.0611558 5.00155e-05" quat="0.402876 0.402873 0.581108 0.581117" mass="0.0256463" diaginertia="8.50963e-06 6.46826e-06 4.6607e-06" />
                      <joint name="left_arm_gripper_joint2" pos="0 0 0" axis="0 -1 0" type="slide" range="-0.05 0" actuatorfrcrange="-12 12" />
                      <geom type="mesh" contype="0" conaffinity="0" group="1" density="0" rgba="0.592157 0.666667 0.682353 1" mesh="left_arm_gripper_right_finger" />
                      <geom type="mesh" rgba="0.592157 0.666667 0.682353 1" mesh="left_arm_gripper_right_finger" />
                    </body>
                  </body>
                </body>
              </body>
            </body>
          </body>
        </body>
      </body>
      <body name="right_arm_link1" pos="0 -0.2145 1.015" quat="0.707107 0.707107 0 0">
        <inertial pos="5.41405e-05 6.54109e-05 0.00226762" quat="-0.00121154 0.704936 0.00489295 0.709253" mass="0.189136" diaginertia="0.000330251 0.000249745 0.000146311" />
        <joint name="right_arm_joint1" pos="0 0 0" axis="0 0 1" range="-2.14 2.14" actuatorfrcrange="-12 12" />
        <geom type="mesh" contype="0" conaffinity="0" group="1" density="0" rgba="0.796078 0.823529 0.937255 1" mesh="right_arm_link1" />
        <geom type="mesh" rgba="0.796078 0.823529 0.937255 1" mesh="right_arm_link1" />
        <body name="right_arm_link2" pos="-0.00045 0 0.04287" quat="0.5 0.5 -0.5 -0.5">
          <inertial pos="0.0294209 0.000476964 6.89589e-05" quat="0.611373 0.419718 0.487356 0.461025" mass="0.0501482" diaginertia="1.62891e-05 1.57687e-05 7.39432e-06" />
          <joint name="right_arm_joint2" pos="0 0 0" axis="0 0 1" range="-0.25 2.14" actuatorfrcrange="-12 12" />
          <geom type="mesh" contype="0" conaffinity="0" group="1" density="0" rgba="0.807843 0.843137 0.905882 1" mesh="right_arm_link2" />
          <geom type="mesh" rgba="0.807843 0.843137 0.905882 1" mesh="right_arm_link2" />
          <body name="right_arm_link3" pos="0.06395 -0.0001 -5e-05" quat="0.5 -0.5 0.5 -0.5">
            <inertial pos="0.000585817 -2.67137e-05 0.120888" quat="0.705612 0.708341 0.0135456 -0.0134441" mass="0.213446" diaginertia="0.000225683 0.000161805 0.000143351" />
            <joint name="right_arm_joint3" pos="0 0 0" axis="0 0 1" range="-2.14 2.14" actuatorfrcrange="-12 12" />
            <geom type="mesh" contype="0" conaffinity="0" group="1" density="0" rgba="0.807843 0.843137 0.905882 1" mesh="right_arm_link3" />
            <geom type="mesh" rgba="0.807843 0.843137 0.905882 1" mesh="right_arm_link3" />
            <body name="right_arm_link4" pos="0.00384 -5e-05 0.20261" quat="0.707107 0.707107 0 0">
              <inertial pos="-0.000541939 0.0284058 0.000320347" quat="0.639534 0.763579 -0.0839367 0.0299576" mass="0.0480071" diaginertia="1.64685e-05 1.57747e-05 7.22527e-06" />
              <joint name="right_arm_joint4" pos="0 0 0" axis="0 0 1" range="-1.57 1.57" actuatorfrcrange="-12 12" />
              <geom type="mesh" contype="0" conaffinity="0" group="1" density="0" rgba="0.807843 0.843137 0.905882 1" mesh="right_arm_link4" />
              <geom type="mesh" rgba="0.807843 0.843137 0.905882 1" mesh="right_arm_link4" />
              <body name="right_arm_link5" pos="0 0.06395 -0.00025" quat="0.707107 -0.707107 0 0">
                <inertial pos="-0.000910668 0.000236819 0.0811518" quat="0.707152 0.0227093 0.0214097 0.706373" mass="0.11632" diaginertia="0.000100264 9.34946e-05 3.80105e-05" />
                <joint name="right_arm_joint5" pos="0 0 0" axis="0 0 1" range="-2.14 2.14" actuatorfrcrange="-12 12" />
                <geom type="mesh" contype="0" conaffinity="0" group="1" density="0" rgba="0.807843 0.843137 0.905882 1" mesh="right_arm_link5" />
                <geom type="mesh" rgba="0.807843 0.843137 0.905882 1" mesh="right_arm_link5" />
                <body name="right_arm_link6" pos="0.00384 0 0.2106" quat="0.707107 0.707107 0 0">
                  <inertial pos="0.000759195 0.0240066 4.41836e-05" quat="0.999602 0.00398416 -0.000608784 0.0279095" mass="0.0325623" diaginertia="1.56847e-05 1.2779e-05 9.25012e-06" />
                  <joint name="right_arm_joint6" pos="0 0 0" axis="0 0 1" range="-1.57 1.57" actuatorfrcrange="-12 12" />
                  <geom type="mesh" contype="0" conaffinity="0" group="1" density="0" rgba="0.807843 0.843137 0.905882 1" mesh="right_arm_link6" />
                  <geom type="mesh" rgba="0.807843 0.843137 0.905882 1" mesh="right_arm_link6" />
                  <body name="right_arm_link7" pos="0.0009 0.0556 0" quat="0.5 -0.5 -0.5 0.5">
                    <inertial pos="0.0419064 -0.000135185 0.0266704" quat="0.702948 0.64131 0.227637 -0.206801" mass="0.130618" diaginertia="0.000133483 9.13959e-05 8.92644e-05" />
                    <joint name="right_arm_joint7" pos="0 0 0" axis="0 0 1" range="-1.57 1.57" actuatorfrcrange="-12 12" />
                    <geom type="mesh" contype="0" conaffinity="0" group="1" density="0" rgba="0.592157 0.666667 0.682353 1" mesh="right_arm_link7" />
                    <geom type="mesh" rgba="0.592157 0.666667 0.682353 1" mesh="right_arm_link7" />
                    <geom type="mesh" contype="0" conaffinity="0" group="1" density="0" rgba="0.807843 0.843137 0.905882 1" mesh="right_arm_gripper_base" />
                    <geom type="mesh" rgba="0.807843 0.843137 0.905882 1" mesh="right_arm_gripper_base" />
                    <body name="right_arm_gripper_left_finger" pos="0.14128 0.0505 5e-05" quat="0.707107 0.707107 0 0">
                      <inertial pos="-0.0434087 -1.54794e-08 -0.0106596" quat="1.78281e-06 0.569751 -6.43108e-06 0.821818" mass="0.0256463" diaginertia="8.50963e-06 6.46826e-06 4.6607e-06" />
                      <joint name="right_arm_gripper_joint1" pos="0 0 0" axis="0 0 1" type="slide" range="0 0.05" actuatorfrcrange="-12 12" />
                      <geom type="mesh" contype="0" conaffinity="0" group="1" density="0" rgba="0.592157 0.666667 0.682353 1" mesh="right_arm_gripper_left_finger" />
                      <geom type="mesh" rgba="0.592157 0.666667 0.682353 1" mesh="right_arm_gripper_left_finger" />
                    </body>
                    <body name="right_arm_gripper_right_finger" pos="0.14128 -0.0505 5e-05" quat="0.707107 -0.707107 0 0">
                      <inertial pos="-0.0434087 -1.54806e-08 -0.0106558" quat="1.78288e-06 0.569751 -6.43136e-06 0.821818" mass="0.0256463" diaginertia="8.50963e-06 6.46826e-06 4.6607e-06" />
                      <joint name="right_arm_gripper_joint2" pos="0 0 0" axis="0 0 -1" type="slide" range="-0.05 0" actuatorfrcrange="-12 12" />
                      <geom type="mesh" contype="0" conaffinity="0" group="1" density="0" rgba="0.592157 0.666667 0.682353 1" mesh="right_arm_gripper_right_finger" />
                      <geom type="mesh" rgba="0.592157 0.666667 0.682353 1" mesh="right_arm_gripper_right_finger" />
                    </body>
                  </body>
                </body>
              </body>
            </body>
          </body>
        </body>
      </body>
    </body>
  </worldbody>
</mujoco>