<?xml version="1.0" encoding="utf-8" ?>
<!-- This URDF was automatically created by SolidWorks to URDF Exporter! Originally created by Stephen Brawner (brawner@gmail.com) 
     Commit Version: 1.6.0-4-g7f85cfe  Build Version: 1.6.7995.38578
     For more information, please see http://wiki.ros.org/sw_urdf_exporter -->
<robot name="Bessica_D_v1_0_Skeleton">
    <mujoco>
        <compiler meshdir="../../meshes/Bessica_D_v1_0/SkeletonOnly/" balanceinertia="true" discardvisual="false" />
        <contact>
            <exclude body1="base_link" body2="left_arm_base_link" />
            <exclude body1="left_arm_base_link" body2="left_arm_link1" />
            <exclude body1="left_arm_link1" body2="left_arm_link2" />
            <exclude body1="left_arm_link2" body2="left_arm_link3" />
            <exclude body1="left_arm_link3" body2="left_arm_link4" />
            <exclude body1="left_arm_link4" body2="left_arm_link5" />
            <exclude body1="left_arm_link5" body2="left_arm_link6" />
            <exclude body1="left_arm_link6" body2="left_arm_link7" />
            <exclude body1="left_arm_link7" body2="left_arm_gripper_left_finger" />
            <exclude body1="left_arm_link7" body2="left_arm_gripper_right_finger" />
            <exclude body1="base_link" body2="right_arm_base_link" />
            <exclude body1="right_arm_base_link" body2="right_arm_link1" />
            <exclude body1="right_arm_link1" body2="right_arm_link2" />
            <exclude body1="right_arm_link2" body2="right_arm_link3" />
            <exclude body1="right_arm_link3" body2="right_arm_link4" />
            <exclude body1="right_arm_link4" body2="right_arm_link5" />
            <exclude body1="right_arm_link5" body2="right_arm_link6" />
            <exclude body1="right_arm_link6" body2="right_arm_link7" />
            <exclude body1="right_arm_link7" body2="right_arm_gripper_left_finger" />
            <exclude body1="right_arm_link7" body2="right_arm_gripper_right_finger" />
        </contact>
    </mujoco>
    <link name="base_link">
        <visual>
            <origin xyz="0 0 0" rpy="0 0 0" />
            <geometry>
                <mesh filename="../../meshes/Bessica_D_v1_0/SkeletonOnly/base_link.STL" />
            </geometry>
            <material name="">
                <color rgba="0.592156862745098 0.666666666666667 0.682352941176471 1" />
            </material>
        </visual>
        <collision>
            <origin xyz="0 0 0" rpy="0 0 0" />
            <geometry>
                <mesh filename="../../meshes/Bessica_D_v1_0/SkeletonOnly/base_link.STL" />
            </geometry>
        </collision>
        <inertial>
            <mass value="0.1" />
            <origin xyz="0 0 0" rpy="0 0 0" />
            <inertia ixx="0.03" iyy="0.03" izz="0.03" ixy="0.0" ixz="0.0" iyz="0.0" />
        </inertial>
    </link>
    <link name="left_arm_base_link">
        <visual>
            <origin xyz="0 0 0" rpy="0 0 0" />
            <geometry>
                <mesh filename="../../meshes/Bessica_D_v1_0/SkeletonOnly/left_arm_base_link.STL" />
            </geometry>
            <material name="">
                <color rgba="0.592156862745098 0.666666666666667 0.682352941176471 1" />
            </material>
        </visual>
        <collision>
            <origin xyz="0 0 0" rpy="0 0 0" />
            <geometry>
                <mesh filename="../../meshes/Bessica_D_v1_0/SkeletonOnly/left_arm_base_link.STL" />
            </geometry>
        </collision>
        <inertial>
            <mass value="0.1" />
            <origin xyz="0 0 0" rpy="0 0 0" />
            <inertia ixx="0.03" iyy="0.03" izz="0.03" ixy="0.0" ixz="0.0" iyz="0.0" />
        </inertial>
    </link>
    <joint name="left_arm_base_joint" type="fixed">
        <origin xyz="0 0.1 1.01500000066667" rpy="-1.5707963267949 0 0" />
        <parent link="base_link" />
        <child link="left_arm_base_link" />
        <axis xyz="0 0 0" />
    </joint>
    <link name="left_arm_link1">
        <inertial>
            <origin xyz="-0.000164977722784185 6.51727945009444E-05 -0.00243570338411384" rpy="0 0 0" />
            <mass value="0.189922225867714" />
            <inertia ixx="0.000146347772116188" ixy="8.97185586680608E-07" ixz="-1.12252162303393E-06" iyy="0.000249759799894508" iyz="-4.11548403173903E-07" izz="0.000330262694467369" />
        </inertial>
        <visual>
            <origin xyz="0 0 0" rpy="0 0 0" />
            <geometry>
                <mesh filename="../../meshes/Bessica_D_v1_0/SkeletonOnly/left_arm_link1.STL" />
            </geometry>
            <material name="">
                <color rgba="0.796078431372549 0.823529411764706 0.937254901960784 1" />
            </material>
        </visual>
        <collision>
            <origin xyz="0 0 0" rpy="0 0 0" />
            <geometry>
                <mesh filename="../../meshes/Bessica_D_v1_0/SkeletonOnly/left_arm_link1.STL" />
            </geometry>
        </collision>
    </link>
    <joint name="left_arm_joint1" type="revolute">
        <origin xyz="0 0 0.1145" rpy="3.14159265358979 0 0" />
        <parent link="left_arm_base_link" />
        <child link="left_arm_link1" />
        <axis xyz="0 0 1" />
        <limit lower="-2.14" upper="2.14" effort="12" velocity="5" />
    </joint>
    <link name="left_arm_link2">
        <inertial>
            <origin xyz="0.0292978987910792 0.000514105850466684 0.000371089505223361" rpy="0 0 0" />
            <mass value="0.0465252707223917" />
            <inertia ixx="7.30112380112833E-06" ixy="5.76060636775077E-07" ixz="-1.43192461618647E-06" iyy="1.56957054082706E-05" iyz="-1.34505028400512E-08" izz="1.49256044559259E-05" />
        </inertial>
        <visual>
            <origin xyz="0 0 0" rpy="0 0 0" />
            <geometry>
                <mesh filename="../../meshes/Bessica_D_v1_0/SkeletonOnly/left_arm_link2.STL" />
            </geometry>
            <material name="">
                <color rgba="0.807843137254902 0.843137254901961 0.905882352941176 1" />
            </material>
        </visual>
        <collision>
            <origin xyz="0 0 0" rpy="0 0 0" />
            <geometry>
                <mesh filename="../../meshes/Bessica_D_v1_0/SkeletonOnly/left_arm_link2.STL" />
            </geometry>
        </collision>
    </link>
    <joint name="left_arm_joint2" type="revolute">
        <origin xyz="0.000449999999998569 0 -0.04287" rpy="-1.5707963267949 0 -1.5707963267949" />
        <parent link="left_arm_link1" />
        <child link="left_arm_link2" />
        <axis xyz="0 0 1" />
        <limit lower="-0.25" upper="2.14" effort="12" velocity="5" />
    </joint>
    <link name="left_arm_link3">
        <inertial>
            <origin xyz="0.000585816890663893 2.67134447653953E-05 -0.120888401586103" rpy="0 0 0" />
            <mass value="0.213446468640546" />
            <inertia ixx="0.000225589752278573" ixy="-1.5155044694364E-08" ixz="2.43597245450492E-06" iyy="0.00014335125310894" iyz="-7.17913825480148E-08" izz="0.000161898121849544" />
        </inertial>
        <visual>
            <origin xyz="0 0 0" rpy="0 0 0" />
            <geometry>
                <mesh filename="../../meshes/Bessica_D_v1_0/SkeletonOnly/left_arm_link3.STL" />
            </geometry>
            <material name="">
                <color rgba="0.807843137254902 0.843137254901961 0.905882352941176 1" />
            </material>
        </visual>
        <collision>
            <origin xyz="0 0 0" rpy="0 0 0" />
            <geometry>
                <mesh filename="../../meshes/Bessica_D_v1_0/SkeletonOnly/left_arm_link3.STL" />
            </geometry>
        </collision>
    </link>
    <joint name="left_arm_joint3" type="revolute">
        <origin xyz="0.0639500000000051 -0.000100000000002043 -5.00000000017345E-05" rpy="1.5707963267949 0 -1.5707963267949" />
        <parent link="left_arm_link2" />
        <child link="left_arm_link3" />
        <axis xyz="0 0 1" />
        <limit lower="-2.14" upper="2.14" effort="12" velocity="5" />
    </joint>
    <link name="left_arm_link4">
        <inertial>
            <origin xyz="-0.000541938878743597 0.0284058061970648 0.000320347235384871" rpy="0 0 0" />
            <mass value="0.0480071391158091" />
            <inertia ixx="1.64141913891155E-05" ixy="-5.7845673769066E-07" ixz="9.62946752561962E-09" iyy="7.54093815008541E-06" iyz="-1.52193904000395E-06" izz="1.55133391025038E-05" />
        </inertial>
        <visual>
            <origin xyz="0 0 0" rpy="0 0 0" />
            <geometry>
                <mesh filename="../../meshes/Bessica_D_v1_0/SkeletonOnly/left_arm_link4.STL" />
            </geometry>
            <material name="">
                <color rgba="0.807843137254902 0.843137254901961 0.905882352941176 1" />
            </material>
        </visual>
        <collision>
            <origin xyz="0 0 0" rpy="0 0 0" />
            <geometry>
                <mesh filename="../../meshes/Bessica_D_v1_0/SkeletonOnly/left_arm_link4.STL" />
            </geometry>
        </collision>
    </link>
    <joint name="left_arm_joint4" type="revolute">
        <origin xyz="0.00383999999999851 5.0000000004364E-05 -0.202609999999996" rpy="-1.57079632679489 0 0" />
        <parent link="left_arm_link3" />
        <child link="left_arm_link4" />
        <axis xyz="0 0 1" />
        <limit lower="-1.57" upper="1.57" effort="12" velocity="5" />
    </joint>
    <link name="left_arm_link5">
        <inertial>
            <origin xyz="-0.000910668202409481 -0.000236818946050908 -0.0811518411270211" rpy="0 0 0" />
            <mass value="0.116319653363722" />
            <inertia ixx="9.32787799992093E-05" ixy="-1.43207862251841E-08" ixz="3.45337326970064E-06" iyy="0.000100263941574271" iyz="1.15839563826208E-07" izz="3.8226465560725E-05" />
        </inertial>
        <visual>
            <origin xyz="0 0 0" rpy="0 0 0" />
            <geometry>
                <mesh filename="../../meshes/Bessica_D_v1_0/SkeletonOnly/left_arm_link5.STL" />
            </geometry>
            <material name="">
                <color rgba="0.807843137254902 0.843137254901961 0.905882352941176 1" />
            </material>
        </visual>
        <collision>
            <origin xyz="0 0 0" rpy="0 0 0" />
            <geometry>
                <mesh filename="../../meshes/Bessica_D_v1_0/SkeletonOnly/left_arm_link5.STL" />
            </geometry>
        </collision>
    </link>
    <joint name="left_arm_joint5" type="revolute">
        <origin xyz="0 0.0639500000000003 -0.000249999999995355" rpy="1.57079632679489 0 0" />
        <parent link="left_arm_link4" />
        <child link="left_arm_link5" />
        <axis xyz="0 0 1" />
        <limit lower="-2.14" upper="2.14" effort="12" velocity="5" />
    </joint>
    <link name="left_arm_link6">
        <inertial>
            <origin xyz="0.000759194613479341 0.0240065523153092 4.41835628682764E-05" rpy="0 0 0" />
            <mass value="0.0325622574716058" />
            <inertia ixx="1.56755999138173E-05" ixy="1.61833904254131E-07" ixz="7.68617040825205E-09" iyy="1.27877692587564E-05" iyz="2.8459924750808E-08" izz="9.25035078924422E-06" />
        </inertial>
        <visual>
            <origin xyz="0 0 0" rpy="0 0 0" />
            <geometry>
                <mesh filename="../../meshes/Bessica_D_v1_0/SkeletonOnly/left_arm_link6.STL" />
            </geometry>
            <material name="">
                <color rgba="0.807843137254902 0.843137254901961 0.905882352941176 1" />
            </material>
        </visual>
        <collision>
            <origin xyz="0 0 0" rpy="0 0 0" />
            <geometry>
                <mesh filename="../../meshes/Bessica_D_v1_0/SkeletonOnly/left_arm_link6.STL" />
            </geometry>
        </collision>
    </link>
    <joint name="left_arm_joint6" type="revolute">
        <origin xyz="0.00384000000000206 0 -0.210600000000004" rpy="-1.57079632679489 0 0" />
        <parent link="left_arm_link5" />
        <child link="left_arm_link6" />
        <axis xyz="0 0 1" />
        <limit lower="-1.57" upper="1.57" effort="12" velocity="5" />
    </joint>
    <link name="left_arm_link7">
        <inertial>
            <origin xyz="0.0177009441165684 1.21978843153611E-05 0.000335001782082178" rpy="0 0 0" />
            <mass value="0.0286926698302179" />
            <inertia ixx="1.38664319212237E-05" ixy="6.17342972752011E-09" ixz="-6.29106498416858E-08" iyy="1.07947986839636E-05" iyz="-6.61591376223645E-09" izz="9.90947221972601E-06" />
        </inertial>
        <visual>
            <origin xyz="0 0 0" rpy="0 0 0" />
            <geometry>
                <mesh filename="../../meshes/Bessica_D_v1_0/SkeletonOnly/left_arm_link7.STL" />
            </geometry>
            <material name="">
                <color rgba="0.592156862745098 0.666666666666667 0.682352941176471 1" />
            </material>
        </visual>
        <collision>
            <origin xyz="0 0 0" rpy="0 0 0" />
            <geometry>
                <mesh filename="../../meshes/Bessica_D_v1_0/SkeletonOnly/left_arm_link7.STL" />
            </geometry>
        </collision>
    </link>
    <joint name="left_arm_joint7" type="revolute">
        <origin xyz="0.000900000000000928 0.0556000000000006 0" rpy="-1.5707963267949 0 1.5707963267949" />
        <parent link="left_arm_link6" />
        <child link="left_arm_link7" />
        <axis xyz="0 0 -1" />
        <limit lower="-1.57" upper="1.57" effort="12" velocity="5" />
    </joint>
    <link name="left_arm_gripper_base">
        <inertial>
            <origin xyz="0.0487203584260385 -0.000176674281962666 0.0340839884785232" rpy="0 0 0" />
            <mass value="0.101924990923369" />
            <inertia ixx="7.96904620280455E-05" ixy="2.09550360751484E-08" ixz="3.52058599123849E-06" iyy="3.14423593116517E-05" iyz="-9.78209339202269E-09" izz="7.43475827788386E-05" />
        </inertial>
        <visual>
            <origin xyz="0 0 0" rpy="0 0 0" />
            <geometry>
                <mesh filename="../../meshes/Bessica_D_v1_0/SkeletonOnly/left_arm_gripper_base.STL" />
            </geometry>
            <material name="">
                <color rgba="0.807843137254902 0.843137254901961 0.905882352941176 1" />
            </material>
        </visual>
        <collision>
            <origin xyz="0 0 0" rpy="0 0 0" />
            <geometry>
                <mesh filename="../../meshes/Bessica_D_v1_0/SkeletonOnly/left_arm_gripper_base.STL" />
            </geometry>
        </collision>
    </link>
    <joint name="left_arm_gripper_base_joint" type="fixed">
        <origin xyz="0 0 0" rpy="0 0 0" />
        <parent link="left_arm_link7" />
        <child link="left_arm_gripper_base" />
        <axis xyz="0 0 0" />
    </joint>
    <link name="left_arm_gripper_left_finger">
        <inertial>
            <origin xyz="-0.0434086639321445 -1.54744196345646E-08 -0.0111596340364527" rpy="0 0 0" />
            <mass value="0.0256462690106054" />
            <inertia ixx="5.13427082501846E-06" ixy="2.4476015523607E-11" ixz="-1.26430153583773E-06" iyy="6.46826196607971E-06" iyz="-4.17572060497099E-13" izz="8.03606713459157E-06" />
        </inertial>
        <visual>
            <origin xyz="0 0 0" rpy="0 0 0" />
            <geometry>
                <mesh filename="../../meshes/Bessica_D_v1_0/SkeletonOnly/left_arm_gripper_left_finger.STL" />
            </geometry>
            <material name="">
                <color rgba="0.592156862745098 0.666666666666667 0.682352941176471 1" />
            </material>
        </visual>
        <collision>
            <origin xyz="0 0 0" rpy="0 0 0" />
            <geometry>
                <mesh filename="../../meshes/Bessica_D_v1_0/SkeletonOnly/left_arm_gripper_left_finger.STL" />
            </geometry>
        </collision>
    </link>
    <joint name="left_arm_gripper_joint1" type="prismatic">
        <origin xyz="0.141279659620435 0.0499999999999949 4.99999999989953E-05" rpy="1.57079632679486 0 0" />
        <parent link="left_arm_gripper_base" />
        <child link="left_arm_gripper_left_finger" />
        <axis xyz="0 0 1" />
        <limit lower="0" upper="0.05" effort="12" velocity="5" />
    </joint>
    <link name="left_arm_gripper_right_finger">
        <inertial>
            <origin xyz="0.0978709957456659 -0.0611558150927951 5.00154803947939E-05" rpy="0 0 0" />
            <mass value="0.0256462690533079" />
            <inertia ixx="5.13427082582461E-06" ixy="-1.26430153770072E-06" ixz="-2.44813468131313E-11" iyy="8.03606718467521E-06" iyz="4.17408877377817E-13" izz="6.46826201535656E-06" />
        </inertial>
        <visual>
            <origin xyz="0 0 0" rpy="0 0 0" />
            <geometry>
                <mesh filename="../../meshes/Bessica_D_v1_0/SkeletonOnly/left_arm_gripper_right_finger.STL" />
            </geometry>
            <material name="">
                <color rgba="0.592156862745098 0.666666666666667 0.682352941176471 1" />
            </material>
        </visual>
        <collision>
            <origin xyz="0 0 0" rpy="0 0 0" />
            <geometry>
                <mesh filename="../../meshes/Bessica_D_v1_0/SkeletonOnly/left_arm_gripper_right_finger.STL" />
            </geometry>
        </collision>
    </link>
    <joint name="left_arm_gripper_joint2" type="prismatic">
        <origin xyz="0 0 0" rpy="0 0 0" />
        <parent link="left_arm_gripper_base" />
        <child link="left_arm_gripper_right_finger" />
        <axis xyz="0 -1 0" />
        <limit lower="-0.05" upper="0" effort="12" velocity="5" />
        <mimic joint="left_arm_gripper_joint1" multiplier="-1" offset="0"/>
    </joint>
    <link name="right_arm_base_link">
        <visual>
            <origin xyz="0 0 0" rpy="0 0 0" />
            <geometry>
                <mesh filename="../../meshes/Bessica_D_v1_0/SkeletonOnly/right_arm_base_link.STL" />
            </geometry>
            <material name="">
                <color rgba="0.592156862745098 0.666666666666667 0.682352941176471 1" />
            </material>
        </visual>
        <collision>
            <origin xyz="0 0 0" rpy="0 0 0" />
            <geometry>
                <mesh filename="../../meshes/Bessica_D_v1_0/SkeletonOnly/right_arm_base_link.STL" />
            </geometry>
        </collision>
        <inertial>
            <mass value="0.1" />
            <origin xyz="0 0 0" rpy="0 0 0" />
            <inertia ixx="0.03" iyy="0.03" izz="0.03" ixy="0.0" ixz="0.0" iyz="0.0" />
        </inertial>
    </link>
    <joint name="right_arm_base_joint" type="fixed">
        <origin xyz="0 -0.1 1.01500000066667" rpy="1.5707963267949 0 0" />
        <parent link="base_link" />
        <child link="right_arm_base_link" />
        <axis xyz="0 0 0" />
    </joint>
    <link name="right_arm_link1">
        <inertial>
            <origin xyz="5.41404702287845E-05 6.54108681446706E-05 0.00226761786539081" rpy="0 0 0" />
            <mass value="0.189135928104252" />
            <inertia ixx="0.000146325899368165" ixy="-8.97098733928049E-07" ixz="-1.12251453991552E-06" iyy="0.000249739133125008" iyz="4.11555762771362E-07" izz="0.000330241998873376" />
        </inertial>
        <visual>
            <origin xyz="0 0 0" rpy="0 0 0" />
            <geometry>
                <mesh filename="../../meshes/Bessica_D_v1_0/SkeletonOnly/right_arm_link1.STL" />
            </geometry>
            <material name="">
                <color rgba="0.796078431372549 0.823529411764706 0.937254901960784 1" />
            </material>
        </visual>
        <collision>
            <origin xyz="0 0 0" rpy="0 0 0" />
            <geometry>
                <mesh filename="../../meshes/Bessica_D_v1_0/SkeletonOnly/right_arm_link1.STL" />
            </geometry>
        </collision>
    </link>
    <joint name="right_arm_joint1" type="revolute">
        <origin xyz="0 0 0.1145" rpy="0 0 0" />
        <parent link="right_arm_base_link" />
        <child link="right_arm_link1" />
        <axis xyz="0 0 1" />
        <limit lower="-2.14" upper="2.14" effort="12" velocity="5" />
    </joint>
    <link name="right_arm_link2">
        <inertial>
            <origin xyz="0.0294208671216254 0.000476964264628787 6.89589001957562E-05" rpy="0 0 0" />
            <mass value="0.0501482304791557" />
            <inertia ixx="7.68324123453962E-06" ixy="5.76060636775076E-07" ixz="-1.43192461618645E-06" iyy="1.62270247131466E-05" iyz="-1.34505028400508E-08" izz="1.55418254850872E-05" />
        </inertial>
        <visual>
            <origin xyz="0 0 0" rpy="0 0 0" />
            <geometry>
                <mesh filename="../../meshes/Bessica_D_v1_0/SkeletonOnly/right_arm_link2.STL" />
            </geometry>
            <material name="">
                <color rgba="0.807843137254902 0.843137254901961 0.905882352941176 1" />
            </material>
        </visual>
        <collision>
            <origin xyz="0 0 0" rpy="0 0 0" />
            <geometry>
                <mesh filename="../../meshes/Bessica_D_v1_0/SkeletonOnly/right_arm_link2.STL" />
            </geometry>
        </collision>
    </link>
    <joint name="right_arm_joint2" type="revolute">
        <origin xyz="-0.000450000000003194 0 0.04287" rpy="1.5707963267949 0 -1.5707963267949" />
        <parent link="right_arm_link1" />
        <child link="right_arm_link2" />
        <axis xyz="0 0 1" />
        <limit lower="-0.25" upper="2.14" effort="12" velocity="5" />
    </joint>
    <link name="right_arm_link3">
        <inertial>
            <origin xyz="0.000585816809109463 -2.67136522423358E-05 0.120888400266339" rpy="0 0 0" />
            <mass value="0.213446471207483" />
            <inertia ixx="0.000225589753877211" ixy="1.51549990964315E-08" ixz="-2.43597248062431E-06" iyy="0.000143351253925419" iyz="-7.17922215577811E-08" izz="0.000161898122637632" />
        </inertial>
        <visual>
            <origin xyz="0 0 0" rpy="0 0 0" />
            <geometry>
                <mesh filename="../../meshes/Bessica_D_v1_0/SkeletonOnly/right_arm_link3.STL" />
            </geometry>
            <material name="">
                <color rgba="0.807843137254902 0.843137254901961 0.905882352941176 1" />
            </material>
        </visual>
        <collision>
            <origin xyz="0 0 0" rpy="0 0 0" />
            <geometry>
                <mesh filename="../../meshes/Bessica_D_v1_0/SkeletonOnly/right_arm_link3.STL" />
            </geometry>
        </collision>
    </link>
    <joint name="right_arm_joint3" type="revolute">
        <origin xyz="0.0639500000000051 -0.000100000000002043 -5.00000000018359E-05" rpy="-1.5707963267949 0 -1.5707963267949" />
        <parent link="right_arm_link2" />
        <child link="right_arm_link3" />
        <axis xyz="0 0 1" />
        <limit lower="-2.14" upper="2.14" effort="12" velocity="5" />
    </joint>
    <link name="right_arm_link4">
        <inertial>
            <origin xyz="-0.000541938878781345 0.0284058061970335 0.000320347235456701" rpy="0 0 0" />
            <mass value="0.0480071391155925" />
            <inertia ixx="1.64141913890448E-05" ixy="-5.78456737665048E-07" ixz="9.6294675061873E-09" iyy="7.54093815004724E-06" iyz="-1.52193904003985E-06" izz="1.55133391024455E-05" />
        </inertial>
        <visual>
            <origin xyz="0 0 0" rpy="0 0 0" />
            <geometry>
                <mesh filename="../../meshes/Bessica_D_v1_0/SkeletonOnly/right_arm_link4.STL" />
            </geometry>
            <material name="">
                <color rgba="0.807843137254902 0.843137254901961 0.905882352941176 1" />
            </material>
        </visual>
        <collision>
            <origin xyz="0 0 0" rpy="0 0 0" />
            <geometry>
                <mesh filename="../../meshes/Bessica_D_v1_0/SkeletonOnly/right_arm_link4.STL" />
            </geometry>
        </collision>
    </link>
    <joint name="right_arm_joint4" type="revolute">
        <origin xyz="0.00383999999999868 -5.00000000043614E-05 0.202609999999996" rpy="1.5707963267949 0 0" />
        <parent link="right_arm_link3" />
        <child link="right_arm_link4" />
        <axis xyz="0 0 1" />
        <limit lower="-1.57" upper="1.57" effort="12" velocity="5" />
    </joint>
    <link name="right_arm_link5">
        <inertial>
            <origin xyz="-0.000910668202409259 0.000236818946051091 0.0811518411270223" rpy="0 0 0" />
            <mass value="0.116319653363723" />
            <inertia ixx="9.32787799992096E-05" ixy="1.43207862252008E-08" ixz="-3.45337326970064E-06" iyy="0.000100263941574272" iyz="1.15839563826274E-07" izz="3.82264655607251E-05" />
        </inertial>
        <visual>
            <origin xyz="0 0 0" rpy="0 0 0" />
            <geometry>
                <mesh filename="../../meshes/Bessica_D_v1_0/SkeletonOnly/right_arm_link5.STL" />
            </geometry>
            <material name="">
                <color rgba="0.807843137254902 0.843137254901961 0.905882352941176 1" />
            </material>
        </visual>
        <collision>
            <origin xyz="0 0 0" rpy="0 0 0" />
            <geometry>
                <mesh filename="../../meshes/Bessica_D_v1_0/SkeletonOnly/right_arm_link5.STL" />
            </geometry>
        </collision>
    </link>
    <joint name="right_arm_joint5" type="revolute">
        <origin xyz="0 0.0639500000000003 -0.000249999999995355" rpy="-1.5707963267949 0 0" />
        <parent link="right_arm_link4" />
        <child link="right_arm_link5" />
        <axis xyz="0 0 1" />
        <limit lower="-2.14" upper="2.14" effort="12" velocity="5" />
    </joint>
    <link name="right_arm_link6">
        <inertial>
            <origin xyz="0.000759194613479314 0.0240065523153093 4.41835628681747E-05" rpy="0 0 0" />
            <mass value="0.0325622574716058" />
            <inertia ixx="1.56755999138173E-05" ixy="1.61833904254118E-07" ixz="7.68617040825267E-09" iyy="1.27877692587564E-05" iyz="2.84599247508302E-08" izz="9.25035078924421E-06" />
        </inertial>
        <visual>
            <origin xyz="0 0 0" rpy="0 0 0" />
            <geometry>
                <mesh filename="../../meshes/Bessica_D_v1_0/SkeletonOnly/right_arm_link6.STL" />
            </geometry>
            <material name="">
                <color rgba="0.807843137254902 0.843137254901961 0.905882352941176 1" />
            </material>
        </visual>
        <collision>
            <origin xyz="0 0 0" rpy="0 0 0" />
            <geometry>
                <mesh filename="../../meshes/Bessica_D_v1_0/SkeletonOnly/right_arm_link6.STL" />
            </geometry>
        </collision>
    </link>
    <joint name="right_arm_joint6" type="revolute">
        <origin xyz="0.00384000000000215 0 0.210600000000004" rpy="1.5707963267949 0 0" />
        <parent link="right_arm_link5" />
        <child link="right_arm_link6" />
        <axis xyz="0 0 1" />
        <limit lower="-1.57" upper="1.57" effort="12" velocity="5" />
    </joint>
    <link name="right_arm_link7">
        <inertial>
            <origin xyz="0.0177009441165683 1.21978843153001E-05 0.000335001782081151" rpy="0 0 0" />
            <mass value="0.028692669830218" />
            <inertia ixx="1.38664319212237E-05" ixy="6.17342972753657E-09" ixz="-6.29106498416753E-08" iyy="1.07947986839637E-05" iyz="-6.61591376222127E-09" izz="9.90947221972603E-06" />
        </inertial>
        <visual>
            <origin xyz="0 0 0" rpy="0 0 0" />
            <geometry>
                <mesh filename="../../meshes/Bessica_D_v1_0/SkeletonOnly/right_arm_link7.STL" />
            </geometry>
            <material name="">
                <color rgba="0.592156862745098 0.666666666666667 0.682352941176471 1" />
            </material>
        </visual>
        <collision>
            <origin xyz="0 0 0" rpy="0 0 0" />
            <geometry>
                <mesh filename="../../meshes/Bessica_D_v1_0/SkeletonOnly/right_arm_link7.STL" />
            </geometry>
        </collision>
    </link>
    <joint name="right_arm_joint7" type="revolute">
        <origin xyz="0.000899999999999929 0.0556000000000009 0" rpy="-1.5707963267949 0 1.5707963267949" />
        <parent link="right_arm_link6" />
        <child link="right_arm_link7" />
        <axis xyz="0 0 1" />
        <limit lower="-1.57" upper="1.57" effort="12" velocity="5" />
    </joint>
    <link name="right_arm_gripper_base">
        <inertial>
            <origin xyz="0.0487203584260383 -0.00017667428196256 0.0340839884785222" rpy="0 0 0" />
            <mass value="0.101924990923369" />
            <inertia ixx="7.96904620280456E-05" ixy="2.0955036075214E-08" ixz="3.52058599123841E-06" iyy="3.14423593116519E-05" iyz="-9.78209339197712E-09" izz="7.43475827788387E-05" />
        </inertial>
        <visual>
            <origin xyz="0 0 0" rpy="0 0 0" />
            <geometry>
                <mesh filename="../../meshes/Bessica_D_v1_0/SkeletonOnly/right_arm_gripper_base.STL" />
            </geometry>
            <material name="">
                <color rgba="0.807843137254902 0.843137254901961 0.905882352941176 1" />
            </material>
        </visual>
        <collision>
            <origin xyz="0 0 0" rpy="0 0 0" />
            <geometry>
                <mesh filename="../../meshes/Bessica_D_v1_0/SkeletonOnly/right_arm_gripper_base.STL" />
            </geometry>
        </collision>
    </link>
    <joint name="right_arm_gripper_base_joint" type="fixed">
        <origin xyz="0 0 0" rpy="0 0 0" />
        <parent link="right_arm_link7" />
        <child link="right_arm_gripper_base" />
        <axis xyz="0 0 0" />
    </joint>
    <link name="right_arm_gripper_left_finger">
        <inertial>
            <origin xyz="-0.0434086639756549 -1.54793821649513E-08 -0.0106596340384053" rpy="0 0 0" />
            <mass value="0.0256462689783714" />
            <inertia ixx="5.1342708245089E-06" ixy="2.44804619079174E-11" ixz="-1.264301534474E-06" iyy="6.46826192853306E-06" iyz="-4.1743082149925E-13" izz="8.03606709651843E-06" />
        </inertial>
        <visual>
            <origin xyz="0 0 0" rpy="0 0 0" />
            <geometry>
                <mesh filename="../../meshes/Bessica_D_v1_0/SkeletonOnly/right_arm_gripper_left_finger.STL" />
            </geometry>
            <material name="">
                <color rgba="0.592156862745098 0.666666666666667 0.682352941176471 1" />
            </material>
        </visual>
        <collision>
            <origin xyz="0 0 0" rpy="0 0 0" />
            <geometry>
                <mesh filename="../../meshes/Bessica_D_v1_0/SkeletonOnly/right_arm_gripper_left_finger.STL" />
            </geometry>
        </collision>
    </link>
    <joint name="right_arm_gripper_joint1" type="prismatic">
        <origin xyz="0.141279659620435 0.0504999999999951 4.99999999979128E-05" rpy="1.57079632679486 0 0" />
        <parent link="right_arm_gripper_base" />
        <child link="right_arm_gripper_left_finger" />
        <axis xyz="0 0 1" />
        <limit lower="0" upper="0.05" effort="12" velocity="5" />
    </joint>
    <link name="right_arm_gripper_right_finger">
        <inertial>
            <origin xyz="-0.0434086638804374 -1.54805618046705E-08 -0.0106558150931387" rpy="0 0 0" />
            <mass value="0.025646269049064" />
            <inertia ixx="5.13427082566662E-06" ixy="2.44814973433412E-11" ixz="-1.26430153743549E-06" iyy="6.46826201050235E-06" iyz="-4.17400491635439E-13" izz="8.03606717969018E-06" />
        </inertial>
        <visual>
            <origin xyz="0 0 0" rpy="0 0 0" />
            <geometry>
                <mesh filename="../../meshes/Bessica_D_v1_0/SkeletonOnly/right_arm_gripper_right_finger.STL" />
            </geometry>
            <material name="">
                <color rgba="0.592156862745098 0.666666666666667 0.682352941176471 1" />
            </material>
        </visual>
        <collision>
            <origin xyz="0 0 0" rpy="0 0 0" />
            <geometry>
                <mesh filename="../../meshes/Bessica_D_v1_0/SkeletonOnly/right_arm_gripper_right_finger.STL" />
            </geometry>
        </collision>
    </link>
    <joint name="right_arm_gripper_joint2" type="prismatic">
        <origin xyz="0.141279659620434 -0.0505000000000061 5.00000000016043E-05" rpy="-1.57079632679493 0 0" />
        <parent link="right_arm_gripper_base" />
        <child link="right_arm_gripper_right_finger" />
        <axis xyz="0 0 -1" />
        <limit lower="-0.05" upper="0" effort="12" velocity="5" />
        <mimic joint="right_arm_gripper_joint1" multiplier="-1" offset="0"/>

    </joint>
    <transmission name="trans_left_arm_joint1">
        <type>transmission_interface/SimpleTransmission</type>
        <joint name="left_arm_joint1">
            <hardwareInterface>hardware_interface/EffortJointInterface</hardwareInterface>
        </joint>
        <actuator name="left_arm_joint1_motor">
            <hardwareInterface>hardware_interface/EffortJointInterface</hardwareInterface>
            <mechanicalReduction>1</mechanicalReduction>
        </actuator>
    </transmission>
    <transmission name="trans_left_arm_joint2">
        <type>transmission_interface/SimpleTransmission</type>
        <joint name="left_arm_joint2">
            <hardwareInterface>hardware_interface/EffortJointInterface</hardwareInterface>
        </joint>
        <actuator name="left_arm_joint2_motor">
            <hardwareInterface>hardware_interface/EffortJointInterface</hardwareInterface>
            <mechanicalReduction>1</mechanicalReduction>
        </actuator>
    </transmission>
    <transmission name="trans_left_arm_joint3">
        <type>transmission_interface/SimpleTransmission</type>
        <joint name="left_arm_joint3">
            <hardwareInterface>hardware_interface/EffortJointInterface</hardwareInterface>
        </joint>
        <actuator name="left_arm_joint3_motor">
            <hardwareInterface>hardware_interface/EffortJointInterface</hardwareInterface>
            <mechanicalReduction>1</mechanicalReduction>
        </actuator>
    </transmission>
    <transmission name="trans_left_arm_joint4">
        <type>transmission_interface/SimpleTransmission</type>
        <joint name="left_arm_joint4">
            <hardwareInterface>hardware_interface/EffortJointInterface</hardwareInterface>
        </joint>
        <actuator name="left_arm_joint4_motor">
            <hardwareInterface>hardware_interface/EffortJointInterface</hardwareInterface>
            <mechanicalReduction>1</mechanicalReduction>
        </actuator>
    </transmission>
    <transmission name="trans_left_arm_joint5">
        <type>transmission_interface/SimpleTransmission</type>
        <joint name="left_arm_joint5">
            <hardwareInterface>hardware_interface/EffortJointInterface</hardwareInterface>
        </joint>
        <actuator name="left_arm_joint5_motor">
            <hardwareInterface>hardware_interface/EffortJointInterface</hardwareInterface>
            <mechanicalReduction>1</mechanicalReduction>
        </actuator>
    </transmission>
    <transmission name="trans_left_arm_joint6">
        <type>transmission_interface/SimpleTransmission</type>
        <joint name="left_arm_joint6">
            <hardwareInterface>hardware_interface/EffortJointInterface</hardwareInterface>
        </joint>
        <actuator name="left_arm_joint6_motor">
            <hardwareInterface>hardware_interface/EffortJointInterface</hardwareInterface>
            <mechanicalReduction>1</mechanicalReduction>
        </actuator>
    </transmission>
    <transmission name="trans_left_arm_joint7">
        <type>transmission_interface/SimpleTransmission</type>
        <joint name="left_arm_joint7">
            <hardwareInterface>hardware_interface/EffortJointInterface</hardwareInterface>
        </joint>
        <actuator name="left_arm_joint7_motor">
            <hardwareInterface>hardware_interface/EffortJointInterface</hardwareInterface>
            <mechanicalReduction>1</mechanicalReduction>
        </actuator>
    </transmission>
    <transmission name="trans_left_arm_gripper_joint1">
        <type>transmission_interface/SimpleTransmission</type>
        <joint name="left_arm_gripper_joint1">
            <hardwareInterface>hardware_interface/EffortJointInterface</hardwareInterface>
        </joint>
        <actuator name="left_arm_gripper_joint1_motor">
            <hardwareInterface>hardware_interface/EffortJointInterface</hardwareInterface>
            <mechanicalReduction>1</mechanicalReduction>
        </actuator>
    </transmission>
    <transmission name="trans_left_arm_gripper_joint2">
        <type>transmission_interface/SimpleTransmission</type>
        <joint name="left_arm_gripper_joint2">
            <hardwareInterface>hardware_interface/EffortJointInterface</hardwareInterface>
        </joint>
        <actuator name="left_arm_gripper_joint2_motor">
            <hardwareInterface>hardware_interface/EffortJointInterface</hardwareInterface>
            <mechanicalReduction>1</mechanicalReduction>
        </actuator>
    </transmission>
    <transmission name="trans_right_arm_joint1">
        <type>transmission_interface/SimpleTransmission</type>
        <joint name="right_arm_joint1">
            <hardwareInterface>hardware_interface/EffortJointInterface</hardwareInterface>
        </joint>
        <actuator name="right_arm_joint1_motor">
            <hardwareInterface>hardware_interface/EffortJointInterface</hardwareInterface>
            <mechanicalReduction>1</mechanicalReduction>
        </actuator>
    </transmission>
    <transmission name="trans_right_arm_joint2">
        <type>transmission_interface/SimpleTransmission</type>
        <joint name="right_arm_joint2">
            <hardwareInterface>hardware_interface/EffortJointInterface</hardwareInterface>
        </joint>
        <actuator name="right_arm_joint2_motor">
            <hardwareInterface>hardware_interface/EffortJointInterface</hardwareInterface>
            <mechanicalReduction>1</mechanicalReduction>
        </actuator>
    </transmission>
    <transmission name="trans_right_arm_joint3">
        <type>transmission_interface/SimpleTransmission</type>
        <joint name="right_arm_joint3">
            <hardwareInterface>hardware_interface/EffortJointInterface</hardwareInterface>
        </joint>
        <actuator name="right_arm_joint3_motor">
            <hardwareInterface>hardware_interface/EffortJointInterface</hardwareInterface>
            <mechanicalReduction>1</mechanicalReduction>
        </actuator>
    </transmission>
    <transmission name="trans_right_arm_joint4">
        <type>transmission_interface/SimpleTransmission</type>
        <joint name="right_arm_joint4">
            <hardwareInterface>hardware_interface/EffortJointInterface</hardwareInterface>
        </joint>
        <actuator name="right_arm_joint4_motor">
            <hardwareInterface>hardware_interface/EffortJointInterface</hardwareInterface>
            <mechanicalReduction>1</mechanicalReduction>
        </actuator>
    </transmission>
    <transmission name="trans_right_arm_joint5">
        <type>transmission_interface/SimpleTransmission</type>
        <joint name="right_arm_joint5">
            <hardwareInterface>hardware_interface/EffortJointInterface</hardwareInterface>
        </joint>
        <actuator name="right_arm_joint5_motor">
            <hardwareInterface>hardware_interface/EffortJointInterface</hardwareInterface>
            <mechanicalReduction>1</mechanicalReduction>
        </actuator>
    </transmission>
    <transmission name="trans_right_arm_joint6">
        <type>transmission_interface/SimpleTransmission</type>
        <joint name="right_arm_joint6">
            <hardwareInterface>hardware_interface/EffortJointInterface</hardwareInterface>
        </joint>
        <actuator name="right_arm_joint6_motor">
            <hardwareInterface>hardware_interface/EffortJointInterface</hardwareInterface>
            <mechanicalReduction>1</mechanicalReduction>
        </actuator>
    </transmission>
    <transmission name="trans_right_arm_joint7">
        <type>transmission_interface/SimpleTransmission</type>
        <joint name="right_arm_joint7">
            <hardwareInterface>hardware_interface/EffortJointInterface</hardwareInterface>
        </joint>
        <actuator name="right_arm_joint7_motor">
            <hardwareInterface>hardware_interface/EffortJointInterface</hardwareInterface>
            <mechanicalReduction>1</mechanicalReduction>
        </actuator>
    </transmission>
    <transmission name="trans_right_arm_gripper_joint1">
        <type>transmission_interface/SimpleTransmission</type>
        <joint name="right_arm_gripper_joint1">
            <hardwareInterface>hardware_interface/EffortJointInterface</hardwareInterface>
        </joint>
        <actuator name="right_arm_gripper_joint1_motor">
            <hardwareInterface>hardware_interface/EffortJointInterface</hardwareInterface>
            <mechanicalReduction>1</mechanicalReduction>
        </actuator>
    </transmission>
    <transmission name="trans_right_arm_gripper_joint2">
        <type>transmission_interface/SimpleTransmission</type>
        <joint name="right_arm_gripper_joint2">
            <hardwareInterface>hardware_interface/EffortJointInterface</hardwareInterface>
        </joint>
        <actuator name="right_arm_gripper_joint2_motor">
            <hardwareInterface>hardware_interface/EffortJointInterface</hardwareInterface>
            <mechanicalReduction>1</mechanicalReduction>
        </actuator>
    </transmission>
    <gazebo>
        <plugin name="gazebo_ros_control" filename="libgazebo_ros_control.so">
            <robotNamespace>/</robotNamespace>
        </plugin>
    </gazebo>
</robot>

