<?xml version="1.0" encoding="utf-8"?>
<!-- This URDF was automatically created by SolidWorks to URDF Exporter! Originally created by Stephen Brawner (brawner@gmail.com) 
     Commit Version: 1.6.0-4-g7f85cfe  Build Version: 1.6.7995.38578
     For more information, please see http://wiki.ros.org/sw_urdf_exporter -->
<robot
  name="Alicia_D_v5_6_leader">
  <mujoco>
    <compiler meshdir="../../meshes/Alicia_D_v5_6/leader" discardvisual="false" />
    <contact>
      <exclude body1="base_link" body2="link1"/>
      <exclude body1="link1" body2="link2"/>
      <exclude body1="lnk2" body2="link3"/>
      <exclude body1="lnk3" body2="link4"/>
      <exclude body1="link4" body2="link5"/>
      <exclude body1="link5" body2="link6"/>
    </contact>
  </mujoco>
  <link
    name="base_link">
    <inertial>
      <origin
        xyz="-0.0059642707899964 -3.50182547375163E-05 0.0254174350023735"
        rpy="0 0 0" />
      <mass
        value="0.368093424916451" />
      <inertia
        ixx="0.000607994786920068"
        ixy="-5.65069989947972E-07"
        ixz="2.55733054344488E-05"
        iyy="0.000550504156181044"
        iyz="-1.55293895511716E-07"
        izz="0.00104942428054456" />
    </inertial>
    <visual>
      <origin
        xyz="0 0 0"
        rpy="0 0 0" />
      <geometry>
        <mesh
          filename="../../meshes/Alicia_D_v5_6/leader/base_link.STL" />
      </geometry>
      <material
        name="">
        <color
          rgba="0.15 0.15 0.15 1" />
      </material>
    </visual>
    <collision>
      <origin
        xyz="0 0 0"
        rpy="0 0 0" />
      <geometry>
        <mesh
          filename="../../meshes/Alicia_D_v5_6/leader/base_link.STL" />
      </geometry>
    </collision>
  </link>
  <link
    name="link1">
    <inertial>
      <origin
        xyz="-2.80402573191625E-05 0.0195626268699366 -0.00251620198325536"
        rpy="0 0 0" />
      <mass
        value="0.0243712954879011" />
      <inertia
        ixx="6.62393141020525E-06"
        ixy="-9.79774818921073E-09"
        ixz="-1.11645471569283E-08"
        iyy="5.81559427910004E-06"
        iyz="7.05505786373697E-08"
        izz="5.80574600156294E-06" />
    </inertial>
    <visual>
      <origin
        xyz="0 0 0"
        rpy="0 0 0" />
      <geometry>
        <mesh
          filename="../../meshes/Alicia_D_v5_6/leader/link1.STL" />
      </geometry>
      <material
        name="">
        <color
          rgba="0.15 0.15 0.15 1" />
      </material>
    </visual>
    <collision>
      <origin
        xyz="0 0 0"
        rpy="0 0 0" />
      <geometry>
        <mesh
          filename="../../meshes/Alicia_D_v5_6/leader/link1.STL" />
      </geometry>
    </collision>
  </link>
  <joint
    name="joint1"
    type="revolute">
    <origin
      xyz="0 0 0.05085"
      rpy="1.5707963267949 0 0" />
    <parent
      link="base_link" />
    <child
      link="link1" />
    <axis
      xyz="0 1 0" />
    <limit
      lower="-2.749"
      upper="2.749"
      effort="5"
      velocity="10" />
  </joint>
  <link
    name="link2">
    <inertial>
      <origin
        xyz="0.105078719016068 0.00201788469032737 -0.000193247980142353"
        rpy="0 0 0" />
      <mass
        value="0.0953620083959412" />
      <inertia
        ixx="2.50001717236586E-05"
        ixy="-1.9710620656602E-06"
        ixz="-4.62729678148582E-07"
        iyy="6.59817922987973E-05"
        iyz="-2.63497593048694E-07"
        izz="5.66495653598225E-05" />
    </inertial>
    <visual>
      <origin
        xyz="0 0 0"
        rpy="0 0 0" />
      <geometry>
        <mesh
          filename="../../meshes/Alicia_D_v5_6/leader/link2.STL" />
      </geometry>
      <material
        name="">
        <color
          rgba="0.15 0.15 0.15 1" />
      </material>
    </visual>
    <collision>
      <origin
        xyz="0 0 0"
        rpy="0 0 0" />
      <geometry>
        <mesh
          filename="../../meshes/Alicia_D_v5_6/leader/link2.STL" />
      </geometry>
    </collision>
  </link>
  <joint
    name="joint2"
    type="revolute">
    <origin
      xyz="0 0.0428599999999999 -0.000300000000000013"
      rpy="3.14159265358979 0 1.5707963267949" />
    <parent
      link="link1" />
    <child
      link="link2" />
    <axis
      xyz="0 0 -1" />
    <limit
      lower="-1.75"
      upper="1.75"
      effort="5"
      velocity="10" />
  </joint>
  <link
    name="link3">
    <inertial>
      <origin
        xyz="-0.0114875741951831 -0.0328018067517344 0.000119091321144637"
        rpy="0 0 0" />
      <mass
        value="0.0548526651976208" />
      <inertia
        ixx="2.01244533174875E-05"
        ixy="-2.1683973971019E-06"
        ixz="5.06703546199542E-08"
        iyy="2.72919905466329E-05"
        iyz="4.71824366016115E-08"
        izz="1.88377641961169E-05" />
    </inertial>
    <visual>
      <origin
        xyz="0 0 0"
        rpy="0 0 0" />
      <geometry>
        <mesh
          filename="../../meshes/Alicia_D_v5_6/leader/link3.STL" />
      </geometry>
      <material
        name="">
        <color
          rgba="0.15 0.15 0.15 1" />
      </material>
    </visual>
    <collision>
      <origin
        xyz="0 0 0"
        rpy="0 0 0" />
      <geometry>
        <mesh
          filename="../../meshes/Alicia_D_v5_6/leader/link3.STL" />
      </geometry>
    </collision>
  </link>
  <joint
    name="joint3"
    type="revolute">
    <origin
      xyz="0.1892 0.027452 0.001"
      rpy="0 0 -2.3562" />
    <parent
      link="link2" />
    <child
      link="link3" />
    <axis
      xyz="0 0 -1" />
    <limit
      lower="-0.6"
      upper="2.2"
      effort="5"
      velocity="10" />
  </joint>
  <link
    name="link4">
    <inertial>
      <origin
        xyz="0.000302577481953559 -0.000654183368382793 0.0662938275283598"
        rpy="0 0 0" />
      <mass
        value="0.0644611791940891" />
      <inertia
        ixx="6.9208032318643E-05"
        ixy="-1.06835017090488E-08"
        ixz="-7.44668684087382E-07"
        iyy="6.77549578878689E-05"
        iyz="1.40643900532034E-07"
        izz="1.66822810256525E-05" />
    </inertial>
    <visual>
      <origin
        xyz="0 0 0"
        rpy="0 0 0" />
      <geometry>
        <mesh
          filename="../../meshes/Alicia_D_v5_6/leader/link4.STL" />
      </geometry>
      <material
        name="">
        <color
          rgba="0.15 0.15 0.15 1" />
      </material>
    </visual>
    <collision>
      <origin
        xyz="0 0 0"
        rpy="0 0 0" />
      <geometry>
        <mesh
          filename="../../meshes/Alicia_D_v5_6/leader/link4.STL" />
      </geometry>
    </collision>
  </link>
  <joint
    name="joint4"
    type="revolute">
    <origin
      xyz="-0.00389378030941123 -0.0576000000000002 0.000500000000000021"
      rpy="1.5707963267949 0 0" />
    <parent
      link="link3" />
    <child
      link="link4" />
    <axis
      xyz="0 0 -1" />
    <limit
      lower="-2.79"
      upper="2.79"
      effort="5"
      velocity="10" />
  </joint>
  <link
    name="link5">
    <inertial>
      <origin
        xyz="-0.0107578483212925 -0.0305541640587372 0.000363115097291391"
        rpy="0 0 0" />
      <mass
        value="0.0510330827595259" />
      <inertia
        ixx="1.93335072933279E-05"
        ixy="-2.11704508848414E-06"
        ixz="5.32700726629763E-08"
        iyy="2.60433997130892E-05"
        iyz="-4.0729601062392E-08"
        izz="1.78207650732133E-05" />
    </inertial>
    <visual>
      <origin
        xyz="0 0 0"
        rpy="0 0 0" />
      <geometry>
        <mesh
          filename="../../meshes/Alicia_D_v5_6/leader/link5.STL" />
      </geometry>
      <material
        name="">
        <color
          rgba="0.15 0.15 0.15 1" />
      </material>
    </visual>
    <collision>
      <origin
        xyz="0 0 0"
        rpy="0 0 0" />
      <geometry>
        <mesh
          filename="../../meshes/Alicia_D_v5_6/leader/link5.STL" />
      </geometry>
    </collision>
  </link>
  <joint
    name="joint5"
    type="revolute">
    <origin
      xyz="0 0 0.12231"
      rpy="-1.5707963267949 0 0" />
    <parent
      link="link4" />
    <child
      link="link5" />
    <axis
      xyz="0 0 -1" />
    <limit
      lower="-1.57"
      upper="1.57"
      effort="5"
      velocity="10" />
  </joint>
  <link
    name="link6">
    <inertial>
      <origin
        xyz="-0.000627623651745346 -7.97092803237298E-05 0.0717230729633379"
        rpy="0 0 0" />
      <mass
        value="0.148889229292563" />
      <inertia
        ixx="8.45527239865299E-05"
        ixy="-9.91864228383859E-08"
        ixz="-5.36136707155622E-07"
        iyy="9.9848648788884E-05"
        iyz="-2.37032776161295E-07"
        izz="3.99647073368167E-05" />
    </inertial>
    <visual>
      <origin
        xyz="0 0 0"
        rpy="0 0 0" />
      <geometry>
        <mesh
          filename="../../meshes/Alicia_D_v5_6/leader/link6.STL" />
      </geometry>
      <material
        name="">
        <color
          rgba="0.15 0.15 0.15 1" />
      </material>
    </visual>
    <collision>
      <origin
        xyz="0 0 0"
        rpy="0 0 0" />
      <geometry>
        <mesh
          filename="../../meshes/Alicia_D_v5_6/leader/link6.STL" />
      </geometry>
    </collision>
  </link>
  <joint
    name="joint6"
    type="revolute">
    <origin
      xyz="-0.0038938 -0.0575 0.0005"
      rpy="1.5708 0 0" />
    <parent
      link="link5" />
    <child
      link="link6" />
    <axis
      xyz="0 0 -1" />
    <limit
      lower="-3.14159"
      upper="3.14159"
      effort="5"
      velocity="10" />
  </joint>
  <link name="tool0">
    <visual>
      <origin xyz="0 0 0" rpy="0 0 0" />
      <geometry>
        <sphere radius="0.005" />
      </geometry>
      <material name="green_virtual_sphere_material">
        <color rgba="0 1 0 1" />
      </material>
    </visual>
  </link>
  <joint name="tool0_joint" type="fixed">
    <origin xyz="0 0 0.05" rpy="0 0 0" />
    <parent link="link6" />
    <child link="tool0" />
    <axis xyz="0 0 0" />
  </joint>
</robot>