<?xml version="1.0" encoding="utf-8"?>
<!-- This URDF was automatically created by SolidWorks to URDF Exporter! Originally created by Stephen Brawner (brawner@gmail.com) 
     Commit Version: 1.6.0-4-g7f85cfe  Build Version: 1.6.7995.38578
     For more information, please see http://wiki.ros.org/sw_urdf_exporter -->
<robot
  name="Alicia_D_v5_6_vertical_50mm">
 <mujoco>
    <compiler meshdir="../../meshes/Alicia_D_v5_6/vertical" discardvisual="false" />
    <contact>
      <exclude body1="base_link" body2="link1"/>
      <exclude body1="link1" body2="link2"/>
      <exclude body1="link2" body2="link3"/>
      <exclude body1="link3" body2="link4"/>
      <exclude body1="link4" body2="link5"/>
      <exclude body1="link5" body2="link6"/>
      <exclude body1="link6" body2="left_gripper"/>
      <exclude body1="left_gripper" body2="right_gripper"/>
    </contact>
  </mujoco>

  <link
    name="base_link">
    <inertial>
      <origin
        xyz="0.0457675129412962 -0.00797844272991024 0.000826234819519947"
        rpy="0 0 0" />
      <mass
        value="0.733961424518811" />
      <inertia
        ixx="0.0027466768320003"
        ixy="1.4865220408027E-05"
        ixz="5.1436012452304E-07"
        iyy="0.00173617223687016"
        iyz="-5.67201110176861E-05"
        izz="0.00138410344755266" />
    </inertial>
    <visual>
      <origin
        xyz="0 0 0"
        rpy="0 0 0" />
      <geometry>
        <mesh
          filename="../../meshes/Alicia_D_v5_6/vertical/base_link.STL" />
      </geometry>
      <material
        name="">
        <color
          rgba="0.15 0.15 0.15 1" />
      </material>
    </visual>
    <collision>
      <origin
        xyz="0 0 0"
        rpy="0 0 0" />
      <geometry>
        <mesh
          filename="../../meshes/Alicia_D_v5_6/vertical/base_link.STL" />
      </geometry>
    </collision>
  </link>
  <link
    name="link1">
    <inertial>
      <origin
        xyz="-0.000230589792664285 -1.29105840686568E-05 0.00303135426436209"
        rpy="0 0 0" />
      <mass
        value="0.195233494789617" />
      <inertia
        ixx="0.000258351163242732"
        ixy="8.79400016610413E-07"
        ixz="-6.87503898066312E-07"
        iyy="0.000149307749011192"
        iyz="-1.07703883144162E-06"
        izz="0.000339791347148405" />
    </inertial>
    <visual>
      <origin
        xyz="0 0 0"
        rpy="0 0 0" />
      <geometry>
        <mesh
          filename="../../meshes/Alicia_D_v5_6/vertical/link1.STL" />
      </geometry>
      <material
        name="">
        <color
          rgba="0.15 0.15 0.15 1" />
      </material>
    </visual>
    <collision>
      <origin
        xyz="0 0 0"
        rpy="0 0 0" />
      <geometry>
        <mesh
          filename="../../meshes/Alicia_D_v5_6/vertical/link1.STL" />
      </geometry>
    </collision>
  </link>
  <joint
    name="Joint1"
    type="revolute">
    <origin
      xyz="0.1295 0 0"
      rpy="0 -1.5708 3.14159" />
    <parent
      link="base_link" />
    <child
      link="link1" />
    <axis
      xyz="0 0 -1" />
    <limit
      lower="-2.749"
      upper="2.749"
      effort="5"
      velocity="12" />
  </joint>
  <link
    name="link2">
    <inertial>
      <origin
        xyz="-0.150588695674104 0.000866069028981259 -0.00065095060713574"
        rpy="0 0 0" />
      <mass
        value="0.20703369319785" />
      <inertia
        ixx="0.000128135500183479"
        ixy="-1.38510375366823E-07"
        ixz="-4.91817924785732E-06"
        iyy="0.000205708390610324"
        iyz="3.50025102033586E-07"
        izz="0.000122721347338349" />
    </inertial>
    <visual>
      <origin
        xyz="0 0 0"
        rpy="0 0 0" />
      <geometry>
        <mesh
          filename="../../meshes/Alicia_D_v5_6/vertical/link2.STL" />
      </geometry>
      <material
        name="">
        <color
          rgba="0.15 0.15 0.15 1" />
      </material>
    </visual>
    <collision>
      <origin
        xyz="0 0 0"
        rpy="0 0 0" />
      <geometry>
        <mesh
          filename="../../meshes/Alicia_D_v5_6/vertical/link2.STL" />
      </geometry>
    </collision>
  </link>
  <joint
    name="Joint2"
    type="revolute">
    <origin
      xyz="0 0 0.0428700000000002"
      rpy="-1.5707963267949 0 0" />
    <parent
      link="link1" />
    <child
      link="link2" />
    <axis
      xyz="0 0 1" />
    <limit
      lower="-0.5"
      upper="3.14159"
      effort="5"
      velocity="12" />
  </joint>
  <link
    name="link3">
    <inertial>
      <origin
        xyz="0.00248146050434591 -0.0557863637984392 0.000269730966530727"
        rpy="0 0 0" />
      <mass
        value="0.0845575648033612" />
      <inertia
        ixx="7.61916348813172E-05"
        ixy="2.26488482553822E-06"
        ixz="-3.82289960541766E-07"
        iyy="2.87941476972434E-05"
        iyz="5.38442445064827E-06"
        izz="8.04368648051262E-05" />
    </inertial>
    <visual>
      <origin
        xyz="0 0 0"
        rpy="0 0 0" />
      <geometry>
        <mesh
          filename="../../meshes/Alicia_D_v5_6/vertical/link3.STL" />
      </geometry>
      <material
        name="">
        <color
          rgba="0.15 0.15 0.15 1" />
      </material>
    </visual>
    <collision>
      <origin
        xyz="0 0 0"
        rpy="0 0 0" />
      <geometry>
        <mesh
          filename="../../meshes/Alicia_D_v5_6/vertical/link3.STL" />
      </geometry>
    </collision>
  </link>
  <joint
    name="Joint3"
    type="revolute">
    <origin
      xyz="-0.223671302741225 0.0224916129580053 -5.00000000000885E-05"
      rpy="0 0 -1.5707963267949" />
    <parent
      link="link2" />
    <child
      link="link3" />
    <axis
      xyz="0 0 1" />
    <limit
      lower="-2.5"
      upper="0.8"
      effort="5"
      velocity="12" />
  </joint>
  <link
    name="link4">
    <inertial>
      <origin
        xyz="-0.000298364425181399 -0.000601364070403842 -0.0659740370733432"
        rpy="0 0 0" />
      <mass
        value="0.0653695784138105" />
      <inertia
        ixx="7.03004001282717E-05"
        ixy="9.68401332189214E-09"
        ixz="-7.50129423129621E-07"
        iyy="6.8747019705046E-05"
        iyz="-4.45213968580794E-08"
        izz="1.68226049361848E-05" />
    </inertial>
    <visual>
      <origin
        xyz="0 0 0"
        rpy="0 0 0" />
      <geometry>
        <mesh
          filename="../../meshes/Alicia_D_v5_6/vertical/link4.STL" />
      </geometry>
      <material
        name="">
        <color
          rgba="0.15 0.15 0.15 1" />
      </material>
    </visual>
    <collision>
      <origin
        xyz="0 0 0"
        rpy="0 0 0" />
      <geometry>
        <mesh
          filename="../../meshes/Alicia_D_v5_6/vertical/link4.STL" />
      </geometry>
    </collision>
  </link>
  <joint
    name="Joint4"
    type="revolute">
    <origin
      xyz="-0.00211000000000214 -0.0990000000000028 0.000200000000000403"
      rpy="-1.5707963267949 0 0" />
    <parent
      link="link3" />
    <child
      link="link4" />
    <axis
      xyz="0 0 1" />
    <limit
      lower="-2.79"
      upper="2.79"
      effort="5"
      velocity="12" />
  </joint>
  <link
    name="link5">
    <inertial>
      <origin
        xyz="-0.0113684261608681 -0.0308687468595606 0.000870452812986841"
        rpy="0 0 0" />
      <mass
        value="0.0507638951828307" />
      <inertia
        ixx="1.87701006163012E-05"
        ixy="-2.01098346983551E-06"
        ixz="5.1524374647551E-08"
        iyy="2.51021006420917E-05"
        iyz="-4.22403492433025E-08"
        izz="1.72571677914921E-05" />
    </inertial>
    <visual>
      <origin
        xyz="0 0 0"
        rpy="0 0 0" />
      <geometry>
        <mesh
          filename="../../meshes/Alicia_D_v5_6/vertical/link5.STL" />
      </geometry>
      <material
        name="">
        <color
          rgba="0.15 0.15 0.15 1" />
      </material>
    </visual>
    <collision>
      <origin
        xyz="0 0 0"
        rpy="0 0 0" />
      <geometry>
        <mesh
          filename="../../meshes/Alicia_D_v5_6/vertical/link5.STL" />
      </geometry>
    </collision>
  </link>
  <joint
    name="Joint5"
    type="revolute">
    <origin
      xyz="0 -0.000499999999999259 -0.12235"
      rpy="1.5707963267949 0 3.14159265358979" />
    <parent
      link="link4" />
    <child
      link="link5" />
    <axis
      xyz="0 0 -1" />
    <limit
      lower="-1.57"
      upper="1.57"
      effort="5"
      velocity="12" />
  </joint>
  <link
    name="link6">
    <inertial>
      <origin
        xyz="-0.0274897845454484 -1.7884123139598E-05 0.0342551101716425"
        rpy="0 0 0" />
      <mass
        value="0.130364815702518" />
      <inertia
        ixx="7.59035719070204E-05"
        ixy="1.14457104266833E-08"
        ixz="-3.58077216673603E-06"
        iyy="3.53175112409851E-05"
        iyz="2.0923010513319E-08"
        izz="8.31975700417851E-05" />
    </inertial>
    <visual>
      <origin
        xyz="0 0 0"
        rpy="0 0 0" />
      <geometry>
        <mesh
          filename="../../meshes/Alicia_D_v5_6/vertical/link6.STL" />
      </geometry>
      <material
        name="">
        <color
          rgba="0.15 0.15 0.15 1" />
      </material>
    </visual>
    <collision>
      <origin
        xyz="0 0 0"
        rpy="0 0 0" />
      <geometry>
        <mesh
          filename="../../meshes/Alicia_D_v5_6/vertical/link6.STL" />
      </geometry>
    </collision>
  </link>
  <joint
    name="Joint6"
    type="revolute">
    <origin
      xyz="-0.00384999999999948 -0.0574999999999999 0.000999999999999556"
      rpy="1.57079632679489 0 0" />
    <parent
      link="link5" />
    <child
      link="link6" />
    <axis
      xyz="0 0 -1" />
    <limit
      lower="-3.14159"
      upper="3.14159"
      effort="5"
      velocity="12" />
  </joint>
  <link
    name="left_gripper">
    <inertial>
      <origin
        xyz="1.54738664173704E-08 -0.0434086639287873 -0.0106558150952316"
        rpy="0 0 0" />
      <mass
        value="0.0256462690131208" />
      <inertia
        ixx="6.46826196895184E-06"
        ixy="-2.44755234308053E-11"
        ixz="4.17599666850939E-13"
        iyy="5.13427082511146E-06"
        iyz="-1.26430153599475E-06"
        izz="8.03606713754067E-06" />
    </inertial>
    <visual>
      <origin
        xyz="0 0 0"
        rpy="0 0 0" />
      <geometry>
        <mesh
          filename="../../meshes/Alicia_D_v5_6/vertical/left_gripper.STL" />
      </geometry>
      <material
        name="">
        <color
          rgba="0.15 0.15 0.15 1" />
      </material>
    </visual>
    <collision>
      <origin
        xyz="0 0 0"
        rpy="0 0 0" />
      <geometry>
        <mesh
          filename="../../meshes/Alicia_D_v5_6/vertical/left_gripper.STL" />
      </geometry>
    </collision>
  </link>
  <joint
    name="left_finger"
    type="prismatic">
    <origin
      xyz="0.000199999999998958 -0.0254999999999972 0.130979659620445"
      rpy="1.5707963267949 0 3.14159265358979" />
    <parent
      link="link6" />
    <child
      link="left_gripper" />
    <axis
      xyz="0 0 1" />
    <limit
      lower="0"
      upper="0.025"
      effort="5"
      velocity="12" />
  </joint>
  <link
    name="right_gripper">
    <inertial>
      <origin
        xyz="1.54744200370205E-08 0.0434086639321447 0.010655815095439"
        rpy="0 0 0" />
      <mass
        value="0.0256462690106051" />
      <inertia
        ixx="6.46826196607957E-06"
        ixy="2.44760155081821E-11"
        ixz="-4.17572017467429E-13"
        iyy="5.1342708250184E-06"
        iyz="-1.26430153583772E-06"
        izz="8.0360671345914E-06" />
    </inertial>
    <visual>
      <origin
        xyz="0 0 0"
        rpy="0 0 0" />
      <geometry>
        <mesh
          filename="../../meshes/Alicia_D_v5_6/vertical/right_gripper.STL" />
      </geometry>
      <material
        name="">
        <color
          rgba="0.15 0.15 0.15 1" />
      </material>
    </visual>
    <collision>
      <origin
        xyz="0 0 0"
        rpy="0 0 0" />
      <geometry>
        <mesh
          filename="../../meshes/Alicia_D_v5_6/vertical/right_gripper.STL" />
      </geometry>
    </collision>
  </link>
  <joint
    name="right_finger"
    type="prismatic">
    <origin
      xyz="0.000200000000001796 0.0255000000000029 0.130979659620445"
      rpy="-1.5707963267949 0 0" />
    <parent
      link="link6" />
    <child
      link="right_gripper" />
    <axis
      xyz="0 0 1" />
    <limit
      lower="-0.025"
      upper="0"
      effort="5"
      velocity="12" />
  </joint>
<link
    name="tool0">
    <visual>
      <origin
        xyz="0 0 0"
        rpy="0 0 0" />
      <geometry>
        <sphere radius="0.005" />
      </geometry>
      <material
        name="green_virtual_sphere_material">
        <color
          rgba="0 1 0 1" />
      </material>
    </visual>
  </link>

  <joint
    name="finger"
    type="fixed">
    <origin
      xyz="0.0002 0 0.13098"
      rpy="0 0 0" />
    <parent
      link="link6" />
    <child
      link="tool0" />
    <axis
      xyz="0 0 0" />
  </joint>
</robot>