<mujoco model="alicia_m_v1_1_gripper_100mm">
  <compiler angle="radian" meshdir="../../meshes/Alicia_M_v1_1/"/>

  <asset>
    <mesh name="base_link" content_type="model/stl" file="base_link.STL"/>
    <mesh name="link1" content_type="model/stl" file="link1.STL"/>
    <mesh name="link2" content_type="model/stl" file="link2.STL"/>
    <mesh name="link3" content_type="model/stl" file="link3.STL"/>
    <mesh name="link4" content_type="model/stl" file="link4.STL"/>
    <mesh name="link5" content_type="model/stl" file="link5.STL"/>
    <mesh name="link6" content_type="model/stl" file="link6.STL"/>
    <mesh name="grasp_base" file="grasp_base.STL"/>
    <mesh name="link7" content_type="model/stl" file="link7.STL"/>
    <mesh name="link8" content_type="model/stl" file="link8.STL"/>
    <texture builtin="gradient" height="100" rgb1=".4 .5 .6" rgb2="0 0 0" type="skybox" width="100" />
    <texture builtin="checker" height="100" name="texplane" rgb1="1 1 1" rgb2=".8 .9 1" type="2d" width="100" />
    <material name="MatPlane" reflectance="0.5" texrepeat="1 1" texture="texplane" texuniform="true" />
    <material name="white" rgba="1 1 1 1" shininess="0.5" specular="0.1" />
    <material name="black" rgba="0.15 0.15 0.15 1" shininess="0.2" specular="0.05" />
    <material name="invisible" rgba="1 1 1 0" shininess="0" specular="0" />
  </asset>

  <worldbody>
    <geom conaffinity="1" condim="3" contype="1" friction="1 .1 .1" group="2" material="MatPlane" name="floor" pos="0 0 0" rgba="0.8 0.9 0.8 1" size="10 10 0.125" type="plane" />
    <light castshadow="false" cutoff="100" diffuse="1 1 1" dir="-0 0 -1.3" directional="true" exponent="1" pos="0 0 1.3" specular=".1 .1 .1" />
    <body name="base_link" pos="0 0 0">
      <geom type="mesh" contype="0" conaffinity="0" group="1" density="0" rgba="0.15 0.15 0.15 1" mesh="base_link"/>
      <geom type="mesh" rgba="0.15 0.15 0.15 1" mesh="base_link"/>
      <body name="link1" pos="0 0 0.10705">
        <inertial pos="0.00037898 -0.0010139 0.039387" quat="0.496344 0.498912 0.491924 0.512583" mass="0.54365" diaginertia="0.000222523 0.000203294 0.000189733"/>
        <joint name="joint1" pos="0 0 0" axis="0 0 1" range="-2.75 2.75" actuatorfrcrange="-5 5"/>
        <geom type="mesh" contype="0" conaffinity="0" group="1" density="0" rgba="0.15 0.15 0.15 1" mesh="link1"/>
        <geom type="mesh" rgba="0.15 0.15 0.15 1" mesh="link1"/>
        <body name="link2" pos="0 0 0.046" quat="0.707105 0.707108 0 0">
          <inertial pos="-0.19722 0.016179 0.00075589" quat="0.518992 0.521254 0.477753 0.480306" mass="1.1153" diaginertia="0.00336302 0.0032279 0.000557451"/>
          <joint name="joint2" pos="0 0 0" axis="0 0 1" range="-3.14 0" actuatorfrcrange="-5 5"/>
          <geom type="mesh" contype="0" conaffinity="0" group="1" density="0" rgba="0.15 0.15 0.15 1" mesh="link2"/>
          <geom type="mesh" rgba="0.15 0.15 0.15 1" mesh="link2"/>
          <body name="link3" pos="-0.28185 0.040324 0" quat="0.707105 0 0 0.707108">
            <inertial pos="0.026259 -0.064912 -0.00065987" quat="0.544393 0.543768 0.449435 0.45383" mass="0.4356" diaginertia="0.000180685 0.00014855 0.000128035"/>
            <joint name="joint3" pos="0 0 0" axis="0 0 -1" range="-3.14 0" actuatorfrcrange="-5 5"/>
            <geom type="mesh" contype="0" conaffinity="0" group="1" density="0" rgba="0.15 0.15 0.15 1" mesh="link3"/>
            <geom type="mesh" rgba="0.15 0.15 0.15 1" mesh="link3"/>
            <body name="link4" pos="0.028563 -0.091416 0" quat="0.000138824 -0.000138824 0.707108 -0.707105">
              <inertial pos="3.9183e-06 0.001144 0.11644" quat="0.705277 -0.000147596 0.000155548 0.708932" mass="0.57265" diaginertia="0.000371781 0.000345569 0.00019935"/>
              <joint name="joint4" pos="0 0 0" axis="-0.00034722 0 1" range="-1.57 1.57" actuatorfrcrange="-5 5"/>
              <geom type="mesh" contype="0" conaffinity="0" group="1" density="0" rgba="0.15 0.15 0.15 1" mesh="link4"/>
              <geom type="mesh" rgba="0.15 0.15 0.15 1" mesh="link4"/>
              <body name="link5" pos="-8.0556e-05 0 0.151" quat="0.707105 0.707108 0.000122761 -0.000122761">
                <inertial pos="-0.0001129 0.054381 0.0022373" quat="0.504681 0.493838 0.494544 0.506801" mass="0.38891" diaginertia="0.0001484 0.000110433 0.000104146"/>
                <joint name="joint5" pos="0 0 0" axis="0 0 1" range="-1.57 1.57" actuatorfrcrange="-5 5"/>
                <geom type="mesh" contype="0" conaffinity="0" group="1" density="0" rgba="0.15 0.15 0.15 1" mesh="link5"/>
                <geom type="mesh" rgba="0.15 0.15 0.15 1" mesh="link5"/>
                <body name="link6" pos="5.2431e-05 0.081 0" quat="0.707105 -0.707108 -0.000122761 0.000122761">
                  <inertial pos="-9.91535e-05 -0.00606335 0.0371697" quat="0.481597 0.516306 -0.51736 0.483561" mass="0.39535" diaginertia="0.000402607 0.000371614 9.85402e-05"/>
                  <joint name="joint6" pos="0 0 0" axis="-0.00034722 0 1" range="-2.75 2.75" actuatorfrcrange="-5 5"/>
                  <geom type="mesh" contype="0" conaffinity="0" group="1" density="0" rgba="0.15 0.15 0.15 1" mesh="link6"/>
                  <geom type="mesh" rgba="0.15 0.15 0.15 1" mesh="link6"/>
                  <geom pos="-3.3333e-05 0 0.055" quat="1 0 0 0" type="mesh" contype="0" conaffinity="0" group="1" density="0" rgba="0.15 0.15 0.15 1" mesh="grasp_base"/>
                  <geom pos="-3.3333e-05 0 0.055" quat="1 0 0 0" type="mesh" rgba="0.15 0.15 0.15 1" mesh="grasp_base"/>
                  <geom size="0.005" pos="0 -0.000675 0.15" contype="0" conaffinity="0" group="1" density="0" rgba="0 1 0 1"/>
                  <body name="link7" pos="0 -0.048175 0.151" quat="0.707105 0.707108 0.000122761 -0.000122761">
                    <inertial pos="-0.0062638 -0.056089 0.0037593" quat="0.913436 0.393188 -0.0116965 -0.104411" mass="0.048674" diaginertia="2.54969e-05 2.21204e-05 1.66597e-05"/>
                    <joint name="left_finger" pos="0 0 0" axis="0 0 1" type="slide" range="-0.05 0" actuatorfrcrange="-5 5"/>
                    <geom type="mesh" contype="0" conaffinity="0" group="1" density="0" rgba="0.15 0.15 0.15 1" mesh="link7"/>
                    <geom type="mesh" rgba="0.15 0.15 0.15 1" mesh="link7"/>
                  </body>
                  <body name="link8" pos="0 0.046825 0.151" quat="0.707105 0.707108 0.000122761 -0.000122761">
                    <inertial pos="0.0062638 -0.056089 -0.0037593" quat="0.393188 0.913436 0.104411 0.0116965" mass="0.048674" diaginertia="2.54969e-05 2.21204e-05 1.66597e-05"/>
                    <joint name="right_finger" pos="0 0 0" axis="0 0 1" type="slide" range="0 0.05" actuatorfrcrange="-5 5"/>
                    <geom type="mesh" contype="0" conaffinity="0" group="1" density="0" rgba="0.15 0.15 0.15 1" mesh="link8"/>
                    <geom type="mesh" rgba="0.15 0.15 0.15 1" mesh="link8"/>
                  </body>
                </body>
              </body>
            </body>
          </body>
        </body>
      </body>
    </body>
  </worldbody>
  <contact>
    <exclude body1="base_link" body2="link1" />
    <exclude body1="link1" body2="link2" />
    <exclude body1="link2" body2="link3" />
    <exclude body1="link3" body2="link4" />
    <exclude body1="link2" body2="link4" />
    <exclude body1="link4" body2="link5" />
    <exclude body1="link5" body2="link6" />
    <exclude body1="link6" body2="link7" />
    <exclude body1="link6" body2="link8" />
    <exclude body1="link7" body2="link8" />
  </contact>
</mujoco>
