<?xml version="1.0" encoding="utf-8"?>
<!-- This URDF was automatically created by SolidWorks to URDF Exporter! Originally created by Stephen Brawner (brawner@gmail.com) 
     Commit Version: 1.6.0-4-g7f85cfe  Build Version: 1.6.7995.38578
     For more information, please see http://wiki.ros.org/sw_urdf_exporter -->
<robot
  name="Bessica_D_v1_1_skeleton">
    <mujoco>
        <compiler meshdir="../../meshes/Bessica_D_v1_1/SkeletonOnly" balanceinertia="true" discardvisual="false" />
        <contact>
            <exclude body1="base_link" body2="left_arm_base_link" />
            <exclude body1="left_arm_base_link" body2="left_arm_link1" />
            <exclude body1="left_arm_link1" body2="left_arm_link2" />
            <exclude body1="left_arm_link2" body2="left_arm_link3" />
            <exclude body1="left_arm_link3" body2="left_arm_link4" />
            <exclude body1="left_arm_link4" body2="left_arm_link5" />
            <exclude body1="left_arm_link5" body2="left_arm_link6" />
            <exclude body1="left_arm_link6" body2="left_arm_link7" />
            <exclude body1="left_arm_link7" body2="left_arm_gripper_left_finger" />
            <exclude body1="left_arm_link7" body2="left_arm_gripper_right_finger" />
            <exclude body1="base_link" body2="right_arm_base_link" />
            <exclude body1="right_arm_base_link" body2="right_arm_link1" />
            <exclude body1="right_arm_link1" body2="right_arm_link2" />
            <exclude body1="right_arm_link2" body2="right_arm_link3" />
            <exclude body1="right_arm_link3" body2="right_arm_link4" />
            <exclude body1="right_arm_link4" body2="right_arm_link5" />
            <exclude body1="right_arm_link5" body2="right_arm_link6" />
            <exclude body1="right_arm_link6" body2="right_arm_link7" />
            <exclude body1="right_arm_link7" body2="right_arm_gripper_left_finger" />
            <exclude body1="right_arm_link7" body2="right_arm_gripper_right_finger" />
        </contact>
    </mujoco>

  <link
    name="base_link">
    <inertial>
      <origin
        xyz="-0.0213994189150022 0.00222516132627618 0.313837183059334"
        rpy="0 0 0" />
      <mass
        value="2.97915154863328" />
      <inertia
        ixx="0.0266780236458614"
        ixy="-8.40632030328001E-06"
        ixz="5.94524047927399E-05"
        iyy="0.0251251736503752"
        iyz="5.57261708333564E-05"
        izz="0.0281701364982913" />
    </inertial>
    <visual>
      <origin
        xyz="0 0 0"
        rpy="0 0 0" />
      <geometry>
        <mesh
          filename="../../meshes/Bessica_D_v1_1/SkeletonOnly/base_link.STL" scale="1 1 1" />
      </geometry>
      <material
        name="">
        <color
          rgba="0.807843137254902 0.843137254901961 0.905882352941176 1" />
      </material>
    </visual>
    <collision>
      <origin
        xyz="0 0 0"
        rpy="0 0 0" />
      <geometry>
        <mesh
          filename="../../meshes/Bessica_D_v1_1/SkeletonOnly/base_link.STL" scale="1 1 1" />
      </geometry>
    </collision>
  </link>
  <link
    name="head_link">
    <inertial>
      <origin
        xyz="-0.0293125008363115 -0.000187466229046737 -0.0543306015967774"
        rpy="0 0 0" />
      <mass
        value="0.14240268640264" />
      <inertia
        ixx="5.88444113087788E-05"
        ixy="3.20781054100873E-08"
        ixz="-2.3670754604199E-07"
        iyy="8.42831926167512E-05"
        iyz="-3.88467674926458E-08"
        izz="0.000119983893551237" />
    </inertial>
    <visual>
      <origin
        xyz="0 0 0"
        rpy="0 0 0" />
      <geometry>
        <mesh
          filename="../../meshes/Bessica_D_v1_1/SkeletonOnly/head.STL" scale="1 1 1" />
      </geometry>
      <material
        name="">
        <color
          rgba="0.592156862745098 0.666666666666667 0.682352941176471 1" />
      </material>
    </visual>
    <collision>
      <origin
        xyz="0 0 0"
        rpy="0 0 0" />
      <geometry>
        <mesh
          filename="../../meshes/Bessica_D_v1_1/SkeletonOnly/head.STL" scale="1 1 1" />
      </geometry>
    </collision>
  </link>
  <joint
    name="head"
    type="fixed">
    <origin
      xyz="0.0608244989821353 0.00175926213288549 0.700041453535696"
      rpy="0 0 0" />
    <parent
      link="base_link" />
    <child
      link="head_link" />
    <axis
      xyz="0 0 0" />
  </joint>
  <link
    name="right_arm_base_link">
    <inertial>
      <origin
        xyz="1.14204610799917E-05 -0.0313122795486606 0.00207120887297763"
        rpy="0 0 0" />
      <mass
        value="0.708886467477366" />
      <inertia
        ixx="0.00109027347212421"
        ixy="1.2427447571166E-07"
        ixz="-3.30654305612188E-08"
        iyy="0.00175522828646041"
        iyz="1.13920582290032E-05"
        izz="0.00103392336580602" />
    </inertial>
    <visual>
      <origin
        xyz="0 0 0"
        rpy="0 0 0" />
      <geometry>
        <mesh
          filename="../../meshes/Bessica_D_v1_1/SkeletonOnly/right_arm_base_link.STL" scale="1 1 1" />
      </geometry>
      <material
        name="">
        <color
          rgba="0.807843137254902 0.843137254901961 0.905882352941176 1" />
      </material>
    </visual>
    <collision>
      <origin
        xyz="0 0 0"
        rpy="0 0 0" />
      <geometry>
        <mesh
          filename="../../meshes/Bessica_D_v1_1/SkeletonOnly/right_arm_base_link.STL" scale="1 1 1" />
      </geometry>
    </collision>
  </link>
  <joint
    name="right_arm_base_joint"
    type="fixed">
    <origin
      xyz="-0.060825 -0.091759 -0.18554"
      rpy="3.1416 0 -3.1416" />
    <parent
      link="head_link" />
    <child
      link="right_arm_base_link" />
    <axis
      xyz="0 0 0" />
  </joint>
  <link
    name="right_arm_link1">
    <inertial>
      <origin
        xyz="0.000110931733588726 -0.00312061750298909 0.000177905469213924"
        rpy="0 0 0" />
      <mass
        value="0.208265932443548" />
      <inertia
        ixx="0.000150652973467298"
        ixy="1.03593056896932E-06"
        ixz="-4.02294223782555E-07"
        iyy="0.000340012950108409"
        iyz="-3.27494058452419E-07"
        izz="0.000262863346156477" />
    </inertial>
    <visual>
      <origin
        xyz="0 0 0"
        rpy="0 0 0" />
      <geometry>
        <mesh
          filename="../../meshes/Bessica_D_v1_1/SkeletonOnly/right_arm_link1.STL" scale="1 1 1" />
      </geometry>
      <material
        name="">
        <color
          rgba="0.807843137254902 0.843137254901961 0.905882352941176 1" />
      </material>
    </visual>
    <collision>
      <origin
        xyz="0 0 0"
        rpy="0 0 0" />
      <geometry>
        <mesh
          filename="../../meshes/Bessica_D_v1_1/SkeletonOnly/right_arm_link1.STL" scale="1 1 1" />
      </geometry>
    </collision>
  </link>
  <joint
    name="right_arm_joint1"
    type="revolute">
    <origin
      xyz="-4.9995E-05 -0.1146 0"
      rpy="0 0 0" />
    <parent
      link="right_arm_base_link" />
    <child
      link="right_arm_link1" />
    <axis
      xyz="0 -1 0" />
    <limit
      lower="-2.749"
      upper="2.749"
      effort="5"
      velocity="12" />
  </joint>
  <link
    name="right_arm_link2">
    <inertial>
      <origin
        xyz="-0.0297080835856076 -0.000293736358338903 -0.000469868640934901"
        rpy="0 0 0" />
      <mass
        value="0.0472690682635543" />
      <inertia
        ixx="7.84810740381452E-06"
        ixy="3.0307330415702E-07"
        ixz="8.12871168227469E-07"
        iyy="1.6196738097515E-05"
        iyz="-2.66374208497861E-08"
        izz="1.57923110620936E-05" />
    </inertial>
    <visual>
      <origin
        xyz="0 0 0"
        rpy="0 0 0" />
      <geometry>
        <mesh
          filename="../../meshes/Bessica_D_v1_1/SkeletonOnly/right_arm_link2.STL" scale="1 1 1" />
      </geometry>
      <material
        name="">
        <color
          rgba="0.592156862745098 0.666666666666667 0.682352941176471 1" />
      </material>
    </visual>
    <collision>
      <origin
        xyz="0 0 0"
        rpy="0 0 0" />
      <geometry>
        <mesh
          filename="../../meshes/Bessica_D_v1_1/SkeletonOnly/right_arm_link2.STL" scale="1 1 1" />
      </geometry>
    </collision>
  </link>
  <joint
    name="right_arm_joint2"
    type="revolute">
    <origin
      xyz="0 -0.04286 0"
      rpy="0 1.5708 0" />
    <parent
      link="right_arm_link1" />
    <child
      link="right_arm_link2" />
    <axis
      xyz="0 0 1" />
    <limit
      lower="-0.1"
      upper="3.1416"
      effort="5"
      velocity="12" />
  </joint>
  <link
    name="right_arm_link3">
    <inertial>
      <origin
        xyz="-0.00359312750625992 -0.000221911456218804 0.0944689553721528"
        rpy="0 0 0" />
      <mass
        value="0.140451564761292" />
      <inertia
        ixx="7.84851547500319E-05"
        ixy="7.63137736391691E-08"
        ixz="-2.13950347562665E-06"
        iyy="8.80462027388166E-05"
        iyz="-2.08857303185621E-07"
        izz="5.54283682942892E-05" />
    </inertial>
    <visual>
      <origin
        xyz="0 0 0"
        rpy="0 0 0" />
      <geometry>
        <mesh
          filename="../../meshes/Bessica_D_v1_1/SkeletonOnly/right_arm_link3.STL" scale="1 1 1" />
      </geometry>
      <material
        name="">
        <color
          rgba="0.807843137254902 0.843137254901961 0.905882352941176 1" />
      </material>
    </visual>
    <collision>
      <origin
        xyz="0 0 0"
        rpy="0 0 0" />
      <geometry>
        <mesh
          filename="../../meshes/Bessica_D_v1_1/SkeletonOnly/right_arm_link3.STL" scale="1 1 1" />
      </geometry>
    </collision>
  </link>
  <joint
    name="right_arm_joint3"
    type="revolute">
    <origin
      xyz="-0.06455 0 -0.0003"
      rpy="3.1416 1.5708 0" />
    <parent
      link="right_arm_link2" />
    <child
      link="right_arm_link3" />
    <axis
      xyz="0 0 1" />
    <limit
      lower="-2.79"
      upper="2.79"
      effort="5"
      velocity="12" />
  </joint>
  <link
    name="right_arm_link4">
    <inertial>
      <origin
        xyz="-2.80228986531128E-05 0.0241582522751294 4.84136443005823E-05"
        rpy="0 0 0" />
      <mass
        value="0.0427207248079551" />
      <inertia
        ixx="1.04868449032066E-05"
        ixy="-6.7403811827915E-10"
        ixz="-2.03399189642414E-12"
        iyy="8.49767825719554E-06"
        iyz="-1.47259005690473E-12"
        izz="8.00564872610079E-06" />
    </inertial>
    <visual>
      <origin
        xyz="0 0 0"
        rpy="0 0 0" />
      <geometry>
        <mesh
          filename="../../meshes/Bessica_D_v1_1/SkeletonOnly/right_arm_link4.STL" scale="1 1 1" />
      </geometry>
      <material
        name="">
        <color
          rgba="0.592156862745098 0.666666666666667 0.682352941176471 1" />
      </material>
    </visual>
    <collision>
      <origin
        xyz="0 0 0"
        rpy="0 0 0" />
      <geometry>
        <mesh
          filename="../../meshes/Bessica_D_v1_1/SkeletonOnly/right_arm_link4.STL" scale="1 1 1" />
      </geometry>
    </collision>
  </link>
  <joint
    name="right_arm_joint4"
    type="revolute">
    <origin
      xyz="-1.8989E-05 -4.9997E-05 0.1816"
      rpy="1.5708 1.5708 0" />
    <parent
      link="right_arm_link3" />
    <child
      link="right_arm_link4" />
    <axis
      xyz="0 0 1" />
    <limit
      lower="-0.5236"
      upper="2.95"
      effort="5"
      velocity="12" />
  </joint>
  <link
    name="right_arm_link5">
    <inertial>
      <origin
        xyz="-0.0018091088753594 -0.000196778378568463 0.0430792595976821"
        rpy="0 0 0" />
      <mass
        value="0.110396949965053" />
      <inertia
        ixx="8.5064631574955E-05"
        ixy="4.15482672393953E-07"
        ixz="-9.67661906182039E-06"
        iyy="8.69928965307323E-05"
        iyz="8.81477407046221E-07"
        izz="4.58202380966561E-05" />
    </inertial>
    <visual>
      <origin
        xyz="0 0 0"
        rpy="0 0 0" />
      <geometry>
        <mesh
          filename="../../meshes/Bessica_D_v1_1/SkeletonOnly/right_arm_link5.STL" scale="1 1 1" />
      </geometry>
      <material
        name="">
        <color
          rgba="0.807843137254902 0.843137254901961 0.905882352941176 1" />
      </material>
    </visual>
    <collision>
      <origin
        xyz="0 0 0"
        rpy="0 0 0" />
      <geometry>
        <mesh
          filename="../../meshes/Bessica_D_v1_1/SkeletonOnly/right_arm_link5.STL" scale="1 1 1" />
      </geometry>
    </collision>
  </link>
  <joint
    name="right_arm_joint5"
    type="revolute">
    <origin
      xyz="0 0.0487999946213909 0.000100002721817094"
      rpy="1.5707963267948 -1.5707963267949 3.14159265358979" />
    <parent
      link="right_arm_link4" />
    <child
      link="right_arm_link5" />
    <axis
      xyz="0 0 1" />
    <limit
      lower="-2.79"
      upper="2.79"
      effort="5"
      velocity="12" />
  </joint>
  <link
    name="right_arm_link6">
    <inertial>
      <origin
        xyz="0.000365897578257224 -0.0257376403738949 -4.10017384462336E-05"
        rpy="0 0 0" />
      <mass
        value="0.0345706786766012" />
      <inertia
        ixx="1.56357560389182E-05"
        ixy="-1.63183630784717E-07"
        ixz="-7.87695854254402E-09"
        iyy="1.27277246485998E-05"
        iyz="2.83300566726252E-08"
        izz="9.20019800183926E-06" />
    </inertial>
    <visual>
      <origin
        xyz="0 0 0"
        rpy="0 0 0" />
      <geometry>
        <mesh
          filename="../../meshes/Bessica_D_v1_1/SkeletonOnly/right_arm_link6.STL" scale="1 1 1" />
      </geometry>
      <material
        name="">
        <color
          rgba="0.807843137254902 0.843137254901961 0.905882352941176 1" />
      </material>
    </visual>
    <collision>
      <origin
        xyz="0 0 0"
        rpy="0 0 0" />
      <geometry>
        <mesh
          filename="../../meshes/Bessica_D_v1_1/SkeletonOnly/right_arm_link6.STL" scale="1 1 1" />
      </geometry>
    </collision>
  </link>
  <joint
    name="right_arm_joint6"
    type="revolute">
    <origin
      xyz="0.00289 -0.0020761 0.10801"
      rpy="-1.5708 0 0" />
    <parent
      link="right_arm_link5" />
    <child
      link="right_arm_link6" />
    <axis
      xyz="0 0 -1" />
    <limit
      lower="-1.675"
      upper="1.675"
      effort="5"
      velocity="12" />
  </joint>
  <link
    name="right_arm_link7">
    <inertial>
      <origin
        xyz="0.0415075863157686 -0.000152826039986842 0.0262966808899044"
        rpy="0 0 0" />
      <mass
        value="0.134443483448265" />
      <inertia
        ixx="9.47488732350365E-05"
        ixy="1.46899642307621E-08"
        ixz="3.66536057576179E-06"
        iyy="4.31456176264887E-05"
        iyz="-1.72469029366528E-08"
        izz="8.45592400210402E-05" />
    </inertial>
    <visual>
      <origin
        xyz="0 0 0"
        rpy="0 0 0" />
      <geometry>
        <mesh
          filename="../../meshes/Bessica_D_v1_1/SkeletonOnly/right_arm_link7.STL" scale="1 1 1" />
      </geometry>
      <material
        name="">
        <color
          rgba="0.807843137254902 0.843137254901961 0.905882352941176 1" />
      </material>
    </visual>
    <collision>
      <origin
        xyz="0 0 0"
        rpy="0 0 0" />
      <geometry>
        <mesh
          filename="../../meshes/Bessica_D_v1_1/SkeletonOnly/right_arm_link7.STL" scale="1 1 1" />
      </geometry>
    </collision>
  </link>
  <joint
    name="right_arm_joint7"
    type="revolute">
    <origin
      xyz="-0.0015 -0.05561 0"
      rpy="1.5708 0 -1.5708" />
    <parent
      link="right_arm_link6" />
    <child
      link="right_arm_link7" />
    <axis
      xyz="0 0 1" />
    <limit
      lower="-1.448"
      upper="1.448"
      effort="5"
      velocity="12" />
  </joint>
  <link
    name="right_arm_gripper_left_finger">
    <inertial>
      <origin
        xyz="-0.0434086592316459 -1.82028284667624E-08 -0.0106596255383133"
        rpy="0 0 0" />
      <mass
        value="0.0256462690507918" />
      <inertia
        ixx="5.13427082573154E-06"
        ixy="2.44818388732062E-11"
        ixz="-1.26430153754377E-06"
        iyy="6.46826201248425E-06"
        iyz="-4.17381220204411E-13"
        izz="8.03606718172584E-06" />
    </inertial>
    <visual>
      <origin
        xyz="0 0 0"
        rpy="0 0 0" />
      <geometry>
        <mesh
          filename="../../meshes/Bessica_D_v1_1/SkeletonOnly/right_arm_gripper_left_finger.STL" scale="1 1 1" />
      </geometry>
      <material
        name="">
        <color
          rgba="0.592156862745098 0.666666666666667 0.682352941176471 1" />
      </material>
    </visual>
    <collision>
      <origin
        xyz="0 0 0"
        rpy="0 0 0" />
      <geometry>
        <mesh
          filename="../../meshes/Bessica_D_v1_1/SkeletonOnly/right_arm_gripper_left_finger.STL" scale="1 1 1" />
      </geometry>
    </collision>
  </link>
  <joint
    name="right_arm_gripper_joint1"
    type="prismatic">
    <origin
      xyz="0.14128 -0.0505 0.00015"
      rpy="-1.5708 0 0" />
    <parent
      link="right_arm_link7" />
    <child
      link="right_arm_gripper_left_finger" />
    <axis
      xyz="0 0 -1" />
    <limit
      lower="-0.05"
      upper="0"
      effort="5"
      velocity="12" />
  </joint>
  <link
    name="right_arm_gripper_right_finger">
    <inertial>
      <origin
        xyz="-0.0434086592316461 -1.2759062806289E-08 -0.0106596425296954"
        rpy="0 0 0" />
      <mass
        value="0.0256462690507921" />
      <inertia
        ixx="5.13427082573152E-06"
        ixy="2.44818388776517E-11"
        ixz="-1.26430153754372E-06"
        iyy="6.46826201248447E-06"
        iyz="-4.17381217859319E-13"
        izz="8.03606718172613E-06" />
    </inertial>
    <visual>
      <origin
        xyz="0 0 0"
        rpy="0 0 0" />
      <geometry>
        <mesh
          filename="../../meshes/Bessica_D_v1_1/SkeletonOnly/right_arm_gripper_right_finger.STL" scale="1 1 1" />
      </geometry>
      <material
        name="">
        <color
          rgba="0.592156862745098 0.666666666666667 0.682352941176471 1" />
      </material>
    </visual>
    <collision>
      <origin
        xyz="0 0 0"
        rpy="0 0 0" />
      <geometry>
        <mesh
          filename="../../meshes/Bessica_D_v1_1/SkeletonOnly/right_arm_gripper_right_finger.STL" scale="1 1 1" />
      </geometry>
    </collision>
  </link>
  <joint
    name="right_arm_gripper_joint2"
    type="prismatic">
    <origin
      xyz="0.14128 0.0505 0.00015"
      rpy="1.5708 0 0" />
    <parent
      link="right_arm_link7" />
    <child
      link="right_arm_gripper_right_finger" />
    <axis
      xyz="0 0 1" />
    <limit
      lower="0"
      upper="0.05"
      effort="5"
      velocity="12" />
  </joint>
  <link
    name="right_tool0">
     <visual>
      <origin
        xyz="0 0 0"
        rpy="0 0 0" />
      <geometry>
        <sphere radius="0.005" />
      </geometry>
      <material
        name="green_virtual_sphere_material">
        <color
          rgba="0 1 0 1" />
      </material>
    </visual>
  </link>

  <joint
    name="right_arm_gripper_joint"
    type="fixed">
    <origin
      xyz="0.14128 0 0.00015"
      rpy="0 0 0" />
    <parent
      link="right_arm_link7" />
    <child
      link="right_tool0" />
    <axis
      xyz="0 0 0" />
  </joint>
  <link
    name="left_arm_base_link">
    <inertial>
      <origin
        xyz="-1.1425444572527E-05 -0.00207120887324641 0.0313122794858798"
        rpy="0 0 0" />
      <mass
        value="0.708886467098045" />
      <inertia
        ixx="0.00109027347213969"
        ixy="-3.30654324040014E-08"
        ixz="1.24274247249233E-07"
        iyy="0.00103392336541501"
        iyz="1.1392058310753E-05"
        izz="0.00175522828618526" />
    </inertial>
    <visual>
      <origin
        xyz="0 0 0"
        rpy="0 0 0" />
      <geometry>
        <mesh
          filename="../../meshes/Bessica_D_v1_1/SkeletonOnly/left_arm_base_link.STL" scale="1 1 1" />
      </geometry>
      <material
        name="">
        <color
          rgba="0.807843137254902 0.843137254901961 0.905882352941176 1" />
      </material>
    </visual>
    <collision>
      <origin
        xyz="0 0 0"
        rpy="0 0 0" />
      <geometry>
        <mesh
          filename="../../meshes/Bessica_D_v1_1/SkeletonOnly/left_arm_base_link.STL" scale="1 1 1" />
      </geometry>
    </collision>
  </link>
  <joint
    name="left_arm_base_joint"
    type="fixed">
    <origin
      xyz="-0.0608244908152262 0.0882407378671147 -0.185541452202364"
      rpy="1.5707963267949 0 -3.14159265358979" />
    <parent
      link="head_link" />
    <child
      link="left_arm_base_link" />
    <axis
      xyz="0 0 0" />
  </joint>
  <link
    name="left_arm_link1">
    <inertial>
      <origin
        xyz="-0.000114066048154726 0.000187361212312442 -0.0037036858224383"
        rpy="0 0 0" />
      <mass
        value="0.197841071704829" />
      <inertia
        ixx="0.000148040974322464"
        ixy="4.02156422686863E-07"
        ixz="-1.03598353298135E-06"
        iyy="0.000260030643771461"
        iyz="-3.27573524729728E-07"
        izz="0.000335789891392015" />
    </inertial>
    <visual>
      <origin
        xyz="0 0 0"
        rpy="0 0 0" />
      <geometry>
        <mesh
          filename="../../meshes/Bessica_D_v1_1/SkeletonOnly/left_arm_link1.STL" scale="1 1 1" />
      </geometry>
      <material
        name="">
        <color
          rgba="0.807843137254902 0.843137254901961 0.905882352941176 1" />
      </material>
    </visual>
    <collision>
      <origin
        xyz="0 0 0"
        rpy="0 0 0" />
      <geometry>
        <mesh
          filename="../../meshes/Bessica_D_v1_1/SkeletonOnly/left_arm_link1.STL" scale="1 1 1" />
      </geometry>
    </collision>
  </link>
  <joint
    name="left_arm_joint1"
    type="revolute">
    <origin
      xyz="4.99975002436759E-05 0 0.1146"
      rpy="3.14159265358979 0 0" />
    <parent
      link="left_arm_base_link" />
    <child
      link="left_arm_link1" />
    <axis
      xyz="0 0 1" />
    <limit
      lower="-2.749"
      upper="2.749"
      effort="5"
      velocity="12" />
  </joint>
  <link
    name="left_arm_link2">
    <inertial>
      <origin
        xyz="-0.0297080811587231 -0.00029373395179691 -0.000469873033539708"
        rpy="0 0 0" />
      <mass
        value="0.047269050971783" />
      <inertia
        ixx="7.84810462964505E-06"
        ixy="3.03073005983045E-07"
        ixz="8.12874806591852E-07"
        iyy="1.61967305681636E-05"
        iyz="-2.66376107909205E-08"
        izz="1.57923059360938E-05" />
    </inertial>
    <visual>
      <origin
        xyz="0 0 0"
        rpy="0 0 0" />
      <geometry>
        <mesh
          filename="../../meshes/Bessica_D_v1_1/SkeletonOnly/left_arm_link2.STL" scale="1 1 1" />
      </geometry>
      <material
        name="">
        <color
          rgba="0.592156862745098 0.666666666666667 0.682352941176471 1" />
      </material>
    </visual>
    <collision>
      <origin
        xyz="0 0 0"
        rpy="0 0 0" />
      <geometry>
        <mesh
          filename="../../meshes/Bessica_D_v1_1/SkeletonOnly/left_arm_link2.STL" scale="1 1 1" />
      </geometry>
    </collision>
  </link>
  <joint
    name="left_arm_joint2"
    type="revolute">
    <origin
      xyz="0 0 -0.04286"
      rpy="1.5707963267949 0 -1.5707963267949" />
    <parent
      link="left_arm_link1" />
    <child
      link="left_arm_link2" />
    <axis
      xyz="0 0 0.999999999999908" />
    <limit
      lower="-0.1"
      upper="3.14159"
      effort="5"
      velocity="12" />
  </joint>
  <link
    name="left_arm_link3">
    <inertial>
      <origin
        xyz="-0.00359313643753523 -0.00022191416785991 0.0944689657047718"
        rpy="0 0 0" />
      <mass
        value="0.140451564579074" />
      <inertia
        ixx="7.84851547058427E-05"
        ixy="7.63137504480604E-08"
        ixz="-2.13950343902015E-06"
        iyy="8.80462026632492E-05"
        iyz="-2.08857323389277E-07"
        izz="5.54283682381524E-05" />
    </inertial>
    <visual>
      <origin
        xyz="0 0 0"
        rpy="0 0 0" />
      <geometry>
        <mesh
          filename="../../meshes/Bessica_D_v1_1/SkeletonOnly/left_arm_link3.STL" scale="1 1 1" />
      </geometry>
      <material
        name="">
        <color
          rgba="0.807843137254902 0.843137254901961 0.905882352941176 1" />
      </material>
    </visual>
    <collision>
      <origin
        xyz="0 0 0"
        rpy="0 0 0" />
      <geometry>
        <mesh
          filename="../../meshes/Bessica_D_v1_1/SkeletonOnly/left_arm_link3.STL" scale="1 1 1" />
      </geometry>
    </collision>
  </link>
  <joint
    name="left_arm_joint3"
    type="revolute">
    <origin
      xyz="-0.0645499982324007 0 -0.000299995732645275"
      rpy="0 -1.5707963267949 0" />
    <parent
      link="left_arm_link2" />
    <child
      link="left_arm_link3" />
    <axis
      xyz="0 0 -0.999999999999908" />
    <limit
      lower="-2.79"
      upper="2.79"
      effort="5"
      velocity="12" />
  </joint>
  <link
    name="left_arm_link4">
    <inertial>
      <origin
        xyz="2.80228986507813E-05 -0.0241582487399286 4.84136442951422E-05"
        rpy="0 0 0" />
      <mass
        value="0.0427207248079551" />
      <inertia
        ixx="1.04868449032066E-05"
        ixy="-6.74038118152915E-10"
        ixz="2.03399188478554E-12"
        iyy="8.4976782571955E-06"
        iyz="1.47259007043504E-12"
        izz="8.0056487261008E-06" />
    </inertial>
    <visual>
      <origin
        xyz="0 0 0"
        rpy="0 0 0" />
      <geometry>
        <mesh
          filename="../../meshes/Bessica_D_v1_1/SkeletonOnly/left_arm_link4.STL" scale="1 1 1" />
      </geometry>
      <material
        name="">
        <color
          rgba="0.592156862745098 0.666666666666667 0.682352941176471 1" />
      </material>
    </visual>
    <collision>
      <origin
        xyz="0 0 0"
        rpy="0 0 0" />
      <geometry>
        <mesh
          filename="../../meshes/Bessica_D_v1_1/SkeletonOnly/left_arm_link4.STL" scale="1 1 1" />
      </geometry>
    </collision>
  </link>
  <joint
    name="left_arm_joint4"
    type="revolute">
    <origin
      xyz="-1.89941608896571E-05 -4.99999999989398E-05 0.1816"
      rpy="1.57079632191723 -1.57079611188729 0" />
    <parent
      link="left_arm_link3" />
    <child
      link="left_arm_link4" />
    <axis
      xyz="0 0 1" />
    <limit
      lower="-0.5236"
      upper="2.95"
      effort="5"
      velocity="12" />
  </joint>
  <link
    name="left_arm_link5">
    <inertial>
      <origin
        xyz="-0.00180910609865517 -0.000196784930609262 0.0430792510138713"
        rpy="0 0 0" />
      <mass
        value="0.110396951419793" />
      <inertia
        ixx="8.50646330315701E-05"
        ixy="4.15482574231161E-07"
        ixz="-9.67661925090857E-06"
        iyy="8.69928977214169E-05"
        iyz="8.81476826739089E-07"
        izz="4.58202384094719E-05" />
    </inertial>
    <visual>
      <origin
        xyz="0 0 0"
        rpy="0 0 0" />
      <geometry>
        <mesh
          filename="../../meshes/Bessica_D_v1_1/SkeletonOnly/left_arm_link5.STL" scale="1 1 1" />
      </geometry>
      <material
        name="">
        <color
          rgba="0.807843137254902 0.843137254901961 0.905882352941176 1" />
      </material>
    </visual>
    <collision>
      <origin
        xyz="0 0 0"
        rpy="0 0 0" />
      <geometry>
        <mesh
          filename="../../meshes/Bessica_D_v1_1/SkeletonOnly/left_arm_link5.STL" scale="1 1 1" />
      </geometry>
    </collision>
  </link>
  <joint
    name="left_arm_joint5"
    type="revolute">
    <origin
      xyz="0 -0.0488000000000013 9.99999999971857E-05"
      rpy="1.5707963267949 1.5707963267949 0" />
    <parent
      link="left_arm_link4" />
    <child
      link="left_arm_link5" />
    <axis
      xyz="0 0 -1" />
    <limit
      lower="-2.79"
      upper="2.79"
      effort="5"
      velocity="12" />
  </joint>
  <link
    name="left_arm_link6">
    <inertial>
      <origin
        xyz="0.000365897578245789 -0.0257376411060571 -4.10017384396277E-05"
        rpy="0 0 0" />
      <mass
        value="0.0345706786766011" />
      <inertia
        ixx="1.56357560389182E-05"
        ixy="-1.63183630784698E-07"
        ixz="-7.87695854254256E-09"
        iyy="1.27277246485998E-05"
        iyz="2.83300566726637E-08"
        izz="9.20019800183918E-06" />
    </inertial>
    <visual>
      <origin
        xyz="0 0 0"
        rpy="0 0 0" />
      <geometry>
        <mesh
          filename="../../meshes/Bessica_D_v1_1/SkeletonOnly/left_arm_link6.STL" scale="1 1 1" />
      </geometry>
      <material
        name="">
        <color
          rgba="0.807843137254902 0.843137254901961 0.905882352941176 1" />
      </material>
    </visual>
    <collision>
      <origin
        xyz="0 0 0"
        rpy="0 0 0" />
      <geometry>
        <mesh
          filename="../../meshes/Bessica_D_v1_1/SkeletonOnly/left_arm_link6.STL" scale="1 1 1" />
      </geometry>
    </collision>
  </link>
  <joint
    name="left_arm_joint6"
    type="revolute">
    <origin
      xyz="0.00289000000000006 -0.00207606624709478 0.108009995732641"
      rpy="-1.5707963267949 0 0" />
    <parent
      link="left_arm_link5" />
    <child
      link="left_arm_link6" />
    <axis
      xyz="0 0 -1" />
    <limit
      lower="-1.675"
      upper="1.675"
      effort="5"
      velocity="12" />
  </joint>
  <link
    name="left_arm_link7">
    <inertial>
      <origin
        xyz="0.0410511427488477 -0.00430969105775492 0.0266716202400142"
        rpy="0 0 0" />
      <mass
        value="0.130827779886618" />
      <inertia
        ixx="9.36649809271695E-05"
        ixy="1.47345014368025E-08"
        ixz="3.64715378550686E-06"
        iyy="4.23029425604473E-05"
        iyz="-1.66579265283484E-08"
        izz="8.42341624949847E-05" />
    </inertial>
    <visual>
      <origin
        xyz="0 0 0"
        rpy="0 0 0" />
      <geometry>
        <mesh
          filename="../../meshes/Bessica_D_v1_1/SkeletonOnly/left_arm_link7.STL" scale="1 1 1" />
      </geometry>
      <material
        name="">
        <color
          rgba="0.807843137254902 0.843137254901961 0.905882352941176 1" />
      </material>
    </visual>
    <collision>
      <origin
        xyz="0 0 0"
        rpy="0 0 0" />
      <geometry>
        <mesh
          filename="../../meshes/Bessica_D_v1_1/SkeletonOnly/left_arm_link7.STL" scale="1 1 1" />
      </geometry>
    </collision>
  </link>
  <joint
    name="left_arm_joint7"
    type="revolute">
    <origin
      xyz="-0.00149999999999997 -0.0563100878103864 0.00415239451449378"
      rpy="1.5707963267949 0 -1.5707963267949" />
    <parent
      link="left_arm_link6" />
    <child
      link="left_arm_link7" />
    <axis
      xyz="0 0 -1" />
    <limit
      lower="-1.448"
      upper="1.448"
      effort="5"
      velocity="12" />
  </joint>
  <link
    name="left_arm_gripper_right_finger">
    <inertial>
      <origin
        xyz="-0.0434086681995018 1.54744227154335E-08 0.111659632268856"
        rpy="0 0 0" />
      <mass
        value="0.025646269010605" />
      <inertia
        ixx="5.13427082501842E-06"
        ixy="-2.44760154990855E-11"
        ixz="1.26430153583781E-06"
        iyy="6.46826196607962E-06"
        iyz="-4.17572002893429E-13"
        izz="8.03606713459141E-06" />
    </inertial>
    <visual>
      <origin
        xyz="0 0 0"
        rpy="0 0 0" />
      <geometry>
        <mesh
          filename="../../meshes/Bessica_D_v1_1/SkeletonOnly/left_arm_gripper_right_finger.STL" scale="1 1 1" />
      </geometry>
      <material
        name="">
        <color
          rgba="0.592156862745098 0.666666666666667 0.682352941176471 1" />
      </material>
    </visual>
    <collision>
      <origin
        xyz="0 0 0"
        rpy="0 0 0" />
      <geometry>
        <mesh
          filename="../../meshes/Bessica_D_v1_1/SkeletonOnly/left_arm_gripper_right_finger.STL" scale="1 1 1" />
      </geometry>
    </collision>
  </link>
  <joint
    name="left_arm_gripper_joint1"
    type="prismatic">
    <origin
      xyz="0.14058 0.046348 0.00015"
      rpy="1.5708 0 0" />
    <parent
      link="left_arm_link7" />
    <child
      link="left_arm_gripper_right_finger" />
    <axis
      xyz="0 0 1" />
    <limit
      lower="-0.05"
      upper="0"
      effort="5"
      velocity="12" />
  </joint>
  <link
    name="left_arm_gripper_left_finger">
    <inertial>
      <origin
        xyz="-0.0434086681995048 1.54744233815673E-08 0.11165963580405"
        rpy="0 0 0" />
      <mass
        value="0.025646269010605" />
      <inertia
        ixx="5.13427082501839E-06"
        ixy="-2.44760154689045E-11"
        ixz="1.26430153583774E-06"
        iyy="6.46826196607951E-06"
        iyz="-4.1757199942874E-13"
        izz="8.03606713459134E-06" />
    </inertial>
    <visual>
      <origin
        xyz="0 0 0"
        rpy="0 0 0" />
      <geometry>
        <mesh
          filename="../../meshes/Bessica_D_v1_1/SkeletonOnly/left_arm_gripper_left_finger.STL" scale="1 1 1" />
      </geometry>
      <material
        name="">
        <color
          rgba="0.592156862745098 0.666666666666667 0.682352941176471 1" />
      </material>
    </visual>
    <collision>
      <origin
        xyz="0 0 0"
        rpy="0 0 0" />
      <geometry>
        <mesh
          filename="../../meshes/Bessica_D_v1_1/SkeletonOnly/left_arm_gripper_left_finger.STL" scale="1 1 1" />
      </geometry>
    </collision>
  </link>
  <joint
    name="left_arm_gripper_joint2"
    type="prismatic">
    <origin
      xyz="0.14058 -0.054652 0.00015"
      rpy="-1.5708 0 0" />
    <parent
      link="left_arm_link7" />
    <child
      link="left_arm_gripper_left_finger" />
    <axis
      xyz="0 0 -1" />
    <limit
      lower="0"
      upper="0.05"
      effort="5"
      velocity="12" />
  </joint>
  <link
    name="left_tool0">
      <visual>
      <origin
        xyz="0 0 0"
        rpy="0 0 0" />
      <geometry>
        <sphere radius="0.005" />
      </geometry>
      <material
        name="green_virtual_sphere_material">
        <color
          rgba="0 1 0 1" />
      </material>
    </visual>
  </link>
  <joint
    name="left_arm_gripper_joint"
    type="fixed">
    <origin
      xyz="0.14058 -0.0041524 0.00015"
      rpy="0 0 0" />
    <parent
      link="left_arm_link7" />
    <child
      link="left_tool0" />
    <axis
      xyz="0 0 0" />
  </joint>
</robot>
