<mujoco model="Alicia_D_v5_5_gripper_100mm">
  <compiler angle="radian" meshdir="../../meshes/Alicia_D_v5_5/" />
  <statistic center="-0.012496 0.000424702 0.622672" extent="1.93611" meansize="0.179951" />
  <visual>
    <scale jointwidth="0.02" framelength="0.3" framewidth="0.01" />
  </visual>
  <default>
    <joint armature="0.001" damping="0.01" frictionloss="0.001" limited="true" margin="0.001" type="hinge" />
    <geom material="black" />
  </default>
  <asset>
    <mesh name="base_link" file="base_link.STL" />
    <mesh name="link1" file="link1.STL" />
    <mesh name="link2" file="link2.STL" />
    <mesh name="link3" file="link3.STL" />
    <mesh name="link4" file="link4.STL" />
    <mesh name="link5" file="link5.STL" />
    <mesh name="link6" file="link6.STL" />
    <mesh name="grasp_base" file="grasp_base.STL" />
    <mesh name="link7" file="link7.STL" />
    <mesh name="link8" file="link8.STL" />
    <texture builtin="gradient" height="100" rgb1=".4 .5 .6" rgb2="0 0 0" type="skybox" width="100" />
    <texture builtin="checker" height="100" name="texplane" rgb1="1 1 1" rgb2=".8 .9 1" type="2d" width="100" />
    <material name="MatPlane" reflectance="0.5" texrepeat="1 1" texture="texplane" texuniform="true" />
    <material name="white" rgba="1 1 1 1" shininess="0.5" specular="0.1" />
    <material name="black" rgba="0.15 0.15 0.15 1" shininess="0.2" specular="0.05" />
    <material name="invisible" rgba="1 1 1 0" shininess="0" specular="0" />
  </asset>

  <worldbody>
    <geom conaffinity="1" condim="3" contype="1" friction="1 .1 .1" group="2" material="MatPlane" name="floor" pos="0 0 0" rgba="0.8 0.9 0.8 1" size="500 500 0.125" type="plane" />
    <light castshadow="false" cutoff="100" diffuse="1 1 1" dir="-0 0 -1.3" directional="true" exponent="1" pos="0 0 1.3" specular=".1 .1 .1" />
    <body name="base_link" pos="0 0 0" quat="1 0 0 0">
      <geom type="mesh" contype="0" conaffinity="0" group="1" density="0" mesh="base_link" />
      <geom type="mesh" mesh="base_link" />
      <body name="link1" pos="0 0 0.1295">
        <inertial pos="-0.000232391 -1.30049e-05 0.00272123" quat="0.494444 0.501273 -0.501535 0.502706" mass="0.193725" diaginertia="0.000339765 0.000258314 0.000149221" />
        <joint name="Joint1" pos="0 0 0" axis="0 0 1" range="-2.16 2.16" actuatorfrcrange="-12 12" />
        <geom type="mesh" contype="0" conaffinity="0" group="1" density="0" mesh="link1" />
        <geom type="mesh" mesh="link1" />
        <body name="link2" pos="0 -5e-05 0.04287" quat="0.499998 0.5 -0.5 0.500002">
          <inertial pos="0.149948 -0.000737331 -0.000614553" quat="0.527603 0.470175 0.472922 0.526226" mass="0.216765" diaginertia="0.000226233 0.000143401 0.000128092" />
          <joint name="Joint2" pos="0 0 0" axis="0 0 1" range="-1.57 1.57" actuatorfrcrange="-12 12" />
          <geom type="mesh" contype="0" conaffinity="0" group="1" density="0" mesh="link2" />
          <geom type="mesh" mesh="link2" />
          <body name="link3" pos="0.22367 -0.022592 0" quat="0.382681 0 0 -0.923881">
            <inertial pos="0.0557863 0.00248144 0.000269721" quat="-0.0276295 0.669803 0.007161 0.74199" mass="0.0845576" diaginertia="8.09971e-05 7.62965e-05 2.81294e-05" />
            <joint name="Joint3" pos="0 0 0" axis="0 0 1" range="-0.5 2.35619" actuatorfrcrange="-12 12" />
            <geom type="mesh" contype="0" conaffinity="0" group="1" density="0" mesh="link3" />
            <geom type="mesh" mesh="link3" />
            <body name="link4" pos="0.0986 -0.00211 0.0002" quat="0.499998 -0.5 0.500002 -0.5">
              <inertial pos="0.000298366 -0.000601369 0.066374" quat="0.99997 0.000404214 0.00701296 -0.00329826" mass="0.0653696" diaginertia="7.0311e-05 6.8747e-05 1.68121e-05" />
              <joint name="Joint4" pos="0 0 0" axis="0 0 -1" range="-3.14 3.14" actuatorfrcrange="-12 12" />
              <geom type="mesh" contype="0" conaffinity="0" group="1" density="0" mesh="link4" />
              <geom type="mesh" mesh="link4" />
              <body name="link5" pos="0 0.00015 0.12275" quat="0.707105 0.707108 0 0">
                <inertial pos="-0.0110961 0.0308025 -0.000207575" quat="0.809364 0.00843495 0.0103138 0.587157" mass="0.0463941" diaginertia="2.46438e-05 1.77644e-05 1.6394e-05" />
                <joint name="Joint5" pos="0 0 0" axis="0 0 1" range="-1.57 1.5" actuatorfrcrange="-12 12" />
                <geom type="mesh" contype="0" conaffinity="0" group="1" density="0" mesh="link5" />
                <geom type="mesh" mesh="link5" />
                <body name="link6" pos="-0.00385 0.0573 -0.00035" quat="0.707105 -0.707108 0 0">
                  <inertial pos="-0.0319074 -0.000167766 0.027366" quat="0.322675 0.322765 -0.628921 0.629413" mass="0.120575" diaginertia="9.08499e-05 7.88777e-05 3.47596e-05" />
                  <joint name="Joint6" pos="0 0 0" axis="0 0 -1" range="-3.14 3.14" actuatorfrcrange="-12 12" />
                  <geom type="mesh" contype="0" conaffinity="0" group="1" density="0" mesh="link6" />
                  <geom type="mesh" mesh="link6" />
                  <geom type="mesh" contype="0" conaffinity="0" group="1" density="0" mesh="grasp_base" />
                  <geom type="mesh" mesh="grasp_base" />
                  <geom size="0.005" pos="-0.0002 -0.0003 0.13118" contype="0" conaffinity="0" group="1" density="0" rgba="0 1 0 1" />
                  <body name="link7" pos="-0.0002 0.050502 0.13118" quat="0.707105 -0.707108 0 0">
                    <inertial pos="2.97088e-08 0.0434088 0.0106597" quat="0.402868 0.581114 -0.581113 0.402878" mass="0.0256461" diaginertia="8.50964e-06 6.4683e-06 4.66071e-06" />
                    <joint name="left_finger" pos="0 0 0" axis="0 0 1" type="slide" range="-0.05 0" actuatorfrcrange="-5 5" />
                    <geom type="mesh" contype="0" conaffinity="0" group="1" density="0" mesh="link7" />
                    <geom type="mesh" mesh="link7" />
                  </body>
                  <body name="link8" pos="-0.0002 -0.050498 0.13118" quat="0.707105 0.707108 0 0">
                    <inertial pos="-2.97088e-08 -0.0434088 0.0106597" quat="0.581113 0.402878 -0.402868 0.581114" mass="0.0256461" diaginertia="8.50964e-06 6.4683e-06 4.66071e-06" />
                    <joint name="right_finger" pos="0 0 0" axis="0 0 -1" type="slide" range="0 0.05" actuatorfrcrange="-5 5" />
                    <geom type="mesh" contype="0" conaffinity="0" group="1" density="0" mesh="link8" />
                    <geom type="mesh" mesh="link8" />
                  </body>
                </body>
              </body>
            </body>
          </body>
        </body>
      </body>
    </body>
  </worldbody>
  <actuator>
    <motor joint="Joint1" gear="100" />
    <motor joint="Joint2" gear="100" />
    <motor joint="Joint3" gear="100" />
    <motor joint="Joint4" gear="100" />
    <motor joint="Joint5" gear="100" />
    <motor joint="Joint6" gear="100" />
    <position joint="left_finger" />
    <position joint="right_finger" />
  </actuator>
  <contact>
    <exclude body1="base_link" body2="link1" />
    <exclude body1="link1" body2="link2" />
    <exclude body1="link2" body2="link3" />
    <exclude body1="link3" body2="link4" />
    <exclude body1="link4" body2="link5" />
    <exclude body1="link5" body2="link6" />
    <exclude body1="link6" body2="link7" />
    <exclude body1="link6" body2="link8" />
  </contact>
</mujoco>