<mujoco model="Bessica_M_v1_0">
  <compiler angle="radian" meshdir="../../meshes/Bessica_M_v1_0/"/>
  <statistic center="-0.012496 0.000424702 0.622672" extent="1.93611" meansize="0.179951" />

  <asset>
    <mesh name="base_link" file="base_link.STL"/>
    <mesh name="torso_link1" file="torso_link1.STL"/>
    <mesh name="torso_link2" file="torso_link2.STL"/>
    <mesh name="torso_link3" file="torso_link3.STL"/>
    <mesh name="right_arm_link1" file="right_arm_link1.STL"/>
    <mesh name="right_arm_link2" file="right_arm_link2.STL"/>
    <mesh name="right_arm_link3" file="right_arm_link3.STL"/>
    <mesh name="right_arm_link4" file="right_arm_link4.STL"/>
    <mesh name="right_arm_link5" file="right_arm_link5.STL"/>
    <mesh name="right_arm_link6" file="right_arm_link6.STL"/>
    <mesh name="right_arm_link7" file="right_arm_link7.STL"/>
    <mesh name="right_arm_link8" file="right_arm_link8.STL"/>
    <mesh name="right_arm_link9" file="right_arm_link9.STL"/>
    <mesh name="left_arm_link1" file="left_arm_link1.STL"/>
    <mesh name="left_arm_link2" file="left_arm_link2.STL"/>
    <mesh name="left_arm_link3" file="left_arm_link3.STL"/>
    <mesh name="left_arm_link4" file="left_arm_link4.STL"/>
    <mesh name="left_arm_link5" file="left_arm_link5.STL"/>
    <mesh name="left_arm_link6" file="left_arm_link6.STL"/>
    <mesh name="left_arm_link7" file="left_arm_link7.STL"/>
    <mesh name="left_arm_link8" file="left_arm_link8.STL"/>
    <mesh name="left_arm_link9" file="left_arm_link9.STL"/>
    <texture builtin="gradient" height="100" rgb1=".4 .5 .6" rgb2="0 0 0" type="skybox" width="100" />
    <texture builtin="checker" height="100" name="texplane" rgb1="1 1 1" rgb2=".8 .9 1" type="2d" width="100" />
    <material name="MatPlane" reflectance="0.5" texrepeat="1 1" texture="texplane" texuniform="true" />
    <material name="white" rgba="1 1 1 1" shininess="0.5" specular="0.1" />
    <material name="black" rgba="0.15 0.15 0.15 1" shininess="0.2" specular="0.05" />
    <material name="invisible" rgba="1 1 1 0" shininess="0" specular="0" />
  </asset>

  <worldbody>
    <geom conaffinity="1" condim="3" contype="1" friction="1 .1 .1" group="2" material="MatPlane" name="floor" pos="0 0 -0.6" rgba="0.8 0.9 0.8 1" size="500 500 0.125" type="plane" />
    <light castshadow="false" cutoff="100" diffuse="1 1 1" dir="-0 0 -1.3" directional="true" exponent="1" pos="0 0 1.3" specular=".1 .1 .1" />
    <body name="base_link" pos="0 0 0">
      <geom type="mesh" contype="0" conaffinity="0" group="1" density="0" rgba="0.792157 0.819608 0.933333 1" mesh="base_link"/>
      <geom type="mesh" rgba="0.792157 0.819608 0.933333 1" mesh="base_link"/>
      <body name="torso_link1" pos="0.0148249 -0.00771287 -0.004" quat="0 1 0 0">
        <inertial pos="-0.0436025 -0.00771289 -0.010242" quat="0.500197 0.500197 -0.499803 0.499803" mass="0.102876" diaginertia="0.000285251 0.000157432 0.000137303"/>
        <joint name="torso_joint1" pos="0 0 0" axis="0 0 -1" range="-1.57 1.57" actuatorfrcrange="-5 5"/>
        <geom type="mesh" contype="0" conaffinity="0" group="1" density="0" rgba="0.792157 0.819608 0.933333 1" mesh="torso_link1"/>
        <geom type="mesh" rgba="0.792157 0.819608 0.933333 1" mesh="torso_link1"/>
        <body name="torso_link2" pos="-0.0138253 -0.00771287 -0.0365491" quat="0.707107 -0.707107 0 0">
          <inertial pos="7.55191e-07 -1.06021e-05 -2.54455e-08" quat="0.499991 0.499999 0.500021 0.49999" mass="0.0301214" diaginertia="9.06743e-06 7.68992e-06 6.48454e-06"/>
          <joint name="torso_joint2" pos="0 0 0" axis="-1 0 0" range="-0.52 0.52" actuatorfrcrange="-5 5"/>
          <geom type="mesh" contype="0" conaffinity="0" group="1" density="0" rgba="0.792157 0.819608 0.933333 1" mesh="torso_link2"/>
          <geom type="mesh" rgba="0.792157 0.819608 0.933333 1" mesh="torso_link2"/>
          <body name="torso_link3" quat="0.707107 0 0.707107 0">
            <inertial pos="-7.80728e-10 0.186312 -2.557e-07" quat="1 0 2.01178e-05 0" mass="2.00368" diaginertia="0.00505191 0.00319835 0.00281101"/>
            <joint name="torso_joint3" pos="0 0 0" axis="1 0 0" range="-0.52 0.52" actuatorfrcrange="-5 5"/>
            <geom type="mesh" contype="0" conaffinity="0" group="1" density="0" rgba="0.792157 0.819608 0.933333 1" mesh="torso_link3"/>
            <geom type="mesh" rgba="0.792157 0.819608 0.933333 1" mesh="torso_link3"/>
            <body name="right_arm_link1" pos="-0.14639 0.288056 0" quat="0 0.573576 -0.819152 0">
              <inertial pos="-0.000146047 0.0600601 -0.0022175" quat="-0.000412026 0.707107 0.000412026 0.707107" mass="0.375516" diaginertia="0.00040581 0.000273013 0.000260319"/>
              <joint name="right_joint1" pos="0 0 0" axis="0 1 0" range="-3.14159 3.14159" actuatorfrcrange="-5 5"/>
              <geom type="mesh" contype="0" conaffinity="0" group="1" density="0" rgba="0.792157 0.819608 0.933333 1" mesh="right_arm_link1"/>
              <geom type="mesh" rgba="0.792157 0.819608 0.933333 1" mesh="right_arm_link1"/>
              <body name="right_arm_link2" pos="0.0001 0.065 0" quat="0 -0.707107 0.707107 0">
                <inertial pos="0.00248315 -0.0393122 0.0226272" quat="0.529321 0.518538 -0.500819 0.447345" mass="0.0428316" diaginertia="2.14184e-05 1.94015e-05 1.03465e-05"/>
                <joint name="right_joint2" pos="0 0 0" axis="0 0 -1" range="0 3.14159" actuatorfrcrange="-5 5"/>
                <geom type="mesh" contype="0" conaffinity="0" group="1" density="0" rgba="0.792157 0.819608 0.933333 1" mesh="right_arm_link2"/>
                <geom type="mesh" rgba="0.792157 0.819608 0.933333 1" mesh="right_arm_link2"/>
                <body name="right_arm_link3" pos="0.00889252 -0.069432 0" quat="0.696364 0.696364 0.122788 0.122788">
                  <inertial pos="-6.70574e-09 0.00308845 0.0871177" quat="0.706325 0.000171871 1.45738e-05 0.707888" mass="0.281936" diaginertia="0.000221166 0.00020708 0.000100861"/>
                  <joint name="right_joint3" pos="0 0 0" axis="0 0 1" range="-1.5708 1.5708" actuatorfrcrange="-5 5"/>
                  <geom type="mesh" contype="0" conaffinity="0" group="1" density="0" rgba="0.792157 0.819608 0.933333 1" mesh="right_arm_link3"/>
                  <geom type="mesh" rgba="0.792157 0.819608 0.933333 1" mesh="right_arm_link3"/>
                  <body name="right_arm_link4" pos="0 0 0.15105" quat="0.707107 -0.707107 0 0">
                    <inertial pos="-1.58293e-08 -0.0639677 0.00176461" quat="0.707058 0.00746059 -0.00550601 0.707095" mass="0.148" diaginertia="6.21169e-05 5.46899e-05 5.06877e-05"/>
                    <joint name="right_joint4" pos="0 0 0" axis="0 0 1" range="-0.261799 2.35619" actuatorfrcrange="-5 5"/>
                    <geom type="mesh" contype="0" conaffinity="0" group="1" density="0" rgba="0.792157 0.819608 0.933333 1" mesh="right_arm_link4"/>
                    <geom type="mesh" rgba="0.792157 0.819608 0.933333 1" mesh="right_arm_link4"/>
                    <body name="right_arm_link5" pos="0 -0.0983 0.001175" quat="0.707107 0.707107 0 0">
                      <inertial pos="0.00347007 5.04579e-05 0.0466864" quat="0.999997 -0.000329185 0.00227171 -0.0012495" mass="0.162666" diaginertia="8.003e-05 6.33316e-05 3.83306e-05"/>
                      <joint name="right_joint5" pos="0 0 0" axis="0 0 1" range="-1.309 1.309" actuatorfrcrange="-5 5"/>
                      <geom type="mesh" contype="0" conaffinity="0" group="1" density="0" rgba="0.792157 0.819608 0.933333 1" mesh="right_arm_link5"/>
                      <geom type="mesh" rgba="0.792157 0.819608 0.933333 1" mesh="right_arm_link5"/>
                      <body name="right_arm_link6" pos="0.0005 -0.001175 0.1395" quat="0.5 0.5 -0.5 -0.5">
                        <inertial pos="-0.00163702 2.00389e-05 0.000702819" quat="0.999934 -0.0113632 -0.0013781 0.000602128" mass="0.148254" diaginertia="5.62864e-05 4.44903e-05 4.10839e-05"/>
                        <joint name="right_joint6" pos="0 0 0" axis="0 0 1" range="-1.0472 1.0472" actuatorfrcrange="-5 5"/>
                        <geom type="mesh" contype="0" conaffinity="0" group="1" density="0" rgba="0.898039 0.917647 0.929412 1" mesh="right_arm_link6"/>
                        <geom type="mesh" rgba="0.898039 0.917647 0.929412 1" mesh="right_arm_link6"/>
                        <body name="right_arm_link7" quat="0.0127436 0.706992 -0.0127436 -0.706992">
                          <inertial pos="-0.00235413 -0.065253 0.00953461" quat="0.482976 0.533509 0.463845 0.516673" mass="0.162887" diaginertia="8.75735e-05 8.20968e-05 4.48809e-05"/>
                          <joint name="right_joint7" pos="0 0 0" axis="0 0 -1" range="-3.14159 3.14159" actuatorfrcrange="-5 5"/>
                          <geom type="mesh" contype="0" conaffinity="0" group="1" density="0" rgba="0.898039 0.917647 0.929412 1" mesh="right_arm_link7"/>
                          <geom type="mesh" rgba="0.898039 0.917647 0.929412 1" mesh="right_arm_link7"/>
                          <body name="right_arm_link8" pos="-0.0314347 -0.177983 0.003675" quat="0.0127436 0.706992 0.0127436 -0.706992">
                            <inertial pos="-1.661e-08 -0.0425075 0.0107212" quat="0.580019 0.40445 -0.404441 0.580022" mass="0.023939" diaginertia="8.4495e-06 6.39318e-06 4.54617e-06"/>
                            <joint name="right_gripper1" pos="0 0 0" axis="0 0 1" type="slide" range="-0.025 0.025" actuatorfrcrange="-5 5"/>
                            <geom type="mesh" contype="0" conaffinity="0" group="1" density="0" rgba="0.592157 0.666667 0.682353 1" mesh="right_arm_link8"/>
                            <geom type="mesh" rgba="0.592157 0.666667 0.682353 1" mesh="right_arm_link8"/>
                          </body>
                          <body name="right_arm_link9" pos="0.0185329 -0.179785 0.003675" quat="0.706992 0.0127436 0.706992 -0.0127436">
                            <inertial pos="1.661e-08 0.0425075 0.0107212" quat="0.404441 0.580022 -0.580019 0.40445" mass="0.023939" diaginertia="8.4495e-06 6.39318e-06 4.54617e-06"/>
                            <joint name="right_gripper2" pos="0 0 0" axis="0 0 -1" type="slide" range="-0.025 0.025" actuatorfrcrange="-5 5"/>
                            <geom type="mesh" contype="0" conaffinity="0" group="1" density="0" rgba="0.592157 0.666667 0.682353 1" mesh="right_arm_link9"/>
                            <geom type="mesh" rgba="0.592157 0.666667 0.682353 1" mesh="right_arm_link9"/>
                          </body>
                        </body>
                      </body>
                    </body>
                  </body>
                </body>
              </body>
            </body>
            <body name="left_arm_link1" pos="0.14639 0.288056 0" quat="0.40558 0.40558 0.579228 0.579228">
              <inertial pos="-0.000146047 0.0022175 0.0600601" quat="0.500291 0.499709 0.499709 0.500291" mass="0.375516" diaginertia="0.00040581 0.000273013 0.000260319"/>
              <joint name="left_joint1" pos="0 0 0" axis="0 0 -1" range="-3.14159 3.14159" actuatorfrcrange="-5 5"/>
              <geom type="mesh" contype="0" conaffinity="0" group="1" density="0" rgba="0.792157 0.819608 0.933333 1" mesh="left_arm_link1"/>
              <geom type="mesh" rgba="0.792157 0.819608 0.933333 1" mesh="left_arm_link1"/>
              <body name="left_arm_link2" pos="0.0001 0.0301 0.065" quat="0.5 0.5 0.5 -0.5">
                <inertial pos="0.00154995 -0.0334136 0.00347539" quat="0.504389 0.479245 -0.511931 0.503829" mass="0.0664892" diaginertia="3.96656e-05 3.39284e-05 1.43607e-05"/>
                <joint name="left_joint2" pos="0 0 0" axis="0 0 -1" range="0 3.14159" actuatorfrcrange="-5 5"/>
                <geom type="mesh" contype="0" conaffinity="0" group="1" density="0" rgba="0.792157 0.819608 0.933333 1" mesh="left_arm_link2"/>
                <geom type="mesh" rgba="0.792157 0.819608 0.933333 1" mesh="left_arm_link2"/>
                <body name="left_arm_link3" pos="0.00889252 -0.069432 0.0301" quat="0.696364 0.696364 0.122788 0.122788">
                  <inertial pos="-3.7107e-05 -0.00356033 0.0859017" quat="0.705933 -0.000172302 -1.35359e-05 0.708278" mass="0.276674" diaginertia="0.000218816 0.000205987 9.95728e-05"/>
                  <joint name="left_joint3" pos="0 0 0" axis="0 0 -1" range="-1.5708 1.5708" actuatorfrcrange="-5 5"/>
                  <geom type="mesh" contype="0" conaffinity="0" group="1" density="0" rgba="0.792157 0.819608 0.933333 1" mesh="left_arm_link3"/>
                  <geom type="mesh" rgba="0.792157 0.819608 0.933333 1" mesh="left_arm_link3"/>
                  <body name="left_arm_link4" pos="0 -0.029675 0.15105" quat="0.707107 0.707107 0 0">
                    <inertial pos="1.58345e-08 0.0639677 -0.0279104" quat="0.707058 -0.00746059 0.00550601 0.707095" mass="0.148" diaginertia="6.21169e-05 5.46899e-05 5.06877e-05"/>
                    <joint name="left_joint4" pos="0 0 0" axis="0 0 -1" range="-2.35619 0.261799" actuatorfrcrange="-5 5"/>
                    <geom type="mesh" contype="0" conaffinity="0" group="1" density="0" rgba="0.792157 0.819608 0.933333 1" mesh="left_arm_link4"/>
                    <geom type="mesh" rgba="0.792157 0.819608 0.933333 1" mesh="left_arm_link4"/>
                    <body name="left_arm_link5" pos="0 0.0983 -0.0285" quat="0.707107 0.707107 0 0">
                      <inertial pos="0.00347007 -5.04579e-05 -0.0466864" quat="0.999997 -0.000329185 -0.00227171 0.0012495" mass="0.162666" diaginertia="8.003e-05 6.33316e-05 3.83306e-05"/>
                      <joint name="left_joint5" pos="0 0 0" axis="0 0 1" range="-1.309 1.309" actuatorfrcrange="-5 5"/>
                      <geom type="mesh" contype="0" conaffinity="0" group="1" density="0" rgba="0.792157 0.819608 0.933333 1" mesh="left_arm_link5"/>
                      <geom type="mesh" rgba="0.792157 0.819608 0.933333 1" mesh="left_arm_link5"/>
                      <body name="left_arm_link6" pos="0.0005 0 -0.1395" quat="0.5 0.5 -0.5 -0.5">
                        <inertial pos="-0.000462025 2.00389e-05 0.000702819" quat="0.999934 -0.0113632 -0.0013781 0.000602128" mass="0.148254" diaginertia="5.62864e-05 4.44903e-05 4.10839e-05"/>
                        <joint name="left_joint6" pos="0 0 0" axis="0 0 -1" range="-1.0472 1.0472" actuatorfrcrange="-5 5"/>
                        <geom type="mesh" contype="0" conaffinity="0" group="1" density="0" rgba="1 1 1 1" mesh="left_arm_link6"/>
                        <geom type="mesh" rgba="1 1 1 1" mesh="left_arm_link6"/>
                        <body name="left_arm_link7" quat="0 0.707107 0 -0.707107">
                          <inertial pos="9.73358e-07 0.0652955 0.00835961" quat="0.525063 0.473586 0.525293 0.473385" mass="0.162887" diaginertia="8.75735e-05 8.20968e-05 4.48809e-05"/>
                          <joint name="left_joint7" pos="0 0 0" axis="0 0 1" range="-3.14159 3.14159" actuatorfrcrange="-5 5"/>
                          <geom type="mesh" contype="0" conaffinity="0" group="1" density="0" rgba="0.898039 0.917647 0.929412 1" mesh="left_arm_link7"/>
                          <geom type="mesh" rgba="0.898039 0.917647 0.929412 1" mesh="left_arm_link7"/>
                          <body name="left_arm_link8" pos="0.025 0.179 0.0025" quat="0.707107 0 0.707107 0">
                            <inertial pos="-1.661e-08 -0.0425075 0.0107212" quat="0.580019 0.40445 -0.404441 0.580022" mass="0.023939" diaginertia="8.4495e-06 6.39318e-06 4.54617e-06"/>
                            <joint name="left_gripper1" pos="0 0 0" axis="0 0 1" type="slide" range="-0.025 0.025" actuatorfrcrange="-5 5"/>
                            <geom type="mesh" contype="0" conaffinity="0" group="1" density="0" rgba="0.592157 0.666667 0.682353 1" mesh="left_arm_link8"/>
                            <geom type="mesh" rgba="0.592157 0.666667 0.682353 1" mesh="left_arm_link8"/>
                          </body>
                          <body name="left_arm_link9" pos="-0.025 0.179 0.0025" quat="0 0.707107 0 -0.707107">
                            <inertial pos="1.661e-08 0.0425075 0.0107212" quat="0.404441 0.580022 -0.580019 0.40445" mass="0.023939" diaginertia="8.4495e-06 6.39318e-06 4.54617e-06"/>
                            <joint name="left_gripper2" pos="0 0 0" axis="0 0 -1" type="slide" range="-0.025 0.025" actuatorfrcrange="-5 5"/>
                            <geom type="mesh" contype="0" conaffinity="0" group="1" density="0" rgba="0.592157 0.666667 0.682353 1" mesh="left_arm_link9"/>
                            <geom type="mesh" rgba="0.592157 0.666667 0.682353 1" mesh="left_arm_link9"/>
                          </body>
                        </body>
                      </body>
                    </body>
                  </body>
                </body>
              </body>
            </body>
          </body>
        </body>
      </body>
    </body>
  </worldbody>
  <contact>
    <exclude body1="base_link" body2="torso_link1"/>
    <exclude body1="base_link" body2="torso_link2"/>
    <exclude body1="torso_link1" body2="torso_link2"/>
    <exclude body1="torso_link1" body2="torso_link3"/>
    <exclude body1="torso_link2" body2="torso_link3"/>
    <exclude body1="torso_link3" body2="left_arm_link1"/>
    <exclude body1="left_arm_link1" body2="left_arm_link2"/>
    <exclude body1="left_arm_link2" body2="left_arm_link3"/>
    <exclude body1="left_arm_link3" body2="left_arm_link4"/>
    <exclude body1="left_arm_link4" body2="left_arm_link5"/>
    <exclude body1="left_arm_link5" body2="left_arm_link6"/>
    <exclude body1="left_arm_link5" body2="left_arm_link7"/>
    <exclude body1="left_arm_link6" body2="left_arm_link7"/>
    <exclude body1="left_arm_link7" body2="left_arm_link8"/>
    <exclude body1="left_arm_link7" body2="left_arm_link9"/>
    <exclude body1="torso_link3" body2="right_arm_link1"/>
    <exclude body1="right_arm_link1" body2="right_arm_link2"/>
    <exclude body1="right_arm_link2" body2="right_arm_link3"/>
    <exclude body1="right_arm_link3" body2="right_arm_link4"/>
    <exclude body1="right_arm_link4" body2="right_arm_link5"/>
    <exclude body1="right_arm_link5" body2="right_arm_link6"/>
    <exclude body1="right_arm_link5" body2="right_arm_link7"/>
    <exclude body1="right_arm_link6" body2="right_arm_link7"/>
    <exclude body1="right_arm_link7" body2="right_arm_link8"/>
    <exclude body1="right_arm_link7" body2="right_arm_link9"/>
  </contact>
</mujoco>
