<mujoco model="lingdong_shijiaobi_ur">
  <compiler angle="radian" meshdir="../../meshes/Alicia_D_v5_6/leader_ur/"/>

  <asset>
    <mesh name="base_link" file="base_link.STL"/>
    <mesh name="link1" file="link1.STL"/>
    <mesh name="link2" file="link2.STL"/>
    <mesh name="link3" file="link3.STL"/>
    <mesh name="link4" file="link4.STL"/>
    <mesh name="link5" file="link5.STL"/>
    <mesh name="link6" file="link6.STL"/>
    <texture builtin="gradient" height="100" rgb1=".4 .5 .6" rgb2="0 0 0" type="skybox" width="100" />
    <texture builtin="checker" height="100" name="texplane" rgb1="1 1 1" rgb2=".8 .9 1" type="2d" width="100" />
    <material name="MatPlane" reflectance="0.5" texrepeat="1 1" texture="texplane" texuniform="true" />
    <material name="white" rgba="1 1 1 1" shininess="0.5" specular="0.1" />
    <material name="black" rgba="0.15 0.15 0.15 1" shininess="0.2" specular="0.05" />
    <material name="invisible" rgba="1 1 1 0" shininess="0" specular="0" />
  </asset>

  <worldbody>
    <geom conaffinity="1" condim="3" contype="1" friction="1 .1 .1" group="2" material="MatPlane" name="floor" pos="0 0 0" rgba="0.8 0.9 0.8 1" size="10 10 0.125" type="plane" />
    <light castshadow="false" cutoff="100" diffuse="1 1 1" dir="-0 0 -1.3" directional="true" exponent="1" pos="0 0 1.3" specular=".1 .1 .1" />
    <body name="base_link" pos="0 0 0">
      <geom type="mesh" contype="0" conaffinity="0" group="1" density="0" rgba="0.15 0.15 0.15 1" mesh="base_link"/>
      <geom type="mesh" rgba="0.15 0.15 0.15 1" mesh="base_link"/>
      <body name="link1" pos="-0.01474 0 0.05085">
        <inertial pos="-2.04631e-07 -0.00240833 0.0195303" quat="0.923562 0.383449 -0.000420886 0.000199617" mass="0.0240092" diaginertia="6.58028e-06 5.87161e-06 5.69005e-06"/>
        <joint name="joint1" pos="0 0 0" axis="0 0 1" range="-3.14159 3.14159" actuatorfrcrange="-5 5"/>
        <geom type="mesh" contype="0" conaffinity="0" group="1" density="0" rgba="0.15 0.15 0.15 1" mesh="link1"/>
        <geom type="mesh" rgba="0.15 0.15 0.15 1" mesh="link1"/>
        <body name="link2" pos="0 -0.0003 0.04286" quat="0.499998 0.5 -0.5 0.500002">
          <inertial pos="0.10508 0.00201926 -0.000206842" quat="0.498033 0.477654 0.514169 0.509353" mass="0.095362" diaginertia="6.60825e-05 5.66505e-05 2.48985e-05"/>
          <joint name="joint2" pos="0 0 0" axis="0 0 -1" range="-1.75 1.75" actuatorfrcrange="-5 5"/>
          <geom type="mesh" contype="0" conaffinity="0" group="1" density="0" rgba="0.15 0.15 0.15 1" mesh="link2"/>
          <geom type="mesh" rgba="0.15 0.15 0.15 1" mesh="link2"/>
          <body name="link3" pos="0.18922 0.027473 -0.00041" quat="0.923879 0 0 0.382684">
            <inertial pos="-2.22489e-06 0.0809012 0.00133544" quat="0.664106 0.747639 5.54241e-05 -0.000181473" mass="0.095928" diaginertia="5.72049e-05 4.74575e-05 2.50244e-05"/>
            <joint name="joint3" pos="0 0 0" axis="0 0 -1" range="-0.6 2.3562" actuatorfrcrange="-5 5"/>
            <geom type="mesh" contype="0" conaffinity="0" group="1" density="0" rgba="0.15 0.15 0.15 1" mesh="link3"/>
            <geom type="mesh" rgba="0.15 0.15 0.15 1" mesh="link3"/>
            <body name="link4" pos="0 0.1601 0.0187">
              <inertial pos="-9.81217e-08 0.00118475 0.0286616" quat="0.999735 -0.0230161 -7.91204e-05 -7.50127e-06" mass="0.0468353" diaginertia="2.14161e-05 1.76073e-05 1.66067e-05"/>
              <joint name="joint4" pos="0 0 0" axis="0 0 -1" range="-3.14159 3.14159" actuatorfrcrange="-5 5"/>
              <geom type="mesh" contype="0" conaffinity="0" group="1" density="0" rgba="0.15 0.15 0.15 1" mesh="link4"/>
              <geom type="mesh" rgba="0.15 0.15 0.15 1" mesh="link4"/>
              <body name="link5" pos="0 0.02 0.05115" quat="0.707105 -0.707108 0 0">
                <inertial pos="9.74406e-08 -0.00126298 0.0290179" quat="0.999744 0.0226139 7.91971e-05 -7.51974e-06" mass="0.0475893" diaginertia="2.14353e-05 1.76442e-05 1.6626e-05"/>
                <joint name="joint5" pos="0 0 0" axis="0 0 -1" range="-3.14159 3.14159" actuatorfrcrange="-5 5"/>
                <geom type="mesh" contype="0" conaffinity="0" group="1" density="0" rgba="0.15 0.15 0.15 1" mesh="link5"/>
                <geom type="mesh" rgba="0.15 0.15 0.15 1" mesh="link5"/>
                <body name="link6" pos="0 -0.0213 0.05115" quat="0.707105 0.707108 0 0">
                  <inertial pos="-7.97113e-05 0.000627623 0.0717231" quat="0.999975 0.00602149 0.00196965 0.00316189" mass="0.148889" diaginertia="9.98502e-05 8.45586e-05 3.99573e-05"/>
                  <joint name="joint6" pos="0 0 0" axis="0 0 -1" range="-3.14159 3.14159" actuatorfrcrange="-5 5"/>
                  <geom type="mesh" contype="0" conaffinity="0" group="1" density="0" rgba="0.15 0.15 0.15 1" mesh="link6"/>
                  <geom type="mesh" rgba="0.15 0.15 0.15 1" mesh="link6"/>
                  <body name="tool0" pos="0 0 0.05">
                    <inertial pos="0 0 0" quat="1 0 0 0" mass="0.001" diaginertia="1e-08 1e-08 1e-08"/>
                    <geom type="sphere" size="0.01" contype="0" conaffinity="0" group="1" density="0" rgba="1 0 0 0.5"/>
                    <site name="tool0_site" pos="0 0 0" size="0.01" type="sphere"/>
                  </body>
                </body>
              </body>
            </body>
          </body>
        </body>
      </body>
    </body>
  </worldbody>
  <contact>
    <exclude body1="base_link" body2="link1" />
    <exclude body1="link1" body2="link2" />
    <exclude body1="link2" body2="link3" />
    <exclude body1="link3" body2="link4" />
    <exclude body1="link4" body2="link5" />
    <exclude body1="link5" body2="link6" />
  </contact>
</mujoco>
